File: Calibration Data/test_PC_ASTM638.is_tens_RawData/Specimen_RawData_2.csv
Operator,"Quentin Govignon"
Our Reference Number,""
Customer Reference,""
Temperature (°C),21.0
Humidity (%),50.
Load Frame,"Instron Model 1185"
Crosshead Speed 1,5.00,mm/min
Extensometer G.L.,"50 mm"
Specimen Name,"PC #2"
Geometry,Rectangular
Length,104.00,mm
Maximum Load,8095.95138,N
Maximum Tensile stress,64.98137,MPa
Modulus (Chord 0.05 % - 0.25 %),2431.49458,MPa
Modulus (Young's 0.025 % - 0.5 %),2511.31873,MPa
Extension at Break (Standard),104.38144,mm
Specimen note 1,""
Specimen note 2,""
Specimen note 3,""

Time,Extension,Load,Strain 1,Tensile stress,Tensile strain,Tensile extension
(sec),(mm),(N),(mm/mm),(MPa),(mm/mm),(mm)
0.00000,-0.00004,0.13109,-0.00002,0.00105,-0.00002,-0.00089
1.60000,0.13316,283.59778,0.00090,2.27627,0.00090,0.04505
3.20000,0.26672,590.60534,0.00191,4.74044,0.00191,0.09547
4.80000,0.40000,891.09959,0.00291,7.15233,0.00291,0.14555
6.40000,0.53336,1206.48099,0.00398,9.68370,0.00398,0.19901
8.00000,0.66676,1504.55711,0.00500,12.07618,0.00500,0.25019
9.60000,0.80008,1800.64812,0.00603,14.45273,0.00603,0.30162
11.20000,0.93332,2091.36978,0.00707,16.78618,0.00707,0.35370
12.80000,1.06668,2369.99113,0.00809,19.02251,0.00809,0.40453
14.40000,1.19996,2645.71719,0.00910,21.23559,0.00910,0.45518
16.00000,1.33320,2912.24420,0.01012,23.37485,0.01012,0.50611
17.60000,1.46672,3175.50711,0.01114,25.48790,0.01114,0.55710
19.20000,1.59996,3428.11123,0.01216,27.51540,0.01216,0.60807
20.80000,1.73332,3684.54009,0.01322,29.57361,0.01322,0.66102
22.40000,1.86664,3922.88640,0.01423,31.48667,0.01423,0.71158
24.00000,1.99996,4153.66814,0.01525,33.33902,0.01525,0.76235
25.60000,2.13332,4376.56268,0.01627,35.12806,0.01627,0.81327
27.20000,2.26664,4592.91227,0.01728,36.86457,0.01728,0.86415
28.80000,2.40000,4814.43964,0.01837,38.64264,0.01837,0.91830
30.40000,2.53324,5014.14873,0.01939,40.24558,0.01939,0.96942
32.00000,2.66668,5194.02660,0.02035,41.68935,0.02035,1.01761
33.60000,2.79996,5354.91928,0.02126,42.98074,0.02126,1.06318
35.20000,2.93328,5544.09549,0.02233,44.49915,0.02233,1.11666
36.80000,3.06668,5695.33221,0.02326,45.71304,0.02326,1.16279
38.40000,3.19992,5833.35608,0.02414,46.82087,0.02414,1.20698
40.00000,3.33328,5964.07577,0.02503,47.87008,0.02503,1.25127
41.60000,3.46672,6116.05719,0.02605,49.08994,0.02605,1.30270
43.20000,3.59996,6257.92295,0.02703,50.22862,0.02703,1.35173
44.80000,3.73328,6370.24045,0.02791,51.13012,0.02791,1.39540
46.40000,3.86668,6478.43108,0.02882,51.99850,0.02882,1.44122
48.00000,3.99992,6626.45474,0.02993,53.18660,0.02993,1.49673
49.60000,4.13324,6720.01764,0.03082,53.93757,0.03082,1.54117
51.20000,4.26680,6859.88888,0.03200,55.06024,0.03200,1.60003
52.80000,4.39996,6946.33201,0.03291,55.75406,0.03291,1.64531
54.40000,4.53332,7070.76341,0.03409,56.75280,0.03409,1.70446
56.00000,4.66676,7146.38606,0.03500,57.35978,0.03500,1.75024
57.60000,4.79992,7255.86787,0.03618,58.23852,0.03618,1.80922
59.20000,4.93328,7318.97280,0.03712,58.74503,0.03712,1.85577
60.80000,5.06672,7419.81715,0.03832,59.55445,0.03832,1.91615
62.40000,5.19996,7468.52085,0.03928,59.94536,0.03928,1.96403
64.00000,5.33320,7564.34947,0.04053,60.71452,0.04053,2.02665
65.60000,5.46664,7648.66620,0.04181,61.39128,0.04181,2.09066
67.20000,5.59992,7683.04914,0.04282,61.66725,0.04282,2.14080
68.80000,5.73328,7760.23492,0.04412,62.28678,0.04412,2.20584
70.40000,5.86660,7827.30579,0.04546,62.82512,0.04546,2.27312
72.00000,5.99996,7884.96509,0.04685,63.28791,0.04685,2.34229
73.60000,6.13328,7902.93887,0.04796,63.43218,0.04796,2.39798
75.20000,6.26676,7956.12708,0.04938,63.85909,0.04938,2.46899
76.80000,6.40004,8001.43778,0.05087,64.22277,0.05087,2.54342
78.40000,6.53340,8035.49662,0.05241,64.49614,0.05241,2.62048
80.00000,6.66680,8061.63847,0.05400,64.70596,0.05400,2.69982
81.60000,6.80000,8079.64504,0.05563,64.85049,0.05563,2.78149
83.20000,6.93336,8090.04977,0.05732,64.93401,0.05732,2.86610
84.80000,7.06680,8095.56693,0.05908,64.97829,0.05908,2.95423
86.40000,7.20000,8093.34740,0.06090,64.96047,0.06090,3.04490
88.00000,7.33336,8084.05578,0.06278,64.88589,0.06278,3.13877
89.60000,7.46676,8068.11303,0.06473,64.75793,0.06473,3.23634
91.20000,7.59996,8045.47742,0.06673,64.57625,0.06673,3.33639
92.80000,7.73336,8014.66256,0.06880,64.32892,0.06880,3.43981
94.39000,7.86568,7977.49832,0.07089,64.03062,0.07058,3.52886
95.99000,7.99908,7930.95753,0.07525,63.65707,0.07186,3.59300
97.59000,8.13232,7878.87648,0.16251,63.23904,0.07314,3.65705
99.19000,8.26588,7814.82533,0.17853,62.72494,0.07443,3.72127
100.79000,8.39896,7727.04780,0.17794,62.02040,0.07570,3.78525
102.39000,8.53228,7579.41753,0.16373,60.83546,0.07699,3.84934
103.99000,8.66580,7133.10093,0.16544,57.25315,0.07827,3.91353
105.59001,8.79896,6253.80203,0.15982,50.19554,0.07955,3.97755
107.19001,8.93232,5951.23880,0.16257,47.76704,0.08083,4.04167
108.79001,9.06572,5860.83345,0.16425,47.04142,0.08212,4.10580
110.39001,9.19892,5831.15593,0.16216,46.80321,0.08340,4.16984
111.99001,9.33232,5826.87482,0.16178,46.76885,0.08468,4.23398
113.59001,9.46580,5830.92235,0.16310,46.80134,0.08596,4.29815
115.19001,9.59896,5836.58740,0.16310,46.84681,0.08724,4.36217
116.79001,9.73228,5843.15844,0.16229,46.89955,0.08853,4.42627
118.39001,9.86572,5848.56458,0.16241,46.94294,0.08981,4.49042
119.99001,9.99896,5854.57012,0.16291,46.99114,0.09109,4.55448
121.59001,10.13220,5858.77970,0.16278,47.02493,0.09237,4.61853
123.19001,10.26572,5865.65398,0.16243,47.08011,0.09365,4.68273
124.79001,10.39892,5871.38161,0.16258,47.12608,0.09494,4.74677
126.39001,10.53220,5875.07039,0.16279,47.15569,0.09622,4.81084
127.99001,10.66568,5879.14251,0.16269,47.18837,0.09750,4.87502
129.59001,10.79896,5882.01545,0.16256,47.21143,0.09878,4.93909
131.19001,10.93224,5885.17375,0.16265,47.23678,0.10006,5.00317
132.79001,11.06576,5887.84330,0.16273,47.25821,0.10135,5.06736
134.39001,11.19896,5890.57580,0.16264,47.28014,0.10263,5.13140
135.99001,11.33224,5892.28868,0.16260,47.29389,0.10391,5.19548
137.59001,11.46572,5894.79916,0.16266,47.31404,0.10519,5.25965
139.19001,11.59900,5896.50348,0.16269,47.32772,0.10647,5.32373
140.79001,11.73228,5896.19428,0.16267,47.32524,0.10776,5.38780
142.39001,11.86568,5898.86270,0.16264,47.34665,0.10904,5.45194
143.99001,11.99892,5898.52966,0.16269,47.34398,0.11032,5.51600
145.59001,12.13224,5898.38885,0.16268,47.34285,0.11160,5.58009
147.19001,12.26572,5900.20418,0.16265,47.35742,0.11289,5.64427
148.79001,12.39884,5901.36386,0.16265,47.36673,0.11417,5.70827
150.39001,12.53220,5901.80159,0.16272,47.37024,0.11545,5.77238
151.99001,12.66564,5902.13686,0.16269,47.37293,0.11673,5.83653
153.59001,12.79880,5900.71864,0.16265,47.36155,0.11801,5.90055
155.19001,12.93220,5901.80568,0.16266,47.37027,0.11929,5.96469
156.79001,13.06572,5903.11587,0.16270,47.38079,0.12058,6.02888
158.39001,13.19888,5901.68908,0.16267,47.36934,0.12186,6.09290
159.99001,13.33220,5902.68746,0.16263,47.37735,0.12314,6.15700
161.59001,13.46572,5904.15001,0.16267,47.38909,0.12442,6.22119
163.19001,13.59904,5904.23830,0.16268,47.38980,0.12571,6.28528
164.79001,13.73232,5902.37677,0.16269,47.37486,0.12699,6.34936
166.39001,13.86584,5902.20690,0.16265,47.37350,0.12827,6.41355
167.99001,13.99912,5902.01654,0.16264,47.37197,0.12955,6.47763
169.59001,14.13232,5901.47637,0.16270,47.36763,0.13083,6.54167
171.19001,14.26588,5902.99070,0.16269,47.37979,0.13212,6.60588
172.79001,14.39904,5903.43028,0.16263,47.38331,0.13340,6.66990
174.39001,14.53236,5903.72942,0.16267,47.38572,0.13468,6.73400
175.99001,14.66580,5903.66684,0.16272,47.38521,0.13596,6.79815
177.59001,14.79904,5902.46432,0.16267,47.37556,0.13724,6.86221
179.19001,14.93232,5901.31320,0.16264,47.36632,0.13853,6.92628
180.79001,15.06580,5902.06981,0.16271,47.37239,0.13981,6.99046
182.39001,15.19904,5902.23297,0.16270,47.37370,0.14109,7.05452
183.99001,15.33232,5902.37193,0.16259,47.37482,0.14237,7.11859
185.59001,15.46580,5903.12667,0.16269,47.38088,0.14366,7.18277
187.19001,15.59904,5903.22800,0.16276,47.38169,0.14494,7.24682
188.79001,15.73232,5901.89807,0.16265,47.37102,0.14622,7.31090
190.39001,15.86584,5902.14506,0.16263,47.37300,0.14750,7.37509
191.99001,15.99908,5901.67865,0.16271,47.36926,0.14878,7.43915
193.59001,16.13228,5901.88652,0.16271,47.37092,0.15006,7.50319
195.19001,16.26580,5902.99852,0.16267,47.37985,0.15135,7.56738
196.79001,16.39904,5902.21211,0.16266,47.37354,0.15263,7.63144
198.39001,16.53232,5903.41687,0.16270,47.38321,0.15391,7.69552
199.99001,16.66572,5903.17696,0.16271,47.38128,0.15519,7.75965
201.59001,16.79892,5902.64760,0.16266,47.37703,0.15647,7.82369
203.19001,16.93224,5901.39404,0.16267,47.36697,0.15776,7.88778
204.79001,17.06568,5902.75824,0.16273,47.37792,0.15904,7.95194
206.39001,17.19892,5902.79028,0.16270,47.37818,0.16032,8.01600
207.99001,17.33228,5902.33132,0.16266,47.37449,0.16160,8.08011
209.59001,17.46564,5904.58177,0.16269,47.39256,0.16288,8.14423
211.19001,17.59896,5903.23694,0.16271,47.38176,0.16417,8.20832
212.79001,17.73224,5902.52243,0.16269,47.37603,0.16545,8.27240
214.39001,17.86564,5902.55596,0.16268,47.37630,0.16673,8.33653
215.99001,17.99900,5902.40844,0.16269,47.37511,0.16801,8.40065
217.59001,18.13224,5903.44295,0.16271,47.38342,0.16929,8.46471
219.19001,18.26576,5904.92561,0.16268,47.39532,0.17058,8.52890
220.79001,18.39892,5905.01502,0.16268,47.39603,0.17186,8.59292
222.39001,18.53224,5905.18303,0.16270,47.39738,0.17314,8.65702
223.99001,18.66568,5904.48380,0.16269,47.39177,0.17442,8.72117
225.59001,18.79892,5902.61780,0.16271,47.37679,0.17570,8.78523
227.19001,18.93216,5903.00374,0.16270,47.37989,0.17699,8.84928
228.79001,19.06564,5905.14503,0.16268,47.39708,0.17827,8.91346
230.39001,19.19892,5904.85036,0.16268,47.39471,0.17955,8.97753
231.99001,19.33216,5904.45846,0.16269,47.39157,0.18083,9.04159
233.59001,19.46568,5904.84254,0.16268,47.39465,0.18212,9.10578
235.19001,19.59896,5903.59606,0.16269,47.38464,0.18340,9.16986
236.79001,19.73220,5902.02473,0.16270,47.37203,0.18468,9.23392
238.39001,19.86560,5902.54739,0.16270,47.37623,0.18596,9.29805
239.99001,19.99892,5902.23521,0.16270,47.37372,0.18724,9.36215
241.59001,20.13220,5901.17350,0.16270,47.36520,0.18852,9.42623
243.19001,20.26564,5902.08806,0.16270,47.37254,0.18981,9.49038
244.79001,20.39896,5903.08495,0.16269,47.38054,0.19109,9.55448
246.39001,20.53224,5902.99964,0.16269,47.37986,0.19237,9.61855
247.99001,20.66564,5902.65319,0.16270,47.37708,0.19365,9.68269
249.59001,20.79900,5902.11824,0.16269,47.37278,0.19494,9.74680
251.19001,20.93228,5902.40769,0.16269,47.37511,0.19622,9.81088
252.79001,21.06580,5902.64238,0.16270,47.37699,0.19750,9.87507
254.39001,21.19904,5903.19745,0.16271,47.38145,0.19878,9.93913
255.99001,21.33244,5903.24849,0.16270,47.38186,0.20007,10.00327
257.59001,21.46580,5904.81721,0.16269,47.39445,0.20135,10.06738
259.19001,21.59908,5904.28188,0.16270,47.39015,0.20263,10.13146
260.79001,21.73240,5903.84789,0.16271,47.38667,0.20391,10.19555
262.39001,21.86576,5902.53323,0.16270,47.37611,0.20519,10.25967
263.99001,21.99912,5902.13090,0.16269,47.37289,0.20648,10.32378
265.59001,22.13236,5902.20541,0.16269,47.37348,0.20776,10.38784
267.19001,22.26584,5903.59494,0.16271,47.38464,0.20904,10.45202
268.79001,22.39912,5905.62187,0.16270,47.40090,0.21032,10.51609
270.39001,22.53244,5905.57307,0.16270,47.40051,0.21160,10.58019
271.99001,22.66580,5906.71599,0.16269,47.40969,0.21289,10.64430
273.59001,22.79908,5906.21606,0.16270,47.40567,0.21417,10.70838
275.19001,22.93236,5905.55668,0.16271,47.40038,0.21545,10.77246
276.79001,23.06584,5906.01899,0.16268,47.40409,0.21673,10.83663
278.39001,23.19900,5904.96249,0.16269,47.39561,0.21801,10.90065
279.99001,23.33236,5905.20687,0.16271,47.39757,0.21930,10.96477
281.59001,23.46572,5905.64832,0.16271,47.40112,0.22058,11.02888
283.19001,23.59896,5905.04222,0.16272,47.39625,0.22186,11.09294
284.79001,23.73232,5903.34833,0.16268,47.38266,0.22314,11.15705
286.39001,23.86576,5903.60798,0.16268,47.38474,0.22442,11.22121
287.99001,23.99896,5901.90515,0.16272,47.37107,0.22570,11.28525
289.59001,24.13232,5901.68200,0.16271,47.36928,0.22699,11.34936
291.19001,24.26576,5902.58986,0.16266,47.37657,0.22827,11.41352
292.79001,24.39892,5903.38223,0.16270,47.38293,0.22955,11.47754
294.39001,24.53224,5903.10283,0.16276,47.38069,0.23083,11.54163
295.99001,24.66572,5902.56490,0.16269,47.37637,0.23212,11.60580
297.59001,24.79892,5901.18729,0.16268,47.36531,0.23340,11.66984
299.19001,24.93216,5901.45513,0.16271,47.36746,0.23468,11.73390
300.79001,25.06560,5901.33294,0.16271,47.36648,0.23596,11.79805
302.39001,25.19884,5901.70510,0.16273,47.36947,0.23724,11.86211
303.99001,25.33220,5901.95507,0.16274,47.37147,0.23852,11.92623
305.59001,25.46552,5902.04336,0.16270,47.37218,0.23981,11.99032
307.19001,25.59888,5902.17151,0.16272,47.37321,0.24109,12.05444
308.79001,25.73220,5899.98923,0.16269,47.35570,0.24237,12.11853
310.39001,25.86560,5898.20556,0.16269,47.34138,0.24365,12.18267
311.99001,25.99896,5898.16719,0.16271,47.34107,0.24494,12.24678
313.59001,26.13224,5898.79677,0.16273,47.34612,0.24622,12.31086
315.19001,26.26572,5899.65731,0.16268,47.35303,0.24750,12.37503
316.79002,26.39888,5900.64563,0.16269,47.36096,0.24878,12.43905
318.39002,26.53224,5900.98687,0.16270,47.36370,0.25006,12.50317
319.99002,26.66572,5901.20032,0.16266,47.36542,0.25135,12.56734
321.59002,26.79888,5900.02984,0.16263,47.35602,0.25263,12.63136
323.19002,26.93228,5899.69717,0.16274,47.35335,0.25391,12.69550
324.79002,27.06572,5899.67929,0.16275,47.35321,0.25519,12.75965
326.39002,27.19888,5898.85488,0.16268,47.34659,0.25647,12.82367
327.99002,27.33228,5898.91635,0.16267,47.34708,0.25776,12.88780
329.59002,27.46560,5899.72660,0.16269,47.35359,0.25904,12.95190
331.19002,27.59896,5898.82769,0.16274,47.34637,0.26032,13.01602
332.79002,27.73220,5897.60877,0.16271,47.33659,0.26160,13.08007
334.39002,27.86572,5898.31099,0.16268,47.34222,0.26289,13.14427
335.99002,27.99892,5897.61660,0.16271,47.33665,0.26417,13.20830
337.59002,28.13228,5897.14721,0.16272,47.33288,0.26545,13.27242
339.19002,28.26584,5898.33185,0.16271,47.34239,0.26673,13.33663
340.79002,28.39896,5898.75393,0.16269,47.34578,0.26801,13.40063
342.39002,28.53240,5898.39369,0.16271,47.34289,0.26930,13.46478
343.99002,28.66588,5897.79727,0.16272,47.33810,0.27058,13.52896
345.59002,28.79904,5897.60877,0.16270,47.33659,0.27186,13.59298
347.19002,28.93240,5897.13901,0.16272,47.33282,0.27314,13.65709
348.79002,29.06592,5898.39332,0.16272,47.34289,0.27443,13.72128
350.39002,29.19904,5899.19873,0.16276,47.34935,0.27571,13.78529
351.99002,29.33240,5899.70686,0.16260,47.35343,0.27699,13.84940
353.59002,29.46584,5901.36349,0.16267,47.36673,0.27827,13.91355
355.19002,29.59912,5902.33542,0.16276,47.37453,0.27955,13.97763
356.79002,29.73236,5902.00387,0.16272,47.37187,0.28083,14.04169
358.39002,29.86584,5901.68163,0.16266,47.36928,0.28212,14.10586
359.99002,29.99904,5902.90502,0.16269,47.37910,0.28340,14.16990
361.59002,30.13232,5903.11289,0.16273,47.38077,0.28468,14.23398
363.19002,30.26588,5905.72953,0.16273,47.40177,0.28596,14.29819
364.79002,30.39908,5905.11970,0.16268,47.39687,0.28724,14.36223
366.39002,30.53236,5905.59319,0.16269,47.40067,0.28853,14.42630
367.99002,30.66584,5905.41735,0.16272,47.39926,0.28981,14.49048
369.59002,30.79900,5904.37427,0.16271,47.39089,0.29109,14.55450
371.19002,30.93228,5903.05850,0.16269,47.38033,0.29237,14.61857
372.79002,31.06580,5903.02125,0.16267,47.38003,0.29366,14.68277
374.39002,31.19904,5904.12095,0.16271,47.38886,0.29494,14.74682
375.99002,31.33228,5903.01827,0.16271,47.38001,0.29622,14.81088
377.59002,31.46568,5904.03043,0.16269,47.38813,0.29750,14.87502
379.19002,31.59892,5904.20403,0.16269,47.38952,0.29878,14.93907
380.79002,31.73224,5903.74209,0.16271,47.38582,0.30006,15.00317
382.39002,31.86568,5905.30336,0.16270,47.39835,0.30135,15.06732
383.99002,31.99884,5904.13213,0.16269,47.38895,0.30263,15.13134
385.59002,32.13216,5905.27281,0.16269,47.39810,0.30391,15.19544
387.19002,32.26572,5906.34607,0.16270,47.40672,0.30519,15.25965
388.79002,32.39880,5906.90337,0.16265,47.41119,0.30647,15.32363
390.39002,32.53216,5905.82751,0.16267,47.40256,0.30775,15.38775
391.99002,32.66572,5907.06803,0.16273,47.41251,0.30904,15.45196
393.59002,32.79888,5905.09996,0.16273,47.39672,0.31032,15.51598
395.19002,32.93212,5904.12393,0.16271,47.38888,0.31160,15.58003
396.79002,33.06564,5903.99876,0.16267,47.38788,0.31288,15.64423
398.39002,33.19892,5905.45237,0.16272,47.39954,0.31417,15.70830
399.99002,33.33216,5905.91319,0.16269,47.40324,0.31545,15.77236
401.59002,33.46568,5907.24237,0.16280,47.41391,0.31673,15.83655
403.19002,33.59892,5905.86588,0.16271,47.40286,0.31801,15.90061
404.79002,33.73216,5905.10592,0.16268,47.39676,0.31929,15.96467
406.39002,33.86572,5905.50303,0.16278,47.39995,0.32058,16.02888
407.99002,33.99892,5904.74345,0.16273,47.39385,0.32186,16.09292
409.59002,34.13228,5904.53520,0.16269,47.39218,0.32314,16.15704
411.19002,34.26572,5905.57903,0.16270,47.40056,0.32442,16.22119
412.79002,34.39896,5907.04307,0.16271,47.41231,0.32570,16.28525
414.39002,34.53220,5908.02655,0.16272,47.42021,0.32699,16.34930
415.99002,34.66568,5908.67735,0.16270,47.42543,0.32827,16.41348
417.59002,34.79896,5907.94981,0.16271,47.41959,0.32955,16.47755
419.19002,34.93220,5906.96521,0.16274,47.41169,0.33083,16.54161
420.79002,35.06572,5908.21579,0.16273,47.42172,0.33212,16.60580
422.39002,35.19892,5907.49048,0.16271,47.41590,0.33340,16.66984
423.99002,35.33224,5907.87642,0.16273,47.41900,0.33468,16.73394
425.59002,35.46580,5908.92844,0.16272,47.42744,0.33596,16.79815
427.19002,35.59908,5909.08714,0.16271,47.42872,0.33724,16.86223
428.79002,35.73228,5908.09733,0.16272,47.42077,0.33853,16.92627
430.39002,35.86588,5909.00593,0.16272,47.42807,0.33981,16.99050
431.99002,35.99912,5907.65253,0.16271,47.41720,0.34109,17.05455
433.59002,36.13240,5908.53319,0.16271,47.42427,0.34237,17.11863
435.19002,36.26592,5909.20560,0.16271,47.42967,0.34366,17.18282
436.79002,36.39912,5909.87094,0.16270,47.43501,0.34494,17.24686
438.39002,36.53236,5909.91527,0.16271,47.43537,0.34622,17.31092
439.99002,36.66580,5909.29762,0.16270,47.43041,0.34750,17.37507
441.59002,36.79904,5908.84797,0.16271,47.42680,0.34878,17.43913
443.19002,36.93236,5907.83469,0.16272,47.41867,0.35006,17.50323
444.79002,37.06580,5907.95204,0.16271,47.41961,0.35135,17.56738
446.39002,37.19908,5908.62520,0.16272,47.42501,0.35263,17.63146
447.99002,37.33236,5908.12713,0.16272,47.42101,0.35391,17.69554
449.59002,37.46576,5910.26098,0.16271,47.43814,0.35519,17.75967
451.19002,37.59908,5910.02703,0.16271,47.43626,0.35648,17.82377
452.79002,37.73240,5908.42217,0.16271,47.42338,0.35776,17.88786
454.39002,37.86580,5907.26547,0.16272,47.41410,0.35904,17.95200
455.99002,37.99900,5907.32433,0.16275,47.41457,0.36032,18.01603
457.59002,38.13228,5907.47446,0.16269,47.41577,0.36160,18.08011
459.19002,38.26584,5908.46874,0.16280,47.42376,0.36289,18.14432
460.79002,38.39900,5908.05933,0.16271,47.42047,0.36417,18.20834
462.39002,38.53220,5907.60782,0.16267,47.41685,0.36545,18.27238
463.99002,38.66568,5907.37201,0.16271,47.41495,0.36673,18.33656
465.59002,38.79896,5906.62323,0.16274,47.40894,0.36801,18.40063
467.19002,38.93216,5905.04967,0.16271,47.39631,0.36929,18.46467
468.79002,39.06568,5905.63864,0.16266,47.40104,0.37058,18.52886
470.39002,39.19896,5904.80156,0.16273,47.39432,0.37186,18.59294
471.99002,39.33220,5902.76048,0.16277,47.37794,0.37314,18.65700
473.59002,39.46556,5903.20006,0.16266,47.38147,0.37442,18.72111
475.19002,39.59888,5902.21547,0.16266,47.37356,0.37570,18.78521
476.79002,39.73216,5901.41751,0.16274,47.36716,0.37699,18.84929
478.39002,39.86560,5902.38124,0.16273,47.37489,0.37827,18.91344
479.99002,39.99892,5900.82072,0.16271,47.36237,0.37955,18.97754
481.59002,40.13220,5900.87771,0.16271,47.36283,0.38083,19.04161
483.19002,40.26564,5900.79166,0.16274,47.36214,0.38212,19.10577
484.79002,40.39892,5901.36088,0.16275,47.36670,0.38340,19.16984
486.39002,40.53220,5900.78011,0.16271,47.36204,0.38468,19.23392
487.99002,40.66573,5899.08883,0.16269,47.34847,0.38596,19.29811
489.59002,40.79888,5897.01571,0.16274,47.33183,0.38724,19.36213
491.19002,40.93224,5895.45928,0.16274,47.31934,0.38852,19.42625
492.79002,41.06564,5895.00144,0.16270,47.31566,0.38981,19.49038
494.39002,41.19896,5894.76265,0.16271,47.31374,0.39109,19.55448
495.99002,41.33232,5894.59874,0.16273,47.31243,0.39237,19.61859
497.59002,41.46568,5893.50276,0.16272,47.30363,0.39365,19.68271
499.19002,41.59900,5892.59826,0.16271,47.29637,0.39494,19.74680
500.79002,41.73224,5890.41300,0.16272,47.27883,0.39622,19.81086
502.39002,41.86572,5888.05974,0.16272,47.25994,0.39750,19.87503
503.99002,41.99900,5886.52268,0.16271,47.24761,0.39878,19.93911
505.59002,42.13228,5885.05492,0.16254,47.23583,0.40006,20.00319
507.19002,42.26572,5885.66698,0.16269,47.24074,0.40135,20.06734
508.79002,42.39892,5885.45017,0.16282,47.23900,0.40263,20.13138
510.39002,42.53224,5883.94254,0.16273,47.22690,0.40391,20.19548
511.99002,42.66572,5882.63609,0.16267,47.21641,0.40519,20.25965
513.59002,42.79896,5881.10015,0.16274,47.20408,0.40647,20.32371
515.19002,42.93232,5879.69795,0.16276,47.19283,0.40776,20.38782
516.79002,43.06572,5879.56384,0.16272,47.19175,0.40904,20.45196
518.39002,43.19900,5877.78836,0.16270,47.17750,0.41032,20.51604
519.99002,43.33236,5876.66146,0.16271,47.16846,0.41160,20.58015
521.59002,43.46584,5878.49654,0.16274,47.18319,0.41289,20.64432
523.19002,43.59908,5877.22063,0.16272,47.17295,0.41417,20.70838
524.79002,43.73248,5876.86040,0.16271,47.17005,0.41545,20.77252
526.39003,43.86588,5876.81681,0.16273,47.16970,0.41673,20.83665
527.99003,43.99904,5876.08963,0.16272,47.16387,0.41801,20.90067
529.59003,44.13240,5876.53890,0.16272,47.16747,0.41930,20.96479
531.19003,44.26584,5877.43185,0.16273,47.17464,0.42058,21.02894
532.79003,44.39908,5878.04765,0.16279,47.17958,0.42186,21.09300
534.39003,44.53232,5878.52299,0.16277,47.18340,0.42314,21.15705
535.99003,44.66580,5879.30456,0.16269,47.18967,0.42442,21.22123
537.59003,44.79904,5878.75471,0.16271,47.18526,0.42571,21.28528
539.19003,44.93236,5878.79494,0.16274,47.18558,0.42699,21.34938
540.79003,45.06568,5879.83914,0.16274,47.19396,0.42827,21.41348
542.39003,45.19900,5881.96702,0.16272,47.21104,0.42955,21.47757
543.99003,45.33228,5884.53710,0.16267,47.23167,0.43083,21.54165
545.59003,45.46564,5887.12804,0.16268,47.25247,0.43212,21.60577
547.19003,45.59900,5888.31455,0.16274,47.26199,0.43340,21.66988
548.79003,45.73236,5889.59567,0.16276,47.27227,0.43468,21.73400
550.39003,45.86572,5892.33600,0.16269,47.29427,0.43596,21.79811
551.99003,45.99888,5894.05112,0.16270,47.30803,0.43724,21.86213
553.59003,46.13224,5896.47070,0.16275,47.32745,0.43852,21.92625
555.19003,46.26576,5898.50619,0.16274,47.34379,0.43981,21.99044
556.79003,46.39892,5901.97891,0.16270,47.37167,0.44109,22.05446
558.39003,46.53228,5903.05775,0.16272,47.38032,0.44237,22.11857
559.99003,46.66572,5904.51472,0.16274,47.39202,0.44365,22.18273
561.59003,46.79884,5904.42568,0.16271,47.39130,0.44493,22.24673
563.19003,46.93220,5906.76963,0.16271,47.41012,0.44622,22.31084
564.79003,47.06560,5910.41930,0.16272,47.43941,0.44750,22.37498
566.39003,47.19892,5913.94566,0.16272,47.46772,0.44878,22.43907
567.99003,47.33216,5916.45800,0.16273,47.48788,0.45006,22.50313
569.59003,47.46568,5920.00298,0.16273,47.51633,0.45135,22.56732
571.19003,47.59888,5922.76938,0.16273,47.53854,0.45263,22.63136
572.79003,47.73220,5925.78836,0.16271,47.56277,0.45391,22.69546
574.39003,47.86576,5929.13479,0.16272,47.58963,0.45519,22.75967
575.99003,47.99888,5930.72362,0.16274,47.60238,0.45647,22.82367
577.59003,48.13224,5933.49040,0.16272,47.62459,0.45776,22.88779
579.19003,48.26572,5937.54612,0.16270,47.65714,0.45904,22.95196
580.79003,48.39896,5942.26532,0.16272,47.69502,0.46032,23.01601
582.39003,48.53228,5945.47167,0.16273,47.72076,0.46160,23.08011
583.99003,48.66584,5949.19212,0.16271,47.75062,0.46289,23.14432
585.59003,48.79900,5949.76731,0.16271,47.75523,0.46417,23.20834
587.19003,48.93232,5950.63902,0.16272,47.76223,0.46545,23.27244
588.79003,49.06576,5953.50824,0.16271,47.78526,0.46673,23.33659
590.39003,49.19896,5955.75869,0.16272,47.80332,0.46801,23.40063
591.99003,49.33224,5957.99536,0.16272,47.82128,0.46929,23.46471
593.59003,49.46568,5961.36525,0.16273,47.84832,0.47058,23.52886
595.19003,49.59892,5964.16928,0.16269,47.87083,0.47186,23.59292
596.79003,49.73220,5967.00571,0.16271,47.89360,0.47314,23.65700
598.39003,49.86564,5969.77435,0.16273,47.91582,0.47442,23.72115
599.99003,49.99896,5972.60110,0.16271,47.93851,0.47570,23.78525
601.59003,50.13224,5976.12113,0.16271,47.96676,0.47699,23.84932
603.19003,50.26584,5981.56564,0.16272,48.01046,0.47827,23.91355
604.79003,50.39900,5985.51892,0.16272,48.04219,0.47955,23.97757
606.39003,50.53232,5988.36541,0.16271,48.06504,0.48083,24.04167
607.99003,50.66584,5992.67483,0.16270,48.09963,0.48212,24.10586
609.59003,50.79912,5996.30028,0.16273,48.12873,0.48340,24.16994
611.19003,50.93236,5999.41798,0.16271,48.15375,0.48468,24.23400
612.79003,51.06580,6002.86685,0.16271,48.18143,0.48596,24.29815
614.39003,51.19904,6007.07866,0.16271,48.21524,0.48724,24.36221
615.99003,51.33236,6010.21834,0.16271,48.24044,0.48853,24.42630
617.59003,51.46580,6014.23569,0.16272,48.27268,0.48981,24.49046
619.19003,51.59896,6017.17308,0.16271,48.29626,0.49109,24.55448
620.79003,51.73232,6019.38665,0.16271,48.31403,0.49237,24.61859
622.39003,51.86580,6022.89699,0.16270,48.34220,0.49366,24.68277
623.99003,51.99896,6025.65818,0.16272,48.36436,0.49494,24.74678
625.59003,52.13236,6029.92997,0.16271,48.39865,0.49622,24.81092
627.19003,52.26588,6034.57615,0.16271,48.43594,0.49750,24.87511
628.79003,52.39904,6038.67508,0.16270,48.46884,0.49878,24.93913
630.39003,52.53228,6042.42086,0.16271,48.49891,0.50006,25.00319
631.99003,52.66580,6046.72879,0.16274,48.53349,0.50135,25.06738
633.59003,52.79904,6050.08155,0.16270,48.56040,0.50263,25.13144
635.19003,52.93228,6051.04677,0.16271,48.56814,0.50391,25.19550
636.79003,53.06576,6055.77938,0.16271,48.60613,0.50519,25.25967
638.39003,53.19896,6060.78170,0.16272,48.64628,0.50647,25.32371
639.99003,53.33216,6064.58597,0.16270,48.67682,0.50775,25.38775
641.59003,53.46568,6070.07965,0.16272,48.72091,0.50904,25.45194
643.19003,53.59892,6073.63693,0.16272,48.74946,0.51032,25.51600
644.79003,53.73228,6078.18365,0.16270,48.78596,0.51160,25.58011
646.39003,53.86572,6082.20585,0.16272,48.81824,0.51289,25.64427
647.99003,53.99900,6086.45156,0.16273,48.85232,0.51417,25.70834
649.59003,54.13220,6091.26016,0.16271,48.89091,0.51545,25.77238
651.19003,54.26572,6097.40056,0.16272,48.94020,0.51673,25.83657
652.79003,54.39892,6101.19402,0.16273,48.97065,0.51801,25.90061
654.39003,54.53216,6105.69231,0.16257,49.00675,0.51929,25.96467
655.99003,54.66568,6110.63987,0.16263,49.04646,0.52058,26.02886
657.59003,54.79892,6115.54906,0.16284,49.08587,0.52186,26.09292
659.19003,54.93216,6121.14184,0.16279,49.13076,0.52314,26.15698
660.79003,55.06568,6125.67328,0.16263,49.16713,0.52442,26.22117
662.39003,55.19896,6130.72254,0.16268,49.20765,0.52570,26.28525
663.99003,55.33220,6135.18506,0.16280,49.24347,0.52699,26.34930
665.59003,55.46568,6140.60611,0.16274,49.28698,0.52827,26.41348
667.19003,55.59896,6145.17331,0.16267,49.32364,0.52955,26.47755
668.79003,55.73228,6151.09652,0.16270,49.37118,0.53083,26.54165
670.39003,55.86576,6155.83360,0.16274,49.40921,0.53212,26.60582
671.99003,55.99900,6160.91527,0.16275,49.44999,0.53340,26.66988
673.59003,56.13228,6166.45701,0.16275,49.49447,0.53468,26.73396
675.19003,56.26576,6174.05847,0.16269,49.55549,0.53596,26.79813
676.79003,56.39896,6181.28739,0.16270,49.61351,0.53724,26.86217
678.39003,56.53228,6187.49745,0.16272,49.66335,0.53853,26.92627
679.99003,56.66572,6195.22147,0.16274,49.72535,0.53981,26.99042
681.59003,56.79904,6201.80406,0.16272,49.77818,0.54109,27.05452
683.19003,56.93228,6208.22832,0.16270,49.82975,0.54237,27.11857
684.79003,57.06564,6215.68523,0.16272,49.88960,0.54365,27.18269
686.39003,57.19896,6223.52920,0.16275,49.95256,0.54494,27.24678
687.99003,57.33228,6230.61359,0.16273,50.00942,0.54622,27.31088
689.59003,57.46568,6239.14897,0.16271,50.07793,0.54750,27.37502
691.19003,57.59892,6245.20704,0.16273,50.12655,0.54878,27.43907
692.79003,57.73228,6251.77249,0.16273,50.17925,0.55006,27.50319
694.39003,57.86580,6258.55625,0.16272,50.23370,0.55135,27.56738
695.99003,57.99900,6266.26685,0.16271,50.29559,0.55263,27.63142
697.59003,58.13224,6275.08312,0.16274,50.36635,0.55391,27.69548
699.19003,58.26584,6285.15035,0.16273,50.44715,0.55519,27.75971
700.79003,58.39904,6291.71729,0.16272,50.49986,0.55647,27.82375
702.39003,58.53228,6298.62249,0.16282,50.55529,0.55776,27.88780
703.99003,58.66580,6305.11120,0.16268,50.60737,0.55904,27.95200
705.59003,58.79908,6312.26525,0.16266,50.66479,0.56032,28.01607
707.19003,58.93232,6318.56546,0.16274,50.71536,0.56160,28.08013
708.79003,59.06572,6326.41986,0.16277,50.77840,0.56289,28.14427
710.39003,59.19904,6334.33983,0.16270,50.84197,0.56417,28.20836
711.99003,59.33232,6340.45601,0.16270,50.89106,0.56545,28.27244
713.59003,59.46576,6349.16425,0.16274,50.96096,0.56673,28.33659
715.19003,59.59908,6355.59931,0.16273,51.01261,0.56801,28.40069
716.79003,59.73236,6361.02706,0.16271,51.05617,0.56930,28.46477
718.39003,59.86576,6366.88098,0.16273,51.10316,0.57058,28.52890
719.99003,59.99904,6373.59619,0.16276,51.15706,0.57186,28.59298
721.59003,60.13228,6379.07088,0.16273,51.20100,0.57314,28.65704
723.19003,60.26584,6386.10944,0.16271,51.25749,0.57442,28.72125
724.79003,60.39900,6390.96051,0.16272,51.29643,0.57571,28.78527
726.39003,60.53232,6395.77359,0.16274,51.33506,0.57699,28.84936
727.99003,60.66572,6400.41158,0.16276,51.37229,0.57827,28.91350
729.59003,60.79900,6403.32922,0.16272,51.39571,0.57955,28.97757
731.19003,60.93232,6405.57855,0.16271,51.41376,0.58083,29.04167
732.79003,61.06568,6407.86514,0.16274,51.43211,0.58212,29.10578
734.39003,61.19896,6409.58548,0.16273,51.44592,0.58340,29.16986
735.99003,61.33228,6409.66669,0.16271,51.44657,0.58468,29.23396
737.59004,61.46568,6411.38405,0.16273,51.46036,0.58596,29.29809
739.19004,61.59896,6409.96173,0.16274,51.44894,0.58724,29.36217
740.79004,61.73228,6409.07064,0.16273,51.44179,0.58853,29.42627
742.39004,61.86568,6407.70346,0.16282,51.43081,0.58981,29.49040
743.99004,61.99892,6405.05925,0.16267,51.40959,0.59109,29.55446
745.59004,62.13220,6403.02226,0.16268,51.39324,0.59237,29.61854
747.19004,62.26580,6403.36350,0.16276,51.39598,0.59366,29.68277
748.79004,62.39892,6402.81737,0.16278,51.39160,0.59494,29.74676
750.39004,62.53224,6403.08186,0.16270,51.39372,0.59622,29.81086
751.99004,62.66564,6403.28899,0.16270,51.39538,0.59750,29.87500
753.59004,62.79892,6402.44633,0.16276,51.38862,0.59878,29.93908
755.19004,62.93224,6402.69518,0.16276,51.39062,0.60006,30.00317
756.79004,63.06572,6405.30139,0.16271,51.41153,0.60135,30.06734
758.39004,63.19896,6407.65056,0.16271,51.43039,0.60263,30.13140
759.99004,63.33236,6410.52127,0.16276,51.45343,0.60391,30.19554
761.59004,63.46576,6412.85926,0.16276,51.47220,0.60519,30.25967
763.19004,63.59896,6415.80671,0.16271,51.49585,0.60647,30.32371
764.79004,63.73236,6418.08137,0.16271,51.51411,0.60776,30.38784
766.39004,63.86572,6421.44158,0.16275,51.54108,0.60904,30.45196
767.99004,63.99896,6423.72072,0.16275,51.55938,0.61032,30.51602
769.59004,64.13220,6427.41770,0.16273,51.58905,0.61160,30.58007
771.19004,64.26572,6432.15328,0.16272,51.62706,0.61289,30.64426
772.79004,64.39892,6435.92402,0.16275,51.65732,0.61417,30.70830
774.39004,64.53220,6441.57380,0.16273,51.70267,0.61545,30.77238
775.99004,64.66560,6445.91451,0.16272,51.73751,0.61673,30.83652
777.59004,64.79897,6450.46160,0.16273,51.77401,0.61801,30.90063
779.19004,64.93220,6455.66359,0.16274,51.81576,0.61929,30.96469
780.79004,65.06564,6459.92309,0.16272,51.84995,0.62058,31.02884
782.39004,65.19896,6466.46768,0.16273,51.90248,0.62186,31.09294
783.99004,65.33236,6472.72989,0.16275,51.95274,0.62314,31.15707
785.59004,65.46580,6479.10759,0.16272,52.00393,0.62442,31.22122
787.19004,65.59900,6483.75079,0.16270,52.04120,0.62571,31.28526
788.79004,65.73236,6489.25602,0.16275,52.08539,0.62699,31.34938
790.39004,65.86588,6495.09132,0.16275,52.13222,0.62827,31.41357
791.99004,65.99905,6501.17844,0.16272,52.18108,0.62955,31.47759
793.59004,66.13236,6507.51293,0.16271,52.23193,0.63083,31.54169
795.19004,66.26588,6514.82642,0.16275,52.29063,0.63212,31.60588
796.79004,66.39896,6520.70567,0.16269,52.33782,0.63340,31.66986
798.39004,66.53232,6528.35518,0.16283,52.39921,0.63468,31.73398
799.99004,66.66576,6534.94373,0.16277,52.45210,0.63596,31.79813
801.59004,66.79904,6541.39295,0.16267,52.50386,0.63724,31.86221
803.19004,66.93232,6548.42257,0.16270,52.56028,0.63853,31.92629
804.79004,67.06584,6557.04513,0.16277,52.62949,0.63981,31.99048
806.39004,67.19900,6563.23433,0.16275,52.67917,0.64109,32.05450
807.99004,67.33236,6570.52398,0.16269,52.73768,0.64237,32.11861
809.59004,67.46580,6578.18764,0.16272,52.79919,0.64366,32.18277
811.19004,67.59896,6585.51529,0.16277,52.85800,0.64494,32.24678
812.79004,67.73232,6591.82221,0.16273,52.90863,0.64622,32.31090
814.39004,67.86580,6599.73249,0.16270,52.97212,0.64750,32.37507
815.99004,67.99896,6606.47005,0.16273,53.02620,0.64878,32.43909
817.59004,68.13232,6614.12105,0.16274,53.08761,0.65006,32.50321
819.19004,68.26584,6622.27795,0.16272,53.15308,0.65135,32.56740
820.79004,68.39896,6630.12341,0.16270,53.21605,0.65263,32.63140
822.39004,68.53224,6637.34823,0.16274,53.27404,0.65391,32.69548
823.99004,68.66572,6645.26746,0.16274,53.33760,0.65519,32.75965
825.59004,68.79896,6651.10424,0.16273,53.38445,0.65647,32.82371
827.19004,68.93224,6657.91705,0.16273,53.43913,0.65776,32.88778
828.79004,69.06564,6665.42500,0.16273,53.49939,0.65904,32.95192
830.39004,69.19885,6673.05812,0.16276,53.56066,0.66032,33.01596
831.99004,69.33216,6680.12723,0.16278,53.61740,0.66160,33.08005
833.59004,69.46564,6689.75338,0.16273,53.69466,0.66288,33.14423
835.19004,69.59892,6697.16373,0.16268,53.75414,0.66417,33.20830
836.79004,69.73220,6704.27606,0.16275,53.81123,0.66545,33.27238
838.39004,69.86576,6710.25813,0.16276,53.85924,0.66673,33.33659
839.99004,69.99892,6716.44583,0.16272,53.90891,0.66801,33.40061
841.59004,70.13220,6722.50018,0.16272,53.95750,0.66929,33.46469
843.19004,70.26580,6729.23252,0.16274,54.01154,0.67058,33.52892
844.79004,70.39900,6736.90811,0.16275,54.07314,0.67186,33.59296
846.39004,70.53224,6743.98020,0.16273,54.12991,0.67314,33.65702
847.99004,70.66564,6751.34510,0.16273,54.18902,0.67442,33.72115
849.59004,70.79892,6759.18236,0.16274,54.25193,0.67570,33.78523
851.19004,70.93220,6766.20379,0.16275,54.30828,0.67699,33.84930
852.79004,71.06569,6773.50909,0.16272,54.36692,0.67827,33.91348
854.39004,71.19884,6779.92329,0.16275,54.41840,0.67955,33.97750
855.99004,71.33220,6788.08615,0.16274,54.48392,0.68083,34.04161
857.59004,71.46564,6794.58827,0.16272,54.53611,0.68212,34.10576
859.19004,71.59880,6800.95330,0.16271,54.58720,0.68340,34.16979
860.79004,71.73220,6806.95698,0.16273,54.63538,0.68468,34.23392
862.39004,71.86572,6813.08731,0.16274,54.68459,0.68596,34.29811
863.99004,71.99889,6819.07386,0.16274,54.73264,0.68724,34.36213
865.59004,72.13213,6825.26603,0.16271,54.78234,0.68852,34.42619
867.19004,72.26577,6832.62125,0.16274,54.84138,0.68981,34.49044
868.79004,72.39901,6839.27760,0.16274,54.89480,0.69109,34.55450
870.39004,72.53224,6846.67602,0.16275,54.95419,0.69237,34.61855
871.99004,72.66580,6854.21973,0.16273,55.01473,0.69366,34.68277
873.59004,72.79908,6859.91123,0.16275,55.06042,0.69494,34.74684
875.19004,72.93228,6865.25851,0.16274,55.10334,0.69622,34.81088
876.79004,73.06584,6872.94602,0.16272,55.16504,0.69750,34.87509
878.39004,73.19904,6880.63055,0.16273,55.22672,0.69878,34.93913
879.99004,73.33240,6887.78535,0.16275,55.28415,0.70006,35.00325
881.59004,73.46576,6894.62200,0.16274,55.33902,0.70135,35.06736
883.19004,73.59904,6901.53018,0.16273,55.39447,0.70263,35.13144
884.79004,73.73232,6907.39676,0.16272,55.44155,0.70391,35.19552
886.39004,73.86580,6913.68133,0.16274,55.49200,0.70519,35.25969
887.99004,73.99908,6919.67383,0.16275,55.54010,0.70648,35.32377
889.59004,74.13232,6925.74531,0.16272,55.58883,0.70776,35.38782
891.19004,74.26588,6934.40288,0.16272,55.65832,0.70904,35.45203
892.79004,74.39908,6941.59195,0.16272,55.71602,0.71032,35.51607
894.39004,74.53232,6948.01882,0.16276,55.76760,0.71160,35.58013
895.99004,74.66584,6955.76966,0.16273,55.82982,0.71289,35.64432
897.59004,74.79908,6961.69138,0.16271,55.87735,0.71417,35.70838
899.19004,74.93232,6967.74498,0.16272,55.92593,0.71545,35.77244
900.79004,75.06581,6974.49222,0.16273,55.98009,0.71673,35.83662
902.39004,75.19905,6981.81540,0.16272,56.03887,0.71801,35.90067
903.99004,75.33232,6987.24687,0.16273,56.08246,0.71929,35.96474
905.59004,75.46572,6994.75408,0.16277,56.14272,0.72058,36.02888
907.19004,75.59900,6999.94862,0.16272,56.18441,0.72186,36.09296
908.79004,75.73225,7005.25567,0.16272,56.22701,0.72314,36.15702
910.39004,75.86569,7012.00515,0.16274,56.28118,0.72442,36.22117
911.99004,75.99896,7017.87546,0.16273,56.32830,0.72570,36.28524
913.59004,76.13224,7024.32469,0.16272,56.38007,0.72699,36.34932
915.19004,76.26576,7031.22020,0.16274,56.43541,0.72827,36.41351
916.79004,76.39900,7038.31911,0.16273,56.49239,0.72955,36.47757
918.39004,76.53220,7045.25709,0.16274,56.54808,0.73083,36.54161
919.99004,76.66564,7052.13249,0.16273,56.60326,0.73212,36.60576
921.59004,76.79896,7058.02143,0.16273,56.65053,0.73340,36.66986
923.19004,76.93228,7064.53174,0.16274,56.70278,0.73468,36.73396
924.79004,77.06564,7070.77533,0.16273,56.75290,0.73596,36.79808
926.39004,77.19888,7077.37580,0.16274,56.80588,0.73724,36.86213
927.99004,77.33216,7082.79610,0.16273,56.84938,0.73852,36.92621
929.59004,77.46568,7089.78251,0.16273,56.90546,0.73981,36.99040
931.19004,77.59892,7095.50828,0.16269,56.95141,0.74109,37.05446
932.79004,77.73221,7100.10082,0.16273,56.98828,0.74237,37.11854
934.39004,77.86568,7105.03757,0.16275,57.02790,0.74365,37.18271
935.99004,77.99892,7110.24404,0.16275,57.06969,0.74494,37.24676
937.59004,78.13212,7116.11584,0.16273,57.11682,0.74622,37.31081
939.19004,78.26572,7122.55463,0.16271,57.16850,0.74750,37.37504
940.79004,78.39897,7128.69316,0.16272,57.21777,0.74878,37.43910
942.39004,78.53220,7134.50760,0.16274,57.26444,0.75006,37.50315
943.99004,78.66560,7139.53897,0.16275,57.30482,0.75135,37.56729
945.59004,78.79889,7146.06047,0.16276,57.35717,0.75263,37.63136
947.19004,78.93221,7150.99797,0.16274,57.39680,0.75391,37.69546
948.79005,79.06561,7157.71168,0.16273,57.45068,0.75519,37.75960
950.39005,79.19893,7163.37413,0.16271,57.49613,0.75647,37.82369
951.99005,79.33220,7168.69682,0.16264,57.53885,0.75776,37.88776
953.59005,79.46560,7175.91196,0.16274,57.59677,0.75904,37.95190
955.19005,79.59897,7180.42478,0.16279,57.63299,0.76032,38.01602
956.79005,79.73225,7185.90170,0.16274,57.67695,0.76160,38.08010
958.39005,79.86576,7191.73849,0.16270,57.72380,0.76289,38.14429
959.99005,79.99896,7194.04668,0.16273,57.74232,0.76417,38.20832
961.59005,80.13236,7198.12214,0.16277,57.77503,0.76545,38.27246
963.19005,80.26584,7203.52009,0.16272,57.81836,0.76673,38.33663
964.79005,80.39908,7209.20786,0.16271,57.86401,0.76801,38.40069
966.39005,80.53240,7213.09185,0.16274,57.89519,0.76930,38.46479
967.99005,80.66581,7217.50036,0.16275,57.93057,0.77058,38.52892
969.59005,80.79913,7221.10420,0.16274,57.95950,0.77186,38.59302
971.19005,80.93236,7225.66172,0.16272,57.99608,0.77314,38.65707
972.79005,81.06580,7230.63424,0.16273,58.03599,0.77442,38.72123
974.39005,81.19908,7235.29756,0.16276,58.07342,0.77571,38.78530
975.99005,81.33240,7239.02062,0.16275,58.10330,0.77699,38.84940
977.59005,81.46580,7244.71435,0.16272,58.14900,0.77827,38.91353
979.19005,81.59908,7249.27038,0.16271,58.18557,0.77955,38.97761
980.79005,81.73240,7253.32052,0.16273,58.21808,0.78083,39.04171
982.39005,81.86584,7256.65540,0.16274,58.24485,0.78212,39.10586
983.99005,81.99904,7260.95140,0.16273,58.27933,0.78340,39.16990
985.59005,82.13232,7264.38537,0.16276,58.30689,0.78468,39.23398
987.19005,82.26580,7268.65008,0.16274,58.34112,0.78596,39.29815
988.79005,82.39901,7273.40505,0.16271,58.37928,0.78724,39.36219
990.39005,82.53229,7275.99859,0.16272,58.40010,0.78853,39.42627
991.99005,82.66577,7279.52719,0.16272,58.42842,0.78981,39.49044
993.59005,82.79896,7282.80544,0.16272,58.45474,0.79109,39.55448
995.19005,82.93232,7286.05837,0.16273,58.48085,0.79237,39.61859
996.79005,83.06572,7289.81495,0.16276,58.51100,0.79365,39.68273
998.39005,83.19892,7292.16486,0.16273,58.52986,0.79494,39.74677
999.99005,83.33229,7295.73369,0.16273,58.55850,0.79622,39.81088
1001.59005,83.46568,7299.46420,0.16274,58.58845,0.79750,39.87501
1003.19005,83.59892,7302.32894,0.16274,58.61144,0.79878,39.93907
1004.79005,83.73217,7304.44342,0.16273,58.62841,0.80006,40.00314
1006.39005,83.86564,7306.40888,0.16273,58.64419,0.80135,40.06730
1007.99005,83.99888,7309.26096,0.16274,58.66708,0.80263,40.13136
1009.59005,84.13216,7311.73009,0.16274,58.68690,0.80391,40.19544
1011.19005,84.26568,7315.17076,0.16273,58.71451,0.80519,40.25963
1012.79005,84.39893,7316.91718,0.16274,58.72853,0.80647,40.32369
1014.39005,84.53216,7320.00619,0.16274,58.75332,0.80775,40.38775
1015.99005,84.66560,7322.28756,0.16274,58.77164,0.80904,40.45190
1017.59005,84.79896,7324.14350,0.16275,58.78653,0.81032,40.51602
1019.19005,84.93228,7324.89154,0.16275,58.79254,0.81160,40.58011
1020.79005,85.06568,7327.42622,0.16270,58.81288,0.81288,40.64425
1022.39005,85.19884,7329.99146,0.16273,58.83347,0.81417,40.70827
1023.99005,85.33220,7331.08446,0.16276,58.84224,0.81545,40.77238
1025.59005,85.46568,7334.95429,0.16275,58.87330,0.81673,40.83656
1027.19005,85.59885,7336.73200,0.16272,58.88757,0.81801,40.90058
1028.79005,85.73225,7338.28992,0.16277,58.90008,0.81929,40.96471
1030.39005,85.86569,7339.69882,0.16275,58.91139,0.82058,41.02887
1031.99005,85.99884,7340.73222,0.16271,58.91968,0.82186,41.09288
1033.59005,86.13216,7343.71617,0.16272,58.94363,0.82314,41.15697
1035.19005,86.26568,7345.83586,0.16275,58.96064,0.82442,41.22117
1036.79005,86.39893,7348.76394,0.16276,58.98415,0.82570,41.28523
1038.39005,86.53216,7350.26076,0.16273,58.99616,0.82699,41.34928
1039.99005,86.66572,7353.30060,0.16265,59.02056,0.82827,41.41350
1041.59005,86.79892,7354.42042,0.16278,59.02955,0.82955,41.47754
1043.19005,86.93228,7356.27413,0.16280,59.04443,0.83083,41.54165
1044.79005,87.06580,7359.02935,0.16272,59.06654,0.83212,41.60584
1046.39005,87.19897,7360.86294,0.16269,59.08126,0.83340,41.66987
1047.99005,87.33236,7362.27483,0.16269,59.09259,0.83468,41.73400
1049.59005,87.46580,7364.99429,0.16276,59.11442,0.83596,41.79815
1051.19005,87.59905,7368.20176,0.16275,59.14016,0.83724,41.86221
1052.79005,87.73240,7369.84760,0.16275,59.15337,0.83853,41.92633
1054.39005,87.86588,7372.12226,0.16270,59.17163,0.83981,41.99049
1055.99005,87.99905,7374.34104,0.16268,59.18944,0.84109,42.05452
1057.59005,88.13237,7375.84606,0.16278,59.20152,0.84237,42.11862
1059.19005,88.26588,7379.72632,0.16278,59.23266,0.84366,42.18280
1060.79005,88.39912,7383.00458,0.16277,59.25897,0.84494,42.24686
1062.39005,88.53232,7385.75086,0.16273,59.28102,0.84622,42.31090
1063.99005,88.66580,7389.14311,0.16271,59.30825,0.84750,42.37507
1065.59005,88.79905,7391.52804,0.16272,59.32739,0.84878,42.43914
1067.19005,88.93237,7393.03529,0.16275,59.33949,0.85006,42.50323
1068.79005,89.06576,7396.46479,0.16275,59.36701,0.85135,42.56736
1070.39005,89.19904,7399.06505,0.16270,59.38788,0.85263,42.63144
1071.99005,89.33237,7402.37981,0.16274,59.41449,0.85391,42.69554
1073.59005,89.46585,7405.81676,0.16276,59.44207,0.85519,42.75971
1075.19005,89.59901,7408.18158,0.16274,59.46106,0.85647,42.82373
1076.79005,89.73232,7411.61928,0.16272,59.48865,0.85776,42.88782
1078.39005,89.86580,7414.38419,0.16273,59.51084,0.85904,42.95200
1079.99005,89.99905,7415.93763,0.16271,59.52331,0.86032,43.01606
1081.59005,90.13224,7418.58333,0.16274,59.54454,0.86160,43.08010
1083.19005,90.26572,7422.91138,0.16276,59.57928,0.86289,43.14427
1084.79005,90.39892,7427.15076,0.16275,59.61331,0.86417,43.20830
1086.39005,90.53221,7430.75311,0.16277,59.64222,0.86545,43.27239
1087.99005,90.66565,7434.13568,0.16270,59.66937,0.86673,43.33654
1089.59005,90.79884,7435.59822,0.16270,59.68111,0.86801,43.40057
1091.19005,90.93220,7439.76831,0.16273,59.71458,0.86929,43.46469
1092.79005,91.06560,7443.66869,0.16279,59.74589,0.87058,43.52882
1094.39005,91.19880,7446.92385,0.16272,59.77202,0.87186,43.59286
1095.99005,91.33221,7450.80933,0.16269,59.80320,0.87314,43.65700
1097.59005,91.46568,7456.28849,0.16273,59.84718,0.87442,43.72117
1099.19005,91.59888,7459.25978,0.16278,59.87103,0.87570,43.78521
1100.79005,91.73216,7463.73460,0.16273,59.90695,0.87699,43.84928
1102.39005,91.86568,7468.06562,0.16273,59.94171,0.87827,43.91348
1103.99005,91.99897,7472.62761,0.16275,59.97833,0.87955,43.97756
1105.59005,92.13217,7476.64571,0.16273,60.01058,0.88083,44.04160
1107.19005,92.26573,7482.46014,0.16272,60.05725,0.88212,44.10581
1108.79005,92.39896,7488.61432,0.16272,60.10664,0.88340,44.16986
1110.39005,92.53217,7493.54511,0.16274,60.14622,0.88468,44.23391
1111.99005,92.66568,7498.70241,0.16274,60.18761,0.88596,44.29809
1113.59005,92.79888,7502.33904,0.16274,60.21680,0.88724,44.36213
1115.19005,92.93220,7508.14304,0.16276,60.26339,0.88852,44.42623
1116.79005,93.06564,7513.73023,0.16273,60.30823,0.88981,44.49038
1118.39005,93.19892,7519.23621,0.16271,60.35242,0.89109,44.55446
1119.99005,93.33217,7524.83159,0.16276,60.39734,0.89237,44.61852
1121.59005,93.46564,7531.17800,0.16275,60.44827,0.89365,44.68269
1123.19005,93.59892,7536.68472,0.16272,60.49247,0.89494,44.74677
1124.79005,93.73216,7542.35387,0.16272,60.53798,0.89622,44.81082
1126.39005,93.86572,7548.74125,0.16277,60.58924,0.89750,44.87503
1127.99005,93.99896,7554.26064,0.16273,60.63355,0.89878,44.93909
1129.59005,94.13220,7560.33584,0.16272,60.68231,0.90006,45.00315
1131.19005,94.26584,7567.22242,0.16275,60.73758,0.90135,45.06740
1132.79005,94.39908,7573.00034,0.16276,60.78396,0.90263,45.13146
1134.39005,94.53232,7578.63894,0.16272,60.82922,0.90391,45.19552
1135.99005,94.66580,7565.23535,0.16269,60.72163,0.90519,45.25969
1137.59005,94.79912,7576.95362,0.16272,60.81569,0.90648,45.32379
1139.19005,94.93240,7588.45359,0.16276,60.90799,0.90776,45.38786
1140.79005,95.06584,7599.37987,0.16275,60.99569,0.90904,45.45202
1142.39005,95.19904,7607.70887,0.16271,61.06254,0.91032,45.51605
1143.99005,95.33232,7616.80454,0.16273,61.13555,0.91160,45.58013
1145.59005,95.46580,7626.06338,0.16273,61.20986,0.91289,45.64430
1147.19005,95.59904,7634.72095,0.16275,61.27935,0.91417,45.70836
1148.79005,95.73241,7642.13279,0.16275,61.33884,0.91545,45.77248
1150.39005,95.86585,7649.65042,0.16271,61.39918,0.91673,45.83663
1151.99005,95.99912,7656.73593,0.16272,61.45605,0.91801,45.90071
1153.59005,96.13240,7663.27754,0.16276,61.50856,0.91930,45.96478
1155.19005,96.26584,7670.27959,0.16274,61.56476,0.92058,46.02894
1156.79005,96.39912,7676.93296,0.16274,61.61816,0.92186,46.09302
1158.39006,96.53240,7683.84412,0.16271,61.67363,0.92314,46.15710
1159.99006,96.66580,7689.70847,0.16273,61.72070,0.92442,46.22123
1161.59006,96.79896,7695.85371,0.16273,61.77003,0.92570,46.28525
1163.19006,96.93229,7700.94544,0.16275,61.81090,0.92699,46.34934
1164.79006,97.06573,7707.70982,0.16274,61.86519,0.92827,46.41350
1166.39006,97.19896,7713.86549,0.16274,61.91460,0.92955,46.47756
1167.99006,97.33220,7720.57027,0.16273,61.96841,0.93083,46.54161
1169.59006,97.46568,7727.67365,0.16276,62.02543,0.93212,46.60578
1171.19006,97.59888,7733.70117,0.16275,62.07381,0.93340,46.66982
1172.79006,97.73216,7739.12445,0.16274,62.11734,0.93468,46.73390
1174.39006,97.86569,7745.50587,0.16270,62.16856,0.93596,46.79809
1175.99006,97.99896,7751.18470,0.16271,62.21414,0.93724,46.86217
1177.59006,98.13217,7756.84789,0.16273,62.25959,0.93852,46.92621
1179.19006,98.26564,7763.84324,0.16273,62.31574,0.93981,46.99038
1180.79006,98.39892,7769.82307,0.16274,62.36374,0.94109,47.05446
1182.39006,98.53220,7775.56822,0.16275,62.40985,0.94237,47.11853
1183.99006,98.66560,7781.40277,0.16274,62.45668,0.94365,47.18267
1185.59006,98.79892,7786.35442,0.16274,62.49642,0.94494,47.24676
1187.19006,98.93221,7790.82030,0.16277,62.53227,0.94622,47.31085
1188.79006,99.06560,7795.51789,0.16272,62.56997,0.94750,47.37498
1190.39006,99.19892,7801.13116,0.16272,62.61503,0.94878,47.43907
1191.99006,99.33220,7806.25194,0.16275,62.65613,0.95006,47.50315
1193.59006,99.46568,7811.91885,0.16274,62.70161,0.95135,47.56732
1195.19006,99.59889,7817.06423,0.16272,62.74291,0.95263,47.63137
1196.79006,99.73228,7821.48093,0.16276,62.77836,0.95391,47.69550
1198.39006,99.86568,7825.97959,0.16281,62.81447,0.95519,47.75963
1199.99006,99.99892,7831.03555,0.16272,62.85505,0.95647,47.82369
1201.59006,100.13224,7834.80257,0.16277,62.88529,0.95776,47.88778
1203.19006,100.26568,7840.01946,0.16269,62.92716,0.95904,47.95194
1204.79006,100.39897,7844.47566,0.16274,62.96293,0.96032,48.01602
1206.39006,100.53220,7843.93921,0.16278,62.95862,0.96160,48.08007
1207.99006,100.66564,7840.41286,0.16275,62.93032,0.96288,48.14423
1209.59006,100.79896,7846.99842,0.16273,62.98318,0.96417,48.20833
1211.19006,100.93228,7854.00644,0.16277,63.03943,0.96545,48.27242
1212.79006,101.06568,7860.96230,0.16276,63.09526,0.96673,48.33655
1214.39006,101.19893,7867.37353,0.16269,63.14672,0.96801,48.40062
1215.99006,101.33228,7873.34964,0.16268,63.19468,0.96929,48.46473
1217.59006,101.46576,7880.11774,0.16278,63.24901,0.97058,48.52890
1219.19006,101.59899,7885.08132,0.16275,63.28885,0.97186,48.59296
1220.79006,101.73236,7890.20881,0.16271,63.33000,0.97314,48.65707
1222.39006,101.86576,7894.57783,0.16289,63.36507,0.97442,48.72121
1223.99006,101.99904,7898.84105,0.16266,63.39929,0.97571,48.78529
1225.59006,102.13236,7902.94409,0.16274,63.43222,0.97699,48.84938
1227.19006,102.26588,7907.98813,0.16280,63.47270,0.97827,48.91357
1228.79006,102.39908,7912.57769,0.16274,63.50954,0.97955,48.97761
1230.39006,102.53244,7916.98173,0.16271,63.54489,0.98083,49.04173
1231.99006,102.66584,7922.35807,0.16272,63.58804,0.98212,49.10586
1233.59006,102.79904,7926.59670,0.16277,63.62206,0.98340,49.16990
1235.19006,102.93240,7930.24972,0.16275,63.65139,0.98468,49.23401
1236.79006,103.06584,7935.10750,0.16273,63.69038,0.98596,49.29817
1238.39006,103.19904,7939.61287,0.16276,63.72654,0.98724,49.36221
1239.99006,103.33233,7944.19646,0.16276,63.76333,0.98853,49.42629
1241.59006,103.46577,7948.94174,0.16277,63.80142,0.98981,49.49044
1243.19006,103.59904,7954.01707,0.16274,63.84215,0.99109,49.55451
1244.79006,103.73232,7958.62079,0.16273,63.87910,0.99237,49.61859
1246.39006,103.86572,7963.21109,0.16277,63.91595,0.99365,49.68273
1247.99006,103.99900,7967.44600,0.16275,63.94994,0.99494,49.74680
1249.59006,104.13224,7972.42522,0.16270,63.98990,0.99622,49.81086
1251.19006,104.26568,7978.56525,0.16273,64.03919,0.99750,49.87502
1252.57806,104.38144,7982.49692,0.16273,64.07074,0.99861,49.93067