File: Calibration Data/test_PC_ASTM638.is_tens_RawData/Specimen_RawData_5.csv
Operator,"Quentin Govignon"
Our Reference Number,""
Customer Reference,""
Temperature (°C),21.0
Humidity (%),50.
Load Frame,"Instron Model 1185"
Crosshead Speed 1,5.00,mm/min
Extensometer G.L.,"50 mm"
Specimen Name,"PC #5"
Geometry,Rectangular
Length,104.00,mm
Maximum Load,8063.42438,N
Maximum Tensile stress,64.64185,MPa
Modulus (Chord 0.05 % - 0.25 %),2387.53285,MPa
Modulus (Young's 0.025 % - 0.5 %),2609.70664,MPa
Extension at Break (Standard),93.42308,mm
Specimen note 1,""
Specimen note 2,""
Specimen note 3,""

Time,Extension,Load,Strain 1,Tensile stress,Tensile strain,Tensile extension
(sec),(mm),(N),(mm/mm),(MPa),(mm/mm),(mm)
0.00000,-0.00004,-0.30637,-0.00001,-0.00246,-0.00001,-0.00025
1.45000,0.12052,239.72602,0.00076,1.92181,0.00076,0.03799
2.90000,0.24164,514.00471,0.00167,4.12061,0.00167,0.08368
4.35000,0.36248,795.49709,0.00264,6.37724,0.00264,0.13219
5.80000,0.48336,1063.77676,0.00358,8.52795,0.00358,0.17898
7.25000,0.60420,1344.73909,0.00456,10.78034,0.00456,0.22804
8.70000,0.72496,1608.35385,0.00550,12.89365,0.00550,0.27507
10.15000,0.84588,1869.67496,0.00643,14.98858,0.00643,0.32165
11.60000,0.96656,2132.90639,0.00740,17.09882,0.00740,0.37018
13.05000,1.08752,2384.42831,0.00834,19.11519,0.00834,0.41702
14.50000,1.20828,2633.37307,0.00928,21.11090,0.00928,0.46405
15.95000,1.32896,2883.35998,0.01025,23.11496,0.01025,0.51268
17.40000,1.45008,3123.22956,0.01120,25.03792,0.01120,0.56002
18.85000,1.57084,3354.12361,0.01214,26.88892,0.01214,0.60690
20.30000,1.69172,3585.85157,0.01310,28.74661,0.01310,0.65522
21.75000,1.81248,3807.15951,0.01405,30.52076,0.01405,0.70234
23.20000,1.93320,4018.09588,0.01498,32.21177,0.01498,0.74907
24.65000,2.05416,4224.96609,0.01594,33.87018,0.01594,0.79679
26.10000,2.17500,4436.09618,0.01692,35.56274,0.01692,0.84608
27.55000,2.29580,4630.15810,0.01786,37.11847,0.01786,0.89321
29.00000,2.41660,4820.22204,0.01883,38.64215,0.01883,0.94134
30.45000,2.53740,5011.31602,0.01982,40.17409,0.01982,0.99101
31.90000,2.65836,5185.50910,0.02077,41.57054,0.02077,1.03840
33.35000,2.77924,5365.44025,0.02177,43.01299,0.02177,1.08845
34.80000,2.90004,5525.78233,0.02272,44.29840,0.02272,1.13605
36.25000,3.02088,5672.75994,0.02364,45.47667,0.02364,1.18201
37.70000,3.14168,5835.84122,0.02466,46.78404,0.02466,1.23311
39.15000,3.26268,5959.60096,0.02552,47.77618,0.02552,1.27604
40.60000,3.38328,6110.31950,0.02655,48.98444,0.02655,1.32750
42.05000,3.50404,6219.73611,0.02738,49.86160,0.02738,1.36910
43.50000,3.62496,6363.31737,0.02843,51.01265,0.02843,1.42162
44.95000,3.74584,6462.24096,0.02926,51.80568,0.02926,1.46296
46.40000,3.86668,6547.17460,0.03007,52.48657,0.03007,1.50360
47.85000,3.98744,6678.98208,0.03111,53.54323,0.03111,1.55562
49.30000,4.10828,6753.12281,0.03192,54.13759,0.03192,1.59624
50.75000,4.22924,6875.79513,0.03298,55.12101,0.03298,1.64891
52.20000,4.35000,6983.95967,0.03402,55.98813,0.03402,1.70109
53.65000,4.47092,7051.92089,0.03484,56.53296,0.03484,1.74207
55.10000,4.59172,7152.44785,0.03590,57.33885,0.03590,1.79489
56.55000,4.71256,7208.63938,0.03672,57.78932,0.03672,1.83608
58.00000,4.83340,7304.41958,0.03780,58.55716,0.03780,1.88986
59.45000,4.95408,7390.88804,0.03889,59.25034,0.03889,1.94457
60.90000,5.07500,7434.48883,0.03973,59.59988,0.03973,1.98674
62.35000,5.19584,7517.33556,0.04086,60.26403,0.04086,2.04311
63.80000,5.31652,7591.78847,0.04201,60.86090,0.04201,2.10027
65.25000,5.43744,7611.51984,0.04289,61.01908,0.04289,2.14442
66.70000,5.55836,7691.87286,0.04408,61.66324,0.04408,2.20383
68.15000,5.67916,7754.83102,0.04527,62.16796,0.04527,2.26341
69.60000,5.80000,7812.35546,0.04651,62.62911,0.04651,2.32556
71.05000,5.92072,7861.50843,0.04777,63.02316,0.04777,2.38857
72.50000,6.04176,7853.53929,0.04874,62.95927,0.04874,2.43700
73.95000,6.16256,7914.14455,0.05004,63.44512,0.05004,2.50217
75.40000,6.28340,7956.07045,0.05137,63.78123,0.05137,2.56853
76.85000,6.40420,7992.58575,0.05275,64.07396,0.05275,2.63752
78.30000,6.52496,8018.78795,0.05417,64.28401,0.05417,2.70869
79.75000,6.64576,8040.34844,0.05565,64.45686,0.05565,2.78245
81.20000,6.76660,8053.16195,0.05717,64.55958,0.05717,2.85842
82.65000,6.88748,8060.11111,0.05872,64.61529,0.05872,2.93615
84.10000,7.00824,8062.70018,0.06035,64.63604,0.06035,3.01748
85.55000,7.12908,8058.17395,0.06202,64.59976,0.06202,3.10092
87.00000,7.25004,8049.07084,0.06375,64.52678,0.06375,3.18757
88.45000,7.37084,8034.10336,0.06553,64.40679,0.06553,3.27636
89.90000,7.49164,8009.70197,0.06738,64.21117,0.06738,3.36885
91.35000,7.61256,7980.80936,0.06930,63.97955,0.06930,3.46479
92.78000,7.73148,7941.23635,0.07123,63.66231,0.07077,3.53841
94.23000,7.85240,7890.92109,0.07330,63.25895,0.07193,3.59654
95.68000,7.97328,7822.00024,0.01336,62.70643,0.07309,3.65466
97.13000,8.09392,7717.88135,0.18583,61.87174,0.07425,3.71266
98.58000,8.21476,7504.11823,0.23330,60.15807,0.07542,3.77076
100.03000,8.33560,6761.65596,0.22936,54.20600,0.07658,3.82885
101.48000,8.45660,6061.79163,0.22445,48.59541,0.07774,3.88703
102.93000,8.57732,5865.96355,0.22405,47.02552,0.07890,3.94506
104.38000,8.69808,5799.52449,0.20106,46.49290,0.08006,4.00312
105.83001,8.81896,5776.68995,0.20998,46.30984,0.08122,4.06124
107.28001,8.93980,5770.36217,0.23303,46.25912,0.08239,4.11933
108.73001,9.06076,5772.20097,0.24631,46.27386,0.08355,4.17749
110.18001,9.18148,5776.17139,0.25150,46.30569,0.08471,4.23553
111.63001,9.30244,5781.09734,0.23477,46.34518,0.08587,4.29368
113.08001,9.42320,5787.08723,0.32416,46.39320,0.08703,4.35174
114.53001,9.54404,5791.61830,0.32080,46.42952,0.08820,4.40983
115.98001,9.66492,5795.60734,0.13807,46.46150,0.08936,4.46795
117.43001,9.78552,5798.74106,0.14160,46.48662,0.09052,4.52593
118.88001,9.90636,5801.63114,0.11449,46.50979,0.09168,4.58402
120.33001,10.02728,5807.54131,0.14672,46.55717,0.09284,4.64216
121.78001,10.14816,5812.28137,0.14512,46.59517,0.09401,4.70028
123.23001,10.26908,5817.36527,0.14537,46.63592,0.09517,4.75841
124.68001,10.38976,5821.43292,0.14514,46.66853,0.09633,4.81643
126.13001,10.51064,5825.09562,0.14523,46.69790,0.09749,4.87454
127.58001,10.63164,5829.35512,0.14527,46.73204,0.09865,4.93272
129.03001,10.75248,5830.66754,0.14519,46.74256,0.09982,4.99081
130.48001,10.87336,5832.52572,0.14522,46.75746,0.10098,5.04893
131.93001,10.99404,5835.36290,0.14528,46.78021,0.10214,5.10695
133.38001,11.11480,5836.61683,0.14516,46.79026,0.10330,5.16501
134.83001,11.23564,5839.77439,0.14527,46.81557,0.10446,5.22310
136.28001,11.35644,5840.66622,0.14526,46.82272,0.10562,5.28118
137.73001,11.47728,5841.84639,0.14521,46.83218,0.10679,5.33928
139.18001,11.59816,5842.89134,0.14521,46.84056,0.10795,5.39739
140.63001,11.71892,5842.90922,0.14522,46.84070,0.10911,5.45545
142.08001,11.83976,5844.73051,0.14525,46.85530,0.11027,5.51354
143.53001,11.96064,5846.14947,0.14522,46.86668,0.11143,5.57166
144.98001,12.08160,5846.60359,0.14521,46.87032,0.11260,5.62981
146.43001,12.20236,5847.98269,0.14528,46.88137,0.11376,5.68787
147.88001,12.32312,5847.66455,0.14519,46.87882,0.11492,5.74593
149.33001,12.44408,5850.10350,0.14520,46.89838,0.11608,5.80408
150.78001,12.56496,5849.82783,0.14524,46.89617,0.11724,5.86220
152.23001,12.68572,5849.36626,0.14522,46.89247,0.11841,5.92026
153.68001,12.80632,5849.41655,0.14522,46.89287,0.11956,5.97824
155.13001,12.92720,5849.28393,0.14525,46.89181,0.12073,6.03635
156.58001,13.04824,5851.66216,0.14520,46.91087,0.12189,6.09454
158.03001,13.16900,5851.09703,0.14519,46.90634,0.12305,6.15260
159.48001,13.28972,5851.47254,0.14524,46.90935,0.12421,6.21064
160.93001,13.41060,5854.73180,0.14527,46.93548,0.12538,6.26876
162.38001,13.53144,5854.30078,0.14524,46.93202,0.12654,6.32685
163.83001,13.65244,5854.88789,0.14520,46.93673,0.12770,6.38503
165.28001,13.77324,5854.19238,0.14524,46.93116,0.12886,6.44310
166.73001,13.89408,5853.88653,0.14525,46.92870,0.13002,6.50120
168.18001,14.01488,5854.97022,0.14521,46.93739,0.13119,6.55927
169.63001,14.13572,5854.73180,0.14522,46.93548,0.13235,6.61737
171.08001,14.25668,5856.85410,0.14523,46.95249,0.13351,6.67553
172.53001,14.37728,5858.08568,0.14523,46.96237,0.13467,6.73351
173.98001,14.49808,5858.03576,0.14519,46.96197,0.13583,6.79158
175.43001,14.61888,5859.37761,0.14523,46.97272,0.13699,6.84966
176.88001,14.73976,5859.88313,0.14525,46.97678,0.13816,6.90777
178.33001,14.86068,5860.83643,0.14523,46.98442,0.13932,6.96591
179.78001,14.98148,5859.23567,0.14523,46.97159,0.14048,7.02399
181.23001,15.10232,5859.06692,0.14528,46.97023,0.14164,7.08208
182.68001,15.22320,5861.39821,0.14520,46.98892,0.14280,7.14020
184.13001,15.34400,5861.13594,0.14522,46.98682,0.14397,7.19828
185.58001,15.46500,5863.03286,0.14521,47.00203,0.14513,7.25645
187.03001,15.58572,5863.74849,0.14528,47.00776,0.14629,7.31449
188.48001,15.70648,5863.37000,0.14522,47.00473,0.14745,7.37254
189.93001,15.82744,5865.01770,0.14517,47.01794,0.14861,7.43070
191.38001,15.94808,5864.03944,0.14525,47.01010,0.14977,7.48870
192.83001,16.06896,5866.11629,0.14526,47.02675,0.15094,7.54681
194.28001,16.18980,5865.59214,0.14519,47.02254,0.15210,7.60491
195.73001,16.31052,5865.11120,0.14520,47.01869,0.15326,7.66295
197.18001,16.43148,5868.65395,0.14526,47.04709,0.15442,7.72110
198.63001,16.55224,5869.17661,0.14527,47.05128,0.15558,7.77916
200.08001,16.67324,5869.41652,0.14521,47.05320,0.15675,7.83733
201.53001,16.79400,5869.24143,0.14521,47.05180,0.15791,7.89539
202.98001,16.91484,5869.07864,0.14525,47.05049,0.15907,7.95349
204.43001,17.03572,5871.06422,0.14527,47.06641,0.16023,8.01160
205.88001,17.15664,5871.68932,0.14522,47.07142,0.16139,8.06974
207.33001,17.27752,5872.76630,0.14514,47.08006,0.16256,8.12785
208.78001,17.39824,5874.61330,0.14524,47.09486,0.16372,8.18589
210.23001,17.51888,5874.12007,0.14524,47.09091,0.16488,8.24389
211.68001,17.63972,5875.60982,0.14519,47.10285,0.16604,8.30199
213.13001,17.76060,5876.02146,0.14523,47.10615,0.16720,8.36010
214.58001,17.88148,5876.37648,0.14525,47.10900,0.16836,8.41822
216.03001,18.00224,5877.51977,0.14524,47.11816,0.16953,8.47627
217.48001,18.12300,5878.80835,0.14522,47.12849,0.17069,8.53433
218.93001,18.24404,5883.46794,0.14519,47.16585,0.17185,8.59253
220.38001,18.36488,5883.13863,0.14521,47.16321,0.17301,8.65062
221.83001,18.48576,5882.87003,0.14526,47.16106,0.17417,8.70874
223.28001,18.60660,5883.81067,0.14521,47.16860,0.17534,8.76683
224.73001,18.72736,5882.70463,0.14524,47.15973,0.17650,8.82489
226.18001,18.84828,5882.87860,0.14524,47.16112,0.17766,8.88303
227.63001,18.96908,5883.08536,0.14522,47.16278,0.17882,8.94110
229.08001,19.08980,5883.62850,0.14522,47.16714,0.17998,8.99914
230.53001,19.21060,5886.30177,0.14521,47.18857,0.18114,9.05722
231.98001,19.33124,5886.14829,0.14522,47.18734,0.18230,9.11522
233.43001,19.45236,5888.90351,0.14525,47.20942,0.18347,9.17345
234.88001,19.57320,5889.52489,0.14522,47.21441,0.18463,9.23154
236.33001,19.69388,5889.42878,0.14520,47.21363,0.18579,9.28956
237.78001,19.81476,5890.78628,0.14527,47.22452,0.18695,9.34768
239.23001,19.93568,5891.26498,0.14524,47.22835,0.18812,9.40581
240.68001,20.05660,5891.16402,0.14522,47.22755,0.18928,9.46395
242.13001,20.17748,5892.78676,0.14518,47.24055,0.19044,9.52206
243.58001,20.29820,5892.40454,0.14522,47.23749,0.19160,9.58010
245.03001,20.41908,5895.54757,0.14528,47.26269,0.19276,9.63822
246.48001,20.53984,5896.12275,0.14522,47.26730,0.19393,9.69627
247.93001,20.66064,5896.87936,0.14519,47.27336,0.19509,9.75435
249.38001,20.78140,5896.80560,0.14525,47.27277,0.19625,9.81241
250.83001,20.90228,5898.17390,0.14524,47.28374,0.19741,9.87053
252.28001,21.02308,5900.16805,0.14521,47.29973,0.19857,9.92860
253.73001,21.14388,5900.11775,0.14519,47.29932,0.19973,9.98668
255.18001,21.26492,5902.53584,0.14523,47.31871,0.20090,10.04487
256.63001,21.38564,5904.61530,0.14526,47.33538,0.20206,10.10291
258.08001,21.50656,5905.46057,0.14520,47.34216,0.20322,10.16104
259.53001,21.62748,5907.44950,0.14518,47.35810,0.20438,10.21918
260.98001,21.74828,5907.84363,0.14524,47.36126,0.20555,10.27726
262.43001,21.86912,5907.15297,0.14525,47.35572,0.20671,10.33535
263.88001,21.98996,5907.63241,0.14520,47.35957,0.20787,10.39345
265.33001,22.11068,5908.41323,0.14519,47.36583,0.20903,10.45149
266.78001,22.23140,5910.38465,0.14526,47.38163,0.21019,10.50953
268.23001,22.35228,5911.33609,0.14525,47.38926,0.21135,10.56764
269.68001,22.47312,5912.49131,0.14524,47.39852,0.21251,10.62574
271.13001,22.59392,5913.31907,0.14524,47.40516,0.21368,10.68381
272.58001,22.71472,5913.60219,0.14522,47.40742,0.21484,10.74189
274.03001,22.83556,5915.61422,0.14522,47.42355,0.21600,10.79999
275.48001,22.95652,5915.78595,0.14522,47.42493,0.21716,10.85814
276.93001,23.07736,5917.70075,0.14528,47.44028,0.21832,10.91624
278.38001,23.19820,5918.43873,0.14520,47.44620,0.21949,10.97433
279.83001,23.31896,5917.63332,0.14518,47.43974,0.22065,11.03239
281.28001,23.43988,5921.45696,0.14522,47.47039,0.22181,11.09053
282.73001,23.56072,5921.50055,0.14524,47.47074,0.22297,11.14862
284.18001,23.68164,5921.00322,0.14518,47.46676,0.22414,11.20676
285.63001,23.80224,5921.73822,0.14519,47.47265,0.22529,11.26474
287.08001,23.92300,5921.35563,0.14526,47.46958,0.22646,11.32279
288.53001,24.04400,5924.03039,0.14526,47.49102,0.22762,11.38097
289.98001,24.16480,5924.24572,0.14523,47.49275,0.22878,11.43905
291.43001,24.28560,5925.54063,0.14516,47.50313,0.22994,11.49712
292.88001,24.40636,5928.61101,0.14521,47.52775,0.23110,11.55518
294.33001,24.52720,5928.91946,0.14525,47.53022,0.23227,11.61328
295.78001,24.64824,5930.21661,0.14530,47.54062,0.23343,11.67147
297.23001,24.76904,5930.61857,0.14524,47.54384,0.23459,11.72954
298.68001,24.88992,5930.12162,0.14519,47.53986,0.23575,11.78766
300.13001,25.01072,5931.12223,0.14524,47.54788,0.23691,11.84574
301.58001,25.13160,5930.64837,0.14525,47.54408,0.23808,11.90385
303.03001,25.25244,5933.38385,0.14523,47.56601,0.23924,11.96195
304.48001,25.37308,5933.67442,0.14520,47.56834,0.24040,12.01995
305.93001,25.49396,5934.58861,0.14523,47.57567,0.24156,12.07806
307.38001,25.61480,5936.38010,0.14527,47.59003,0.24272,12.13616
308.83001,25.73556,5934.54018,0.14523,47.57528,0.24388,12.19422
310.28001,25.85640,5935.88427,0.14523,47.58605,0.24505,12.25231
311.73001,25.97732,5935.58401,0.14524,47.58365,0.24621,12.31045
313.18001,26.09816,5936.32646,0.14521,47.58960,0.24737,12.36854
314.63001,26.21900,5939.27167,0.14523,47.61321,0.24853,12.42664
316.08002,26.33984,5940.50996,0.14522,47.62314,0.24969,12.48474
317.53002,26.46092,5941.94792,0.14525,47.63466,0.25086,12.54295
318.98002,26.58160,5942.59650,0.14524,47.63986,0.25202,12.60097
320.43002,26.70236,5941.54261,0.14521,47.63141,0.25318,12.65903
321.88002,26.82316,5943.44139,0.14523,47.64664,0.25434,12.71710
323.33002,26.94392,5943.27115,0.14524,47.64527,0.25550,12.77516
324.78002,27.06480,5944.36899,0.14523,47.65407,0.25667,12.83327
326.23002,27.18556,5944.34887,0.14525,47.65391,0.25783,12.89133
327.68002,27.30640,5944.78697,0.14525,47.65742,0.25899,12.94943
329.13002,27.42732,5947.25683,0.14523,47.67722,0.26015,13.00756
330.58002,27.54808,5948.19337,0.14521,47.68473,0.26131,13.06562
332.03002,27.66900,5948.19859,0.14524,47.68477,0.26248,13.12376
333.48002,27.78988,5948.87845,0.14525,47.69022,0.26364,13.18187
334.93002,27.91068,5948.85610,0.14524,47.69004,0.26480,13.23995
336.38002,28.03168,5950.08731,0.14524,47.69991,0.26596,13.29812
337.83002,28.15248,5951.77040,0.14523,47.71341,0.26712,13.35620
339.28002,28.27340,5952.12243,0.14525,47.71623,0.26829,13.41433
340.73002,28.39396,5952.60970,0.14524,47.72014,0.26945,13.47229
342.18002,28.51476,5951.88849,0.14525,47.71435,0.27061,13.53037
343.63002,28.63564,5954.28012,0.14525,47.73353,0.27177,13.58849
345.08002,28.75644,5954.40380,0.14525,47.73452,0.27293,13.64656
346.53002,28.87732,5954.49433,0.14523,47.73524,0.27409,13.70468
347.98002,28.99800,5955.55976,0.14522,47.74379,0.27525,13.76270
349.43002,29.11884,5956.20312,0.14525,47.74894,0.27642,13.82079
350.88002,29.23980,5958.93525,0.14525,47.77085,0.27758,13.87895
352.33002,29.36072,5960.13702,0.14525,47.78048,0.27874,13.93708
353.78002,29.48164,5960.55724,0.14525,47.78385,0.27990,13.99522
355.23002,29.60240,5960.83254,0.14525,47.78606,0.28107,14.05327
356.68002,29.72316,5960.54494,0.14525,47.78375,0.28223,14.11133
358.13002,29.84412,5961.18160,0.14527,47.78885,0.28339,14.16949
359.58002,29.96488,5960.39332,0.14523,47.78253,0.28455,14.22754
361.03002,30.08552,5960.09605,0.14520,47.78015,0.28571,14.28555
362.48002,30.20644,5963.13365,0.14530,47.80450,0.28687,14.34368
363.93002,30.32716,5962.92801,0.14537,47.80285,0.28803,14.40172
365.38002,30.44808,5965.10619,0.14518,47.82032,0.28920,14.45985
366.83002,30.56896,5965.55956,0.14517,47.82395,0.29036,14.51797
368.28002,30.68968,5963.98152,0.14523,47.81130,0.29152,14.57601
369.73002,30.81056,5965.09501,0.14530,47.82023,0.29268,14.63412
371.18002,30.93144,5965.12035,0.14526,47.82043,0.29384,14.69224
372.63002,31.05248,5966.70881,0.14512,47.83316,0.29501,14.75043
374.08002,31.17332,5967.21284,0.14528,47.83720,0.29617,14.80852
375.53002,31.29400,5967.08506,0.14532,47.83618,0.29733,14.86655
376.98002,31.41492,5969.56089,0.14525,47.85603,0.29849,14.92468
378.43002,31.53568,5969.43870,0.14516,47.85505,0.29965,14.98274
379.88002,31.65656,5971.27341,0.14527,47.86976,0.30082,15.04085
381.33002,31.77736,5970.39200,0.14525,47.86269,0.30198,15.09893
382.78002,31.89804,5970.06455,0.14525,47.86007,0.30314,15.15695
384.23002,32.01892,5971.24696,0.14525,47.86954,0.30430,15.21506
385.68002,32.13968,5970.81818,0.14523,47.86611,0.30546,15.27312
387.13002,32.26068,5972.00356,0.14525,47.87561,0.30663,15.33129
388.58002,32.38140,5973.00977,0.14526,47.88368,0.30779,15.38933
390.03002,32.50240,5972.78513,0.14523,47.88188,0.30895,15.44751
391.48002,32.62320,5974.24619,0.14523,47.89359,0.31011,15.50558
392.93002,32.74408,5974.24880,0.14525,47.89361,0.31127,15.56370
394.38002,32.86500,5974.84857,0.14526,47.89842,0.31244,15.62183
395.83002,32.98588,5974.29276,0.14523,47.89396,0.31360,15.67995
397.28002,33.10648,5974.07408,0.14525,47.89221,0.31476,15.73793
398.73002,33.22728,5976.23438,0.14527,47.90953,0.31592,15.79601
400.18002,33.34812,5975.47777,0.14527,47.90346,0.31708,15.85410
401.63002,33.46900,5975.60704,0.14521,47.90450,0.31824,15.91222
403.08002,33.58976,5975.88569,0.14523,47.90673,0.31941,15.97028
404.53002,33.71044,5974.43171,0.14530,47.89508,0.32057,16.02829
405.98002,33.83144,5975.71060,0.14532,47.90533,0.32173,16.08647
407.43002,33.95240,5975.94865,0.14527,47.90724,0.32289,16.14462
408.88002,34.07324,5977.00439,0.14527,47.91570,0.32405,16.20272
410.33002,34.19400,5978.08324,0.14522,47.92435,0.32522,16.26077
411.78002,34.31488,5978.52543,0.14521,47.92789,0.32638,16.31889
413.23002,34.43576,5980.29979,0.14523,47.94212,0.32754,16.37701
414.68002,34.55668,5979.80209,0.14524,47.93813,0.32870,16.43514
416.13002,34.67740,5979.25037,0.14528,47.93371,0.32986,16.49318
417.58002,34.79808,5978.66997,0.14528,47.92905,0.33102,16.55120
419.03002,34.91884,5978.06610,0.14515,47.92421,0.33219,16.60926
420.48002,35.03976,5978.10447,0.14516,47.92452,0.33335,16.66739
421.93002,35.16060,5978.87002,0.14533,47.93066,0.33451,16.72549
423.38002,35.28148,5979.00674,0.14531,47.93175,0.33567,16.78360
424.83002,35.40224,5980.49797,0.14512,47.94371,0.33683,16.84166
426.28002,35.52300,5979.92390,0.14521,47.93910,0.33799,16.89972
427.73002,35.64404,5981.05267,0.14533,47.94815,0.33916,16.95791
429.18002,35.76488,5979.91869,0.14529,47.93906,0.34032,17.01601
430.63002,35.88584,5979.19859,0.14521,47.93329,0.34148,17.07416
432.08002,36.00664,5978.84320,0.14524,47.93044,0.34264,17.13224
433.53002,36.12736,5978.40585,0.14524,47.92693,0.34381,17.19028
434.98002,36.24816,5980.03864,0.14527,47.94002,0.34497,17.24835
436.43002,36.36896,5980.09638,0.14522,47.94049,0.34613,17.30643
437.88002,36.48976,5980.34225,0.14528,47.94246,0.34729,17.36451
439.33002,36.61052,5981.16890,0.14527,47.94909,0.34845,17.42256
440.78002,36.73136,5980.77439,0.14521,47.94592,0.34961,17.48066
442.23002,36.85224,5981.24564,0.14522,47.94970,0.35078,17.53877
443.68002,36.97312,5982.02087,0.14526,47.95592,0.35194,17.59689
445.13002,37.09400,5981.35851,0.14524,47.95061,0.35310,17.65501
446.58002,37.21484,5983.08966,0.14523,47.96448,0.35426,17.71310
448.03002,37.33568,5983.63429,0.14522,47.96885,0.35542,17.77120
449.48002,37.45664,5985.98979,0.14531,47.98773,0.35659,17.82935
450.93002,37.57748,5986.67450,0.14530,47.99322,0.35775,17.88745
452.38002,37.69828,5984.98769,0.14522,47.97970,0.35891,17.94553
453.83002,37.81900,5986.00991,0.14522,47.98789,0.36007,18.00356
455.28002,37.93972,5985.17135,0.14524,47.98117,0.36123,18.06160
456.73002,38.06072,5985.89554,0.14524,47.98698,0.36240,18.11977
458.18002,38.18144,5985.20897,0.14524,47.98147,0.36356,18.17781
459.63002,38.30228,5984.26759,0.14523,47.97393,0.36472,18.23591
461.08002,38.42308,5986.46291,0.14527,47.99153,0.36588,18.29399
462.53002,38.54388,5985.71599,0.14526,47.98554,0.36704,18.35206
463.98002,38.66484,5985.76330,0.14524,47.98592,0.36820,18.41022
465.43002,38.78572,5985.56511,0.14525,47.98433,0.36937,18.46833
466.88002,38.90652,5984.75374,0.14524,47.97782,0.37053,18.52641
468.33002,39.02748,5986.13657,0.14526,47.98891,0.37169,18.58456
469.78002,39.14824,5986.52437,0.14524,47.99202,0.37285,18.64262
471.23002,39.26920,5987.04778,0.14522,47.99621,0.37402,18.70078
472.68002,39.38984,5988.37323,0.14527,48.00684,0.37518,18.75878
474.13002,39.51064,5987.78017,0.14529,48.00209,0.37634,18.81685
475.58002,39.63148,5988.13854,0.14526,48.00496,0.37750,18.87495
477.03002,39.75224,5987.95637,0.14521,48.00350,0.37866,18.93301
478.48002,39.87316,5987.99475,0.14521,48.00381,0.37982,18.99114
479.93002,39.99396,5987.45234,0.14527,47.99946,0.38098,19.04922
481.38002,40.11476,5986.89094,0.14527,47.99496,0.38215,19.10729
482.83002,40.23552,5988.66455,0.14524,48.00918,0.38331,19.16535
484.28002,40.35656,5989.37720,0.14521,48.01489,0.38447,19.22355
485.73002,40.47752,5988.27526,0.14523,48.00605,0.38563,19.28170
487.18002,40.59816,5988.43284,0.14521,48.00732,0.38679,19.33970
488.63002,40.71900,5986.33587,0.14524,47.99051,0.38796,19.39779
490.08002,40.83996,5986.82947,0.14525,47.99446,0.38912,19.45595
491.53002,40.96068,5985.41647,0.14524,47.98314,0.39028,19.51399
492.98002,41.08144,5986.03524,0.14524,47.98810,0.39144,19.57205
494.43002,41.20220,5987.84387,0.14522,48.00260,0.39260,19.63010
495.88002,41.32300,5988.72863,0.14525,48.00969,0.39376,19.68818
497.33002,41.44392,5990.33386,0.14526,48.02256,0.39493,19.74631
498.78002,41.56472,5989.49306,0.14521,48.01582,0.39609,19.80439
500.23002,41.68564,5988.86162,0.14520,48.01076,0.39725,19.86253
501.68002,41.80648,5987.69598,0.14524,48.00141,0.39841,19.92062
503.13002,41.92732,5985.86984,0.14525,47.98677,0.39957,19.97872
504.58002,42.04824,5986.72293,0.14526,47.99361,0.40074,20.03685
506.03002,42.16912,5986.38579,0.14526,47.99091,0.40190,20.09497
507.48002,42.28992,5985.75063,0.14526,47.98582,0.40306,20.15304
508.93002,42.41080,5986.93117,0.14525,47.99528,0.40422,20.21116
510.38002,42.53148,5984.58238,0.14525,47.97645,0.40538,20.26918
511.83002,42.65236,5984.91840,0.14525,47.97914,0.40655,20.32730
513.28002,42.77308,5982.96672,0.14525,47.96350,0.40771,20.38534
514.73002,42.89396,5982.45785,0.14525,47.95942,0.40887,20.44345
516.18002,43.01472,5982.34497,0.14525,47.95851,0.41003,20.50151
517.63002,43.13548,5981.70571,0.14525,47.95339,0.41119,20.55956
519.08002,43.25656,5981.93482,0.14525,47.95523,0.41236,20.61778
520.53002,43.37724,5981.87596,0.14526,47.95475,0.41352,20.67580
521.98002,43.49820,5981.39316,0.14529,47.95088,0.41468,20.73395
523.43002,43.61904,5982.56849,0.14525,47.96031,0.41584,20.79204
524.88002,43.73988,5981.40582,0.14524,47.95098,0.41700,20.85014
526.33002,43.86080,5981.88862,0.14524,47.95486,0.41817,20.90828
527.78003,43.98160,5981.83274,0.14522,47.95441,0.41933,20.96635
529.23003,44.10232,5979.95259,0.14525,47.93933,0.42049,21.02439
530.68003,44.22308,5980.15971,0.14526,47.94099,0.42165,21.08245
532.13003,44.34388,5979.63780,0.14525,47.93681,0.42281,21.14053
533.58003,44.46480,5980.06174,0.14524,47.94021,0.42397,21.19866
535.03003,44.58564,5979.75440,0.14524,47.93775,0.42514,21.25676
536.48003,44.70636,5977.75467,0.14523,47.92171,0.42630,21.31480
537.93003,44.82732,5977.91187,0.14524,47.92297,0.42746,21.37295
539.38003,44.94816,5976.64416,0.14524,47.91281,0.42862,21.43105
540.83003,45.06904,5975.31684,0.14525,47.90217,0.42978,21.48916
542.28003,45.18988,5975.13691,0.14526,47.90073,0.43095,21.54726
543.73003,45.31068,5974.49541,0.14525,47.89559,0.43211,21.60533
545.18003,45.43164,5976.15167,0.14531,47.90886,0.43327,21.66349
546.63003,45.55244,5975.24270,0.14534,47.90158,0.43443,21.72156
548.08003,45.67320,5974.01075,0.14517,47.89170,0.43559,21.77962
549.53003,45.79392,5972.91030,0.14514,47.88288,0.43675,21.83766
550.98003,45.91472,5973.98877,0.14528,47.89152,0.43791,21.89574
552.43003,46.03568,5975.02925,0.14531,47.89987,0.43908,21.95389
553.88003,46.15644,5974.70067,0.14530,47.89723,0.44024,22.01195
555.33003,46.27732,5974.80945,0.14520,47.89810,0.44140,22.07006
556.78003,46.39812,5976.36178,0.14524,47.91055,0.44256,22.12814
558.23003,46.51896,5974.75171,0.14517,47.89764,0.44372,22.18624
559.68003,46.63988,5975.93114,0.14526,47.90710,0.44489,22.24437
561.13003,46.76068,5974.94021,0.14528,47.89915,0.44605,22.30245
562.58003,46.88164,5972.93228,0.14525,47.88305,0.44721,22.36060
564.03003,47.00240,5973.21540,0.14520,47.88532,0.44837,22.41866
565.48003,47.12312,5972.48971,0.14520,47.87951,0.44953,22.47670
566.93003,47.24400,5974.93611,0.14526,47.89912,0.45070,22.53481
568.38003,47.36484,5975.09295,0.14525,47.90038,0.45186,22.59291
569.83003,47.48560,5974.56209,0.14527,47.89612,0.45302,22.65097
571.28003,47.60640,5974.66119,0.14522,47.89692,0.45418,22.70905
572.73003,47.72720,5974.14486,0.14525,47.89278,0.45534,22.76712
574.18003,47.84816,5975.32429,0.14527,47.90223,0.45651,22.82528
575.63003,47.96900,5974.25848,0.14525,47.89369,0.45767,22.88337
577.08003,48.08972,5973.25563,0.14527,47.88565,0.45883,22.94141
578.53003,48.21068,5976.99434,0.14525,47.91562,0.45999,22.99957
579.98003,48.33156,5977.78149,0.14526,47.92193,0.46115,23.05768
581.43003,48.45240,5980.42868,0.14525,47.94315,0.46232,23.11578
582.88003,48.57324,5981.70720,0.14522,47.95340,0.46348,23.17387
584.33003,48.69412,5982.04173,0.14524,47.95608,0.46464,23.23199
585.78003,48.81480,5983.03601,0.14525,47.96405,0.46580,23.29001
587.23003,48.93560,5982.70446,0.14526,47.96140,0.46696,23.34808
588.68003,49.05652,5983.68794,0.14526,47.96928,0.46812,23.40622
590.13003,49.17732,5984.48105,0.14526,47.97564,0.46929,23.46430
591.58003,49.29804,5985.49619,0.14525,47.98378,0.47045,23.52233
593.03003,49.41896,5988.69845,0.14523,48.00945,0.47161,23.58047
594.48003,49.53976,5989.51988,0.14521,48.01603,0.47277,23.63854
595.93003,49.66068,5989.82051,0.14522,48.01844,0.47393,23.69668
597.38003,49.78152,5990.62443,0.14526,48.02489,0.47510,23.75477
598.83003,49.90232,5990.95039,0.14528,48.02750,0.47626,23.81285
600.28003,50.02324,5993.30328,0.14526,48.04636,0.47742,23.87099
601.73003,50.14404,5994.40001,0.14525,48.05515,0.47858,23.92906
603.18003,50.26508,5995.92887,0.14522,48.06741,0.47975,23.98726
604.63003,50.38568,5997.18057,0.14524,48.07745,0.48090,24.04524
606.08003,50.50648,5997.33032,0.14528,48.07865,0.48207,24.10331
607.53003,50.62728,5998.60363,0.14527,48.08885,0.48323,24.16139
608.98003,50.74808,6000.19693,0.14525,48.10163,0.48439,24.21947
610.43003,50.86904,6002.77930,0.14525,48.12233,0.48555,24.27762
611.88003,50.98972,6003.84101,0.14525,48.13084,0.48671,24.33564
613.33003,51.11068,6005.36428,0.14526,48.14305,0.48788,24.39379
614.78003,51.23144,6008.14968,0.14526,48.16538,0.48904,24.45185
616.23003,51.35236,6010.01717,0.14527,48.18035,0.49020,24.50999
617.68003,51.47332,6010.60092,0.14525,48.18503,0.49136,24.56814
619.13003,51.59396,6011.91297,0.14525,48.19555,0.49252,24.62614
620.58003,51.71488,6012.13910,0.14527,48.19736,0.49369,24.68427
622.03003,51.83572,6014.45511,0.14529,48.21593,0.49485,24.74237
623.48003,51.95652,6015.76008,0.14525,48.22639,0.49601,24.80045
624.93003,52.07736,6017.37015,0.14523,48.23930,0.49717,24.85855
626.38003,52.19804,6019.50511,0.14525,48.25641,0.49833,24.91656
627.83003,52.31880,6020.99970,0.14526,48.26840,0.49949,24.97462
629.28003,52.43984,6025.09305,0.14526,48.30121,0.50066,25.03281
630.73003,52.56068,6026.95309,0.14525,48.31612,0.50182,25.09091
632.18003,52.68156,6028.56167,0.14526,48.32902,0.50298,25.14903
633.63003,52.80228,6030.65379,0.14526,48.34579,0.50414,25.20707
635.08003,52.92308,6030.66795,0.14521,48.34590,0.50530,25.26514
636.53003,53.04404,6034.12241,0.14524,48.37360,0.50647,25.32329
637.98003,53.16492,6036.15977,0.14528,48.38993,0.50763,25.38141
639.43003,53.28572,6039.79938,0.14527,48.41911,0.50879,25.43949
640.88003,53.40660,6043.15139,0.14522,48.44598,0.50995,25.49760
642.33003,53.52724,6044.11997,0.14525,48.45374,0.51111,25.55560
643.78003,53.64812,6046.65354,0.14525,48.47405,0.51227,25.61372
645.23003,53.76892,6048.43795,0.14525,48.48836,0.51344,25.67180
646.68003,53.88984,6050.91006,0.14526,48.50818,0.51460,25.72993
648.13003,54.01060,6052.90718,0.14526,48.52419,0.51576,25.78799
649.58003,54.13132,6056.67308,0.14527,48.55438,0.51692,25.84603
651.03003,54.25240,6061.86762,0.14529,48.59602,0.51808,25.90424
652.48003,54.37328,6066.25825,0.14527,48.63122,0.51925,25.96235
653.93003,54.49408,6069.63336,0.14513,48.65828,0.52041,26.02043
655.38003,54.61472,6073.56504,0.14525,48.68980,0.52157,26.07843
656.83003,54.73572,6076.96585,0.14532,48.71706,0.52273,26.13660
658.28003,54.85672,6080.69412,0.14530,48.74695,0.52390,26.19477
659.73003,54.97740,6082.10079,0.14523,48.75822,0.52506,26.25280
661.18003,55.09808,6085.29486,0.14523,48.78383,0.52622,26.31082
662.63003,55.21896,6090.13736,0.14530,48.82265,0.52738,26.36893
664.08003,55.33968,6094.66694,0.14528,48.85896,0.52854,26.42697
665.53003,55.46072,6097.68294,0.14526,48.88314,0.52970,26.48516
666.98003,55.58144,6102.53289,0.14523,48.92202,0.53086,26.54320
668.43003,55.70228,6105.86740,0.14526,48.94875,0.53203,26.60129
669.88003,55.82312,6110.47782,0.14527,48.98571,0.53319,26.65939
671.33003,55.94396,6113.24497,0.14527,49.00790,0.53435,26.71749
672.78003,56.06492,6118.17278,0.14524,49.04740,0.53551,26.77564
674.23003,56.18576,6122.86106,0.14529,49.08499,0.53667,26.83374
675.68003,56.30656,6126.65974,0.14531,49.11544,0.53784,26.89181
677.13003,56.42744,6132.66714,0.14526,49.16360,0.53900,26.94993
678.58003,56.54824,6136.95905,0.14522,49.19800,0.54016,27.00801
680.03003,56.66904,6141.28858,0.14523,49.23271,0.54132,27.06608
681.48003,56.78980,6144.64767,0.14526,49.25964,0.54248,27.12414
682.93003,56.91060,6148.41506,0.14527,49.28984,0.54364,27.18222
684.38003,57.03148,6154.45338,0.14526,49.33825,0.54481,27.24033
685.83003,57.15224,6159.21132,0.14526,49.37639,0.54597,27.29839
687.28003,57.27324,6165.41617,0.14525,49.42614,0.54713,27.35656
688.73003,57.39396,6171.58674,0.14526,49.47560,0.54829,27.41460
690.18003,57.51480,6176.20498,0.14526,49.51263,0.54945,27.47270
691.63003,57.63584,6183.00401,0.14526,49.56713,0.55062,27.53089
693.08003,57.75652,6186.62350,0.14530,49.59615,0.55178,27.58891
694.53003,57.87748,6191.29725,0.14525,49.63362,0.55294,27.64706
695.98003,57.99828,6197.34265,0.14522,49.68208,0.55410,27.70514
697.43003,58.11896,6202.71638,0.14526,49.72516,0.55526,27.76316
698.88003,58.23976,6210.23439,0.14528,49.78543,0.55642,27.82124
700.33003,58.36060,6215.75899,0.14525,49.82972,0.55759,27.87933
701.78003,58.48148,6222.58633,0.14526,49.88445,0.55875,27.93745
703.23003,58.60224,6228.30503,0.14525,49.93030,0.55991,27.99551
704.68003,58.72300,6232.64983,0.14525,49.96513,0.56107,28.05357
706.13003,58.84392,6240.54708,0.14527,50.02844,0.56223,28.11170
707.58003,58.96492,6247.02238,0.14527,50.08035,0.56340,28.16987
709.03003,59.08572,6253.02717,0.14525,50.12848,0.56456,28.22795
710.48003,59.20652,6261.03058,0.14525,50.19265,0.56572,28.28603
711.93003,59.32732,6267.01415,0.14528,50.24061,0.56688,28.34410
713.38003,59.44820,6273.33298,0.14528,50.29127,0.56804,28.40222
714.83003,59.56912,6281.47498,0.14527,50.35654,0.56921,28.46035
716.28003,59.68988,6286.67548,0.14527,50.39823,0.57037,28.51841
717.73003,59.81056,6293.06808,0.14523,50.44948,0.57153,28.57643
719.18003,59.93140,6298.42281,0.14522,50.49241,0.57269,28.63453
720.63003,60.05228,6306.48136,0.14526,50.55701,0.57385,28.69264
722.08003,60.17312,6312.68695,0.14529,50.60676,0.57501,28.75074
723.53003,60.29392,6319.57054,0.14526,50.66194,0.57618,28.80881
724.98003,60.41480,6328.06793,0.14523,50.73006,0.57734,28.86693
726.43003,60.53560,6336.61598,0.14524,50.79859,0.57850,28.92500
727.88003,60.65656,6344.31243,0.14528,50.86029,0.57966,28.98316
729.33003,60.77736,6351.06862,0.14527,50.91445,0.58082,29.04124
730.78003,60.89824,6357.70410,0.14524,50.96765,0.58199,29.09935
732.23003,61.01908,6365.68367,0.14521,51.03162,0.58315,29.15745
733.68003,61.13976,6371.90044,0.14524,51.08145,0.58431,29.21547
735.13003,61.26088,6379.94260,0.14528,51.14592,0.58547,29.27370
736.58003,61.38148,6387.55634,0.14527,51.20696,0.58663,29.33168
738.03004,61.50216,6392.77175,0.14526,51.24877,0.58779,29.38970
739.48004,61.62308,6400.17539,0.14523,51.30812,0.58896,29.44783
740.93004,61.74396,6405.99504,0.14527,51.35478,0.59012,29.50595
742.38004,61.86488,6412.63649,0.14528,51.40802,0.59128,29.56408
743.83004,61.98560,6418.30191,0.14527,51.45344,0.59244,29.62212
745.28004,62.10644,6424.49185,0.14526,51.50306,0.59360,29.68022
746.73004,62.22744,6433.58752,0.14525,51.57598,0.59477,29.73839
748.18004,62.34820,6440.78925,0.14525,51.63371,0.59593,29.79645
749.63004,62.46908,6446.34143,0.14523,51.67822,0.59709,29.85456
751.08004,62.58988,6452.01728,0.14526,51.72372,0.59825,29.91264
752.53004,62.71076,6456.62323,0.14525,51.76065,0.59942,29.97075
753.98004,62.83160,6461.27760,0.14525,51.79796,0.60058,30.02885
755.43004,62.95228,6466.08323,0.14526,51.83649,0.60174,30.08687
756.88004,63.07312,6471.12355,0.14527,51.87689,0.60290,30.14497
758.33004,63.19388,6474.54336,0.14525,51.90431,0.60406,30.20302
759.78004,63.31476,6476.94021,0.14524,51.92352,0.60522,30.26114
761.23004,63.43568,6481.59534,0.14523,51.96084,0.60639,30.31927
762.68004,63.55648,6483.76495,0.14526,51.97823,0.60755,30.37735
764.13004,63.67732,6484.23731,0.14529,51.98202,0.60871,30.43545
765.58004,63.79817,6484.47573,0.14527,51.98393,0.60987,30.49355
767.03004,63.91900,6484.73427,0.14522,51.98601,0.61103,30.55164
768.48004,64.03984,6485.98745,0.14525,51.99605,0.61219,30.60974
769.93004,64.16073,6485.95318,0.14524,51.99578,0.61336,30.66785
771.38004,64.28160,6486.62746,0.14530,52.00118,0.61452,30.72597
772.83004,64.40236,6487.16465,0.14532,52.00549,0.61568,30.78403
774.28004,64.52304,6487.29578,0.14527,52.00654,0.61684,30.84204
775.73004,64.64392,6488.65849,0.14521,52.01746,0.61800,30.90016
777.18004,64.76481,6489.37672,0.14523,52.02322,0.61917,30.95828
778.63004,64.88568,6488.62273,0.14527,52.01718,0.62033,31.01639
780.08004,65.00644,6489.80737,0.14527,52.02667,0.62149,31.07445
781.53004,65.12716,6491.00468,0.14526,52.03627,0.62265,31.13249
782.98004,65.24816,6494.19203,0.14524,52.06182,0.62381,31.19066
784.43004,65.36904,6496.46446,0.14526,52.08004,0.62498,31.24877
785.88004,65.48996,6499.37540,0.14527,52.10338,0.62614,31.30691
787.33004,65.61064,6502.28187,0.14530,52.12668,0.62730,31.36493
788.78004,65.73148,6504.23765,0.14522,52.14236,0.62846,31.42303
790.23004,65.85248,6507.07781,0.14520,52.16513,0.62962,31.48120
791.68004,65.97316,6509.81665,0.14522,52.18708,0.63078,31.53922
793.13004,66.09392,6512.23883,0.14528,52.20650,0.63195,31.59727
794.58004,66.21473,6517.58909,0.14526,52.24939,0.63311,31.65535
796.03004,66.33560,6521.65115,0.14525,52.28196,0.63427,31.71347
797.48004,66.45656,6526.90232,0.14525,52.32405,0.63543,31.77162
798.93004,66.57728,6531.17970,0.14526,52.35834,0.63659,31.82966
800.38004,66.69808,6535.24101,0.14526,52.39090,0.63775,31.88774
801.83004,66.81904,6540.70303,0.14524,52.43469,0.63892,31.94589
803.28004,66.93988,6545.68523,0.14526,52.47463,0.64008,32.00399
804.73004,67.06080,6550.55791,0.14532,52.51369,0.64124,32.06212
806.18004,67.18152,6554.89266,0.14527,52.54844,0.64240,32.12016
807.63004,67.30236,6559.09032,0.14522,52.58209,0.64357,32.17826
809.08004,67.42328,6565.98955,0.14522,52.63740,0.64473,32.23639
810.53004,67.54400,6571.78238,0.14525,52.68384,0.64589,32.29443
811.98004,67.66480,6575.27819,0.14527,52.71187,0.64705,32.35250
813.43004,67.78564,6580.98459,0.14528,52.75761,0.64821,32.41060
814.88004,67.90640,6586.02193,0.14525,52.79800,0.64937,32.46866
816.33004,68.02728,6592.02337,0.14525,52.84611,0.65054,32.52677
817.78004,68.14804,6598.26174,0.14544,52.89612,0.65170,32.58483
819.23004,68.26908,6605.16694,0.14543,52.95147,0.65286,32.64302
820.68004,68.38984,6612.48639,0.14521,53.01015,0.65402,32.70108
822.13004,68.51064,6618.35670,0.14513,53.05721,0.65518,32.75916
823.58004,68.63156,6625.28872,0.14523,53.11278,0.65635,32.81729
825.03004,68.75244,6631.38554,0.14530,53.16166,0.65751,32.87541
826.48004,68.87328,6636.36774,0.14541,53.20160,0.65867,32.93351
827.93004,68.99400,6642.93841,0.14536,53.25428,0.65983,32.99154
829.38004,69.11484,6648.52560,0.14523,53.29907,0.66099,33.04964
830.83004,69.23568,6656.83895,0.14518,53.36571,0.66215,33.10774
832.28004,69.35644,6662.98941,0.14522,53.41502,0.66332,33.16579
833.73004,69.47732,6670.96302,0.14527,53.47894,0.66448,33.22391
835.18004,69.59809,6677.96880,0.14531,53.53510,0.66564,33.28197
836.63004,69.71885,6683.45988,0.14527,53.57912,0.66680,33.34003
838.08004,69.83981,6690.58934,0.14523,53.63628,0.66796,33.39818
839.53004,69.96068,6696.32554,0.14525,53.68226,0.66913,33.45629
840.98004,70.08156,6703.33877,0.14520,53.73849,0.67029,33.51441
842.43004,70.20228,6710.93538,0.14528,53.79939,0.67145,33.57245
843.88004,70.32312,6717.50605,0.14534,53.85206,0.67261,33.63055
845.33004,70.44408,6725.43421,0.14529,53.91562,0.67377,33.68870
846.78004,70.56492,6732.44447,0.14520,53.97182,0.67494,33.74680
848.23004,70.68572,6738.01452,0.14507,54.01647,0.67610,33.80487
849.68004,70.80636,6744.09643,0.14532,54.06523,0.67726,33.86287
851.13004,70.92720,6750.81015,0.14537,54.11905,0.67842,33.92097
852.58004,71.04812,6757.80922,0.14523,54.17516,0.67958,33.97910
854.03004,71.16900,6764.09751,0.14523,54.22557,0.68074,34.03722
855.48004,71.28980,6769.53420,0.14525,54.26915,0.68191,34.09529
856.93004,71.41060,6776.81416,0.14524,54.32751,0.68307,34.15337
858.38004,71.53136,6782.61817,0.14525,54.37404,0.68423,34.21143
859.83004,71.65244,6788.57118,0.14532,54.42177,0.68539,34.26964
861.28004,71.77328,6794.26193,0.14537,54.46739,0.68655,34.32774
862.73004,71.89400,6800.35725,0.14528,54.51625,0.68772,34.38578
864.18004,72.01492,6807.69533,0.14519,54.57508,0.68888,34.44391
865.63004,72.13564,6812.78780,0.14521,54.61590,0.69004,34.50195
867.08004,72.25664,6820.88360,0.14529,54.68080,0.69120,34.56012
868.53004,72.37736,6827.62489,0.14530,54.73485,0.69236,34.61816
869.98004,72.49800,6833.82303,0.14523,54.78454,0.69352,34.67616
871.43004,72.61892,6840.41902,0.14524,54.83741,0.69469,34.73429
872.88004,72.73972,6846.08668,0.14527,54.88285,0.69585,34.79237
874.33004,72.86076,6852.68492,0.14529,54.93575,0.69701,34.85056
875.78004,72.98145,6857.38027,0.14527,54.97339,0.69817,34.90858
877.23004,73.10224,6863.39885,0.14528,55.02164,0.69933,34.96666
878.68004,73.22324,6870.20570,0.14525,55.07620,0.70050,35.02483
880.13004,73.34408,6876.07750,0.14521,55.12328,0.70166,35.08293
881.58004,73.46500,6881.38753,0.14525,55.16585,0.70282,35.14106
883.03004,73.58576,6887.53650,0.14532,55.21514,0.70398,35.19912
884.48004,73.70656,6892.12680,0.14530,55.25194,0.70514,35.25720
885.93004,73.82740,6898.58645,0.14524,55.30372,0.70631,35.31529
887.38004,73.94808,6904.05816,0.14525,55.34759,0.70747,35.37331
888.83004,74.06896,6910.34496,0.14528,55.39799,0.70863,35.43143
890.28004,74.18976,6918.00416,0.14525,55.45939,0.70979,35.48950
891.73004,74.31064,6924.83485,0.14527,55.51415,0.71095,35.54762
893.18004,74.43144,6932.54098,0.14525,55.57593,0.71211,35.60570
894.63004,74.55224,6940.96237,0.14531,55.64344,0.71328,35.66378
896.08004,74.67320,6947.41011,0.14531,55.69513,0.71444,35.72193
897.53004,74.79412,6953.70361,0.14525,55.74558,0.71560,35.78006
898.98004,74.91481,6959.74827,0.14525,55.79404,0.71676,35.83808
900.43004,75.03572,6965.18645,0.14526,55.83763,0.71792,35.89622
901.88004,75.15656,6971.48219,0.14529,55.88810,0.71909,35.95431
903.33004,75.27757,6976.41969,0.14527,55.92769,0.72025,36.01249
904.78004,75.39820,6982.88679,0.14526,55.97953,0.72141,36.07049
906.23004,75.51876,6987.22079,0.14527,56.01428,0.72257,36.12845
907.68004,75.63980,6994.11631,0.14528,56.06956,0.72373,36.18664
909.13004,75.76068,6999.23933,0.14523,56.11062,0.72490,36.24476
910.58004,75.88148,7003.55172,0.14524,56.14520,0.72606,36.30283
912.03004,76.00220,7009.72229,0.14526,56.19466,0.72722,36.36087
913.48004,76.12301,7014.75516,0.14530,56.23501,0.72838,36.41895
914.93004,76.24400,7021.61491,0.14531,56.29000,0.72954,36.47712
916.38004,76.36492,7027.58506,0.14525,56.33786,0.73071,36.53525
917.83004,76.48572,7033.66846,0.14526,56.38663,0.73187,36.59333
919.28004,76.60653,7039.64755,0.14525,56.43456,0.73303,36.65141
920.73004,76.72732,7044.94938,0.14524,56.47707,0.73419,36.70949
922.18004,76.84832,7051.48578,0.14525,56.52947,0.73535,36.76766
923.63004,76.96904,7054.98084,0.14528,56.55749,0.73651,36.82570
925.08004,77.08980,7060.50396,0.14529,56.60176,0.73768,36.88375
926.53004,77.21056,7066.45995,0.14525,56.64951,0.73884,36.94181
927.98004,77.33133,7071.00481,0.14523,56.68595,0.74000,36.99987
929.43004,77.45228,7077.69915,0.14526,56.73961,0.74116,37.05802
930.88004,77.57312,7082.46827,0.14530,56.77784,0.74232,37.11612
932.33004,77.69396,7086.84921,0.14527,56.81296,0.74348,37.17422
933.78004,77.81488,7092.19500,0.14524,56.85582,0.74465,37.23235
935.23004,77.93572,7096.36286,0.14520,56.88923,0.74581,37.29045
936.68004,78.05657,7102.34195,0.14520,56.93716,0.74697,37.34855
938.13004,78.17740,7107.57002,0.14527,56.97908,0.74813,37.40664
939.58004,78.29817,7112.61928,0.14530,57.01955,0.74929,37.46470
941.03004,78.41900,7119.44103,0.14529,57.07424,0.75046,37.52279
942.48004,78.53984,7124.30254,0.14527,57.11322,0.75162,37.58089
943.93004,78.66060,7129.71017,0.14521,57.15657,0.75278,37.63895
945.38004,78.78141,7134.40403,0.14519,57.19420,0.75394,37.69703
946.83004,78.90224,7139.13292,0.14524,57.23211,0.75510,37.75512
948.28005,79.02308,7145.93381,0.14532,57.28663,0.75626,37.81322
949.73005,79.14389,7151.60444,0.14529,57.33209,0.75743,37.87130
951.18005,79.26485,7157.52095,0.14523,57.37952,0.75859,37.92945
952.63005,79.38568,7162.98595,0.14522,57.42333,0.75975,37.98755
954.08005,79.50652,7167.61202,0.14525,57.46041,0.76091,38.04564
955.53005,79.62740,7174.27209,0.14525,57.51381,0.76208,38.10376
956.98005,79.74816,7178.79981,0.14527,57.55010,0.76324,38.16182
958.43005,79.86920,7181.94619,0.14527,57.57533,0.76440,38.22000
959.88005,79.98988,7185.72810,0.14526,57.60564,0.76556,38.27803
961.33005,80.11068,7188.80594,0.14527,57.63032,0.76672,38.33610
962.78005,80.23145,7194.97055,0.14524,57.67974,0.76788,38.39416
964.23005,80.35220,7198.71446,0.14529,57.70975,0.76904,38.45222
965.68005,80.47316,7202.68711,0.14526,57.74160,0.77021,38.51037
967.13005,80.59392,7206.23061,0.14524,57.77001,0.77137,38.56843
968.58005,80.71473,7208.77275,0.14524,57.79039,0.77253,38.62651
970.03005,80.83564,7213.36678,0.14527,57.82721,0.77369,38.68464
971.48005,80.95648,7216.82683,0.14529,57.85495,0.77485,38.74274
972.93005,81.07740,7220.37107,0.14529,57.88337,0.77602,38.80087
974.38005,81.19820,7224.89282,0.14524,57.91962,0.77718,38.85895
975.83005,81.31896,7228.32009,0.14523,57.94709,0.77834,38.91701
977.28005,81.43992,7234.11739,0.14525,57.99357,0.77950,38.97516
978.73005,81.56076,7238.38210,0.14527,58.02775,0.78067,39.03326
980.18005,81.68152,7241.11050,0.14529,58.04963,0.78183,39.09131
981.63005,81.80224,7244.45507,0.14525,58.07644,0.78299,39.14936
983.08005,81.92300,7247.38985,0.14524,58.09997,0.78415,39.20741
984.53005,82.04392,7251.74546,0.14524,58.13488,0.78531,39.26555
985.98005,82.16488,7255.74717,0.14526,58.16696,0.78647,39.32370
987.43005,82.28568,7258.63501,0.14528,58.19012,0.78764,39.38178
988.88005,82.40640,7261.94605,0.14525,58.21666,0.78880,39.43982
990.33005,82.52720,7264.85625,0.14524,58.23999,0.78996,39.49789
991.78005,82.64824,7268.74769,0.14522,58.27119,0.79112,39.55608
993.23005,82.76908,7271.49770,0.14525,58.29323,0.79228,39.61418
994.68005,82.88984,7273.30372,0.14527,58.30771,0.79344,39.67224
996.13005,83.01068,7277.01411,0.14527,58.33745,0.79461,39.73033
997.58005,83.13157,7279.39084,0.14521,58.35651,0.79577,39.78845
999.03005,83.25240,7283.23385,0.14511,58.38732,0.79693,39.84654
1000.48005,83.37300,7284.42222,0.14529,58.39684,0.79809,39.90453
1001.93005,83.49393,7287.13796,0.14535,58.41861,0.79925,39.96266
1003.38005,83.61484,7291.37436,0.14530,58.45258,0.80042,40.02079
1004.83005,83.73560,7292.27662,0.14524,58.45981,0.80158,40.07885
1006.28005,83.85653,7294.62653,0.14520,58.47865,0.80274,40.13699
1007.73005,83.97733,7296.90567,0.14524,58.49692,0.80390,40.19507
1009.18005,84.09808,7297.79005,0.14527,58.50401,0.80506,40.25312
1010.63005,84.21900,7301.47585,0.14524,58.53356,0.80623,40.31125
1012.08005,84.33988,7303.11498,0.14524,58.54670,0.80739,40.36937
1013.53005,84.46081,7305.90746,0.14525,58.56908,0.80855,40.42751
1014.98005,84.58152,7307.11818,0.14525,58.57879,0.80971,40.48555
1016.43005,84.70240,7309.12164,0.14526,58.59485,0.81087,40.54366
1017.88005,84.82317,7310.68179,0.14524,58.60736,0.81203,40.60172
1019.33005,84.94385,7311.72264,0.14526,58.61570,0.81319,40.65974
1020.78005,85.06481,7314.11949,0.14520,58.63492,0.81436,40.71789
1022.23005,85.18560,7315.54404,0.14516,58.64634,0.81552,40.77597
1023.68005,85.30641,7317.20328,0.14526,58.65964,0.81668,40.83405
1025.13005,85.42729,7320.85034,0.14525,58.68888,0.81784,40.89216
1026.58005,85.54816,7322.16686,0.14530,58.69943,0.81901,40.95028
1028.03005,85.66909,7324.96902,0.14526,58.72189,0.82017,41.00841
1029.48005,85.78980,7325.46747,0.14522,58.72589,0.82133,41.06645
1030.93005,85.91069,7326.49490,0.14542,58.73413,0.82249,41.12457
1032.38005,86.03157,7328.39182,0.14536,58.74933,0.82365,41.18268
1033.83005,86.15240,7330.64935,0.14501,58.76743,0.82482,41.24078
1035.28005,86.27336,7331.63580,0.14522,58.77534,0.82598,41.29893
1036.73005,86.39405,7333.29505,0.14537,58.78864,0.82714,41.35695
1038.18005,86.51468,7334.49981,0.14530,58.79830,0.82830,41.41495
1039.63005,86.63560,7336.88548,0.14521,58.81742,0.82946,41.47308
1041.08005,86.75648,7337.84363,0.14522,58.82511,0.83062,41.53120
1042.53005,86.87733,7339.31735,0.14527,58.83692,0.83179,41.58930
1043.98005,86.99808,7341.07494,0.14529,58.85101,0.83295,41.64735
1045.43005,87.11884,7343.30192,0.14525,58.86886,0.83411,41.70541
1046.88005,87.23984,7346.25012,0.14525,58.89250,0.83527,41.76359
1048.33005,87.36065,7348.37800,0.14527,58.90956,0.83643,41.82166
1049.78005,87.48161,7349.90016,0.14533,58.92176,0.83760,41.87982
1051.23005,87.60236,7352.25230,0.14517,58.94061,0.83876,41.93787
1052.68005,87.72320,7354.35933,0.14522,58.95751,0.83992,41.99597
1054.13005,87.84420,7357.01248,0.14528,58.97878,0.84108,42.05414
1055.58005,87.96489,7357.54222,0.14530,58.98302,0.84224,42.11216
1057.03005,88.08561,7359.21636,0.14526,58.99644,0.84340,42.17020
1058.48005,88.20640,7363.17933,0.14468,59.02821,0.84457,42.22827
1059.93005,88.32721,7365.16267,0.14515,59.04411,0.84573,42.28636
1061.38005,88.44809,7369.45197,0.14542,59.07850,0.84689,42.34447
1062.83005,88.56893,7371.62605,0.14531,59.09593,0.84805,42.40257
1064.28005,88.68984,7374.11976,0.14520,59.11592,0.84921,42.46070
1065.73005,88.81060,7376.93906,0.14520,59.13852,0.85038,42.51876
1067.18005,88.93144,7377.97171,0.14530,59.14680,0.85154,42.57686
1068.63005,89.05240,7383.02991,0.14531,59.18735,0.85270,42.63501
1070.08005,89.17333,7384.65115,0.14527,59.20035,0.85386,42.69314
1071.53005,89.29404,7386.60693,0.14523,59.21602,0.85502,42.75118
1072.98005,89.41488,7391.44683,0.14526,59.25482,0.85619,42.80928
1074.43005,89.53560,7394.07539,0.14538,59.27590,0.85735,42.86732
1075.88005,89.65652,7397.49894,0.14533,59.30334,0.85851,42.92545
1077.33005,89.77728,7399.53071,0.14521,59.31963,0.85967,42.98351
1078.78005,89.89796,7401.13333,0.14519,59.33248,0.86083,43.04152
1080.23005,90.01892,7405.43976,0.14526,59.36700,0.86199,43.09968
1081.68005,90.13981,7408.12570,0.14530,59.38853,0.86316,43.15780
1083.13005,90.26072,7413.53557,0.14529,59.43190,0.86432,43.21593
1084.58005,90.38145,7416.43757,0.14524,59.45517,0.86548,43.27397
1086.03005,90.50232,7419.26655,0.14524,59.47785,0.86664,43.33208
1087.48005,90.62320,7424.23460,0.14526,59.51767,0.86780,43.39020
1088.93005,90.74409,7427.10903,0.14526,59.54072,0.86897,43.44832
1090.38005,90.86496,7430.78142,0.14527,59.57016,0.87013,43.50643
1091.83005,90.98580,7434.74960,0.14527,59.60197,0.87129,43.56453
1093.28005,91.10648,7437.10995,0.14525,59.62089,0.87245,43.62254
1094.73005,91.22732,7442.53993,0.14527,59.66442,0.87361,43.68064
1096.18005,91.34812,7446.75174,0.14528,59.69819,0.87477,43.73872
1097.63005,91.46901,7451.55737,0.14528,59.73671,0.87594,43.79684
1099.08005,91.58973,7455.35865,0.14526,59.76718,0.87710,43.85488
1100.53005,91.71052,7458.73973,0.14526,59.79429,0.87826,43.91295
1101.98005,91.83148,7464.53628,0.14526,59.84076,0.87942,43.97110
1103.43005,91.95233,7467.77579,0.14525,59.86673,0.88058,44.02920
1104.88005,92.07325,7470.63160,0.14526,59.88962,0.88175,44.08734
1106.33005,92.19404,7475.06320,0.14527,59.92515,0.88291,44.14541
1107.78005,92.31488,7479.02393,0.14527,59.95690,0.88407,44.20351
1109.23005,92.43576,7484.78025,0.14527,60.00305,0.88523,44.26162
1110.68005,92.55661,7488.75439,0.14525,60.03491,0.88639,44.31972
1112.13005,92.67740,7493.25678,0.14528,60.07100,0.88756,44.37780
1113.58005,92.79804,7495.68418,0.14529,60.09046,0.88872,44.43579
1115.03005,92.91888,7499.89599,0.14526,60.12423,0.88988,44.49389
1116.48005,93.03977,7503.36498,0.14525,60.15204,0.89104,44.55201
1117.93005,93.16060,7504.09365,0.14527,60.15788,0.89220,44.61010
1119.38005,93.28156,7501.23262,0.14528,60.13494,0.89337,44.66826
1120.83005,93.40220,7476.47211,0.14527,59.93644,0.89453,44.72625
1121.17405,93.43148,690.10775,0.14536,5.53237,0.89481,44.74034