File: Calibration Data/test_PC_ASTM638.is_tens_RawData/Specimen_RawData_4.csv
Operator,"Quentin Govignon"
Our Reference Number,""
Customer Reference,""
Temperature (°C),21.0
Humidity (%),50.
Load Frame,"Instron Model 1185"
Crosshead Speed 1,5.00,mm/min
Extensometer G.L.,"50 mm"
Specimen Name,"PC #4"
Geometry,Rectangular
Length,104.00,mm
Maximum Load,8045.99151,N
Maximum Tensile stress,64.64201,MPa
Modulus (Chord 0.05 % - 0.25 %),2383.74305,MPa
Modulus (Young's 0.025 % - 0.5 %),2576.08802,MPa
Extension at Break (Standard),78.66029,mm
Specimen note 1,""
Specimen note 2,""
Specimen note 3,""

Time,Extension,Load,Strain 1,Tensile stress,Tensile strain,Tensile extension
(sec),(mm),(N),(mm/mm),(MPa),(mm/mm),(mm)
0.00000,-0.00004,-0.27777,0.00000,-0.00223,0.00000,-0.00015
1.20000,0.09936,209.77957,0.00068,1.68538,0.00068,0.03412
2.40000,0.19988,440.14389,0.00145,3.53614,0.00145,0.07242
3.60000,0.30000,670.32743,0.00223,5.38545,0.00223,0.11173
4.80000,0.40004,894.96309,0.00302,7.19019,0.00302,0.15105
6.00000,0.50000,1126.71927,0.00384,9.05214,0.00384,0.19183
7.20000,0.60000,1349.88427,0.00464,10.84506,0.00464,0.23186
8.40000,0.69992,1568.82834,0.00542,12.60407,0.00542,0.27119
9.60000,0.80008,1795.09502,0.00625,14.42191,0.00625,0.31226
10.80000,0.90000,2007.22665,0.00703,16.12619,0.00703,0.35143
12.00000,0.99996,2217.17339,0.00782,17.81291,0.00782,0.39102
13.20000,1.09992,2423.14860,0.00860,19.46773,0.00860,0.43012
14.40000,1.19996,2635.22658,0.00941,21.17158,0.00941,0.47048
15.60000,1.30016,2836.85550,0.01020,22.79148,0.01020,0.51011
16.80000,1.39988,3035.14153,0.01100,24.38452,0.01100,0.54979
18.00000,1.49992,3227.69731,0.01178,25.93153,0.01178,0.58913
19.20000,1.59996,3417.03296,0.01256,27.45266,0.01256,0.62814
20.40000,1.70004,3599.39709,0.01334,28.91779,0.01334,0.66709
21.60000,1.79992,3786.28373,0.01416,30.41925,0.01416,0.70775
22.80000,1.90000,3962.18896,0.01494,31.83248,0.01494,0.74714
24.00000,1.99992,4133.07361,0.01572,33.20538,0.01572,0.78583
25.20000,2.10008,4299.07739,0.01650,34.53906,0.01650,0.82487
26.40000,2.19988,4460.93343,0.01727,35.83943,0.01727,0.86364
27.60000,2.29996,4614.49362,0.01804,37.07314,0.01804,0.90212
28.80000,2.39996,4772.14344,0.01883,38.33971,0.01883,0.94172
30.00000,2.50004,4901.07797,0.01952,39.37558,0.01952,0.97599
31.20000,2.60012,5024.45698,0.02020,40.36681,0.02020,1.00996
32.40000,2.69992,5141.05670,0.02087,41.30358,0.02087,1.04346
33.60000,2.79996,5293.27542,0.02170,42.52652,0.02170,1.08513
34.80000,2.90004,5382.34934,0.02226,43.24214,0.02226,1.11305
36.00000,3.00004,5497.63925,0.02295,44.16839,0.02295,1.14760
37.20000,3.09992,5606.95753,0.02364,45.04666,0.02364,1.18182
38.40000,3.19996,5717.80019,0.02434,45.93718,0.02434,1.21681
39.60000,3.29996,5824.84864,0.02504,46.79721,0.02504,1.25187
40.80000,3.40004,5932.84965,0.02576,47.66490,0.02576,1.28782
42.00000,3.49984,6034.19766,0.02647,48.47913,0.02647,1.32362
43.20000,3.59996,6136.87746,0.02721,49.30407,0.02721,1.36060
44.40000,3.70000,6234.21259,0.02794,50.08607,0.02794,1.39710
45.60000,3.80004,6331.01165,0.02869,50.86376,0.02869,1.43438
46.80000,3.90000,6424.50452,0.02943,51.61488,0.02943,1.47166
48.00000,3.99992,6516.60934,0.03020,52.35486,0.03020,1.50993
49.20000,4.09996,6606.12956,0.03097,53.07407,0.03097,1.54828
50.40000,4.20000,6694.42564,0.03176,53.78345,0.03176,1.58785
51.60000,4.30000,6779.08808,0.03255,54.46363,0.03255,1.62730
52.80000,4.39992,6862.49211,0.03336,55.13370,0.03336,1.66790
54.00000,4.49996,6942.59182,0.03416,55.77723,0.03416,1.70820
55.20000,4.60008,7021.13062,0.03500,56.40822,0.03500,1.74982
56.40000,4.70004,7094.97258,0.03583,57.00147,0.03583,1.79125
57.60000,4.79988,7167.79605,0.03667,57.58654,0.03667,1.83342
58.80000,4.89992,7236.55075,0.03752,58.13891,0.03752,1.87595
60.00000,5.00000,7303.93380,0.03839,58.68027,0.03839,1.91974
61.20000,5.10004,7367.14602,0.03927,59.18813,0.03927,1.96370
62.40000,5.19996,7430.55493,0.04016,59.69756,0.04016,2.00822
63.60000,5.29992,7488.08384,0.04106,60.15975,0.04106,2.05318
64.80000,5.40000,7543.47220,0.04198,60.60474,0.04198,2.09883
66.00000,5.50000,7595.27907,0.04289,61.02096,0.04289,2.14471
67.20000,5.59992,7645.66734,0.04385,61.42578,0.04385,2.19249
68.40000,5.69996,7695.00211,0.04482,61.82214,0.04482,2.24079
69.60000,5.79996,7749.20806,0.04585,62.25764,0.04585,2.29260
70.80000,5.90004,7795.95822,0.04691,62.63323,0.04691,2.34567
72.00000,5.99996,7838.33861,0.04799,62.97372,0.04799,2.39959
73.20000,6.09992,7845.92703,0.04885,63.03468,0.04885,2.44228
74.40000,6.19988,7891.10288,0.04996,63.39763,0.04996,2.49800
75.60000,6.30004,7924.81750,0.05107,63.66849,0.05107,2.55347
76.80000,6.40004,7957.61794,0.05223,63.93202,0.05223,2.61170
78.00000,6.50000,7983.38354,0.05341,64.13902,0.05341,2.67074
79.20000,6.59992,8004.47613,0.05463,64.30848,0.05463,2.73154
80.40000,6.70008,8021.31072,0.05587,64.44373,0.05587,2.79357
81.60000,6.80000,7997.23342,0.05684,64.25029,0.05684,2.84219
82.80000,6.89992,8023.40209,0.05812,64.46053,0.05812,2.90577
84.00000,6.99992,8038.82256,0.05943,64.58442,0.05943,2.97172
85.20000,7.09988,8044.85902,0.06077,64.63292,0.06077,3.03855
86.40000,7.20000,8041.65602,0.06210,64.60718,0.06210,3.10520
87.60000,7.29988,8038.50591,0.06350,64.58187,0.06350,3.17511
88.80000,7.39992,8033.65856,0.06496,64.54293,0.06496,3.24791
90.00000,7.49988,8021.43738,0.06645,64.44474,0.06645,3.32265
91.20000,7.60004,8004.59534,0.06798,64.30943,0.06798,3.39924
92.40000,7.69996,7984.24035,0.06954,64.14590,0.06954,3.47678
93.57600,7.79776,7959.12519,0.07110,63.94412,0.07071,3.53534
94.77600,7.89776,7930.33019,0.07272,63.71278,0.07167,3.58342
95.97600,7.99796,7898.64734,0.07437,63.45824,0.07263,3.63159
97.17600,8.09780,7862.65209,0.07604,63.16905,0.07359,3.67959
98.37600,8.19776,7825.38503,0.07776,62.86965,0.07455,3.72765
99.57600,8.29772,7781.78275,0.07953,62.51934,0.07551,3.77570
100.77600,8.39784,7735.98775,0.00024,62.15142,0.07648,3.82384
101.97600,8.49788,7685.37447,0.05368,61.74479,0.07744,3.87194
103.17600,8.59776,7630.83920,0.13485,61.30665,0.07840,3.91995
104.37600,8.69784,7570.03650,0.12290,60.81816,0.07936,3.96807
105.57601,8.79772,7500.18209,0.13677,60.25695,0.08032,4.01609
106.77601,8.89784,7414.17184,0.14792,59.56593,0.08128,4.06422
107.97601,8.99776,7305.30992,0.14244,58.69133,0.08225,4.11226
109.17601,9.09776,7142.44395,0.14610,57.38285,0.08321,4.16034
110.37601,9.19776,6864.20947,0.14391,55.14750,0.08417,4.20842
111.57601,9.29788,6452.82343,0.14516,51.84240,0.08513,4.25655
112.77601,9.39772,6127.72219,0.14453,49.23051,0.08609,4.30455
113.97601,9.49780,5956.44861,0.14479,47.85449,0.08705,4.35267
115.17601,9.59780,5868.69493,0.14475,47.14947,0.08801,4.40074
116.37601,9.69788,5823.87857,0.14469,46.78942,0.08898,4.44886
117.57601,9.79780,5799.86013,0.14481,46.59645,0.08994,4.49690
118.77601,9.89776,5788.64887,0.14470,46.50638,0.09090,4.54495
119.97601,9.99780,5784.61736,0.14477,46.47399,0.09186,4.59305
121.17601,10.09784,5783.73224,0.14472,46.46688,0.09282,4.64115
122.37601,10.19776,5786.16671,0.14475,46.48644,0.09378,4.68919
123.57601,10.29776,5787.66502,0.14475,46.49847,0.09475,4.73726
124.77601,10.39776,5791.67642,0.14473,46.53070,0.09571,4.78534
125.97601,10.49780,5793.81660,0.14474,46.54790,0.09667,4.83343
127.17601,10.59788,5796.88065,0.14474,46.57251,0.09763,4.88155
128.37601,10.69776,5799.35648,0.14475,46.59240,0.09859,4.92957
129.57601,10.79780,5801.57414,0.14474,46.61022,0.09955,4.97767
130.77601,10.89780,5803.94566,0.14475,46.62927,0.10051,5.02574
131.97601,10.99784,5806.98550,0.14491,46.65370,0.10148,5.07384
133.17601,11.09768,5808.26141,0.14473,46.66395,0.10244,5.12184
134.37601,11.19776,5812.47695,0.14477,46.69781,0.10340,5.16995
135.57601,11.29780,5814.74081,0.14477,46.71600,0.10436,5.21805
136.77601,11.39788,5820.13801,0.14475,46.75936,0.10532,5.26617
137.97601,11.49772,5821.32787,0.14476,46.76892,0.10628,5.31417
139.17601,11.59780,5824.60091,0.14474,46.79522,0.10725,5.36228
140.37601,11.69776,5825.39663,0.14477,46.80161,0.10821,5.41034
141.57601,11.79784,5826.56935,0.14474,46.81103,0.10917,5.45845
142.77601,11.89788,5827.19445,0.14476,46.81606,0.11013,5.50655
143.97601,11.99776,5828.56387,0.14477,46.82706,0.11109,5.55457
145.17601,12.09780,5828.38692,0.14475,46.82564,0.11205,5.60267
146.37601,12.19780,5830.29799,0.14478,46.84099,0.11301,5.65074
147.57601,12.29788,5830.64370,0.14476,46.84377,0.11398,5.69886
148.77601,12.39768,5831.99933,0.14475,46.85466,0.11494,5.74684
149.97601,12.49784,5833.33671,0.14475,46.86540,0.11590,5.79499
151.17601,12.59784,5833.31995,0.14474,46.86527,0.11686,5.84307
152.37601,12.69788,5832.80437,0.14472,46.86113,0.11782,5.89117
153.57601,12.79760,5831.67002,0.14479,46.85201,0.11878,5.93911
154.77601,12.89784,5831.43011,0.14476,46.85009,0.11975,5.98730
155.97601,12.99776,5832.42103,0.14477,46.85805,0.12071,6.03534
157.17601,13.09784,5833.13480,0.14476,46.86378,0.12167,6.08345
158.37601,13.19772,5833.81988,0.14478,46.86928,0.12263,6.13147
159.57601,13.29768,5834.00615,0.14477,46.87078,0.12359,6.17953
160.77601,13.39784,5837.15849,0.14477,46.89611,0.12455,6.22768
161.97601,13.49788,5835.85091,0.14477,46.88560,0.12552,6.27578
163.17601,13.59788,5836.35382,0.14479,46.88964,0.12648,6.32386
164.37601,13.69772,5833.93723,0.14477,46.87023,0.12744,6.37186
165.57601,13.79780,5834.44536,0.14477,46.87431,0.12840,6.41997
166.77601,13.89788,5833.84633,0.14477,46.86950,0.12936,6.46809
167.97601,13.99796,5834.48969,0.14478,46.87467,0.13032,6.51620
169.17601,14.09768,5832.61736,0.14476,46.85962,0.13128,6.56415
170.37601,14.19780,5834.88643,0.14477,46.87785,0.13225,6.61228
171.57601,14.29772,5834.53290,0.14478,46.87501,0.13321,6.66032
172.77601,14.39784,5837.09143,0.14478,46.89557,0.13417,6.70845
173.97601,14.49772,5834.79665,0.14478,46.87713,0.13513,6.75647
175.17601,14.59776,5835.20196,0.14478,46.88039,0.13609,6.80457
176.37601,14.69784,5835.31335,0.14477,46.88128,0.13705,6.85268
177.57601,14.79792,5835.30553,0.14478,46.88122,0.13802,6.90080
178.77601,14.89780,5834.40438,0.14478,46.87398,0.13898,6.94882
179.97601,14.99780,5834.64168,0.14478,46.87589,0.13994,6.99690
181.17601,15.09784,5833.84484,0.14476,46.86949,0.14090,7.04499
182.37601,15.19788,5835.50557,0.14478,46.88283,0.14186,7.09309
183.57601,15.29784,5834.01620,0.14473,46.87086,0.14282,7.14115
184.77601,15.39772,5836.01743,0.14480,46.88694,0.14378,7.18917
185.97601,15.49780,5835.30478,0.14478,46.88121,0.14475,7.23728
187.17601,15.59784,5837.27174,0.14480,46.89702,0.14571,7.28538
188.37601,15.69788,5835.00266,0.14478,46.87879,0.14667,7.33347
189.57601,15.79776,5835.33198,0.14476,46.88143,0.14763,7.38149
190.77601,15.89772,5835.17402,0.14478,46.88016,0.14859,7.42955
191.97601,15.99788,5836.55462,0.14477,46.89126,0.14955,7.47770
193.17601,16.09788,5835.74809,0.14487,46.88478,0.15052,7.52578
194.37601,16.19776,5835.51526,0.14474,46.88291,0.15148,7.57380
195.57601,16.29780,5835.99024,0.14481,46.88672,0.15244,7.62190
196.77601,16.39788,5837.04486,0.14478,46.89519,0.15340,7.67001
197.97601,16.49796,5836.61012,0.14478,46.89170,0.15436,7.71813
199.17601,16.59776,5836.77590,0.14478,46.89303,0.15532,7.76611
200.37601,16.69780,5835.55102,0.14475,46.88319,0.15628,7.81420
201.57601,16.79780,5836.16905,0.14471,46.88816,0.15725,7.86228
202.77601,16.89792,5834.66329,0.14486,46.87606,0.15821,7.91042
203.97601,16.99776,5834.63982,0.14477,46.87587,0.15917,7.95842
205.17601,17.09776,5833.84857,0.14481,46.86952,0.16013,8.00649
206.37601,17.19772,5835.61547,0.14478,46.88371,0.16109,8.05455
207.57601,17.29792,5834.58096,0.14481,46.87540,0.16205,8.10272
208.77601,17.39788,5835.50148,0.14480,46.88279,0.16302,8.15078
209.97601,17.49780,5834.82534,0.14481,46.87736,0.16398,8.19882
211.17601,17.59784,5835.57747,0.14479,46.88341,0.16494,8.24692
212.37601,17.69784,5834.65248,0.14479,46.87597,0.16590,8.29499
213.57601,17.79792,5835.07307,0.14482,46.87935,0.16686,8.34311
214.77601,17.89772,5833.96554,0.14479,46.87046,0.16782,8.39109
215.97601,17.99784,5835.35619,0.14479,46.88163,0.16878,8.43922
217.17601,18.09776,5835.67843,0.14480,46.88422,0.16975,8.48726
218.37601,18.19788,5837.17562,0.14481,46.89625,0.17071,8.53540
219.57601,18.29768,5835.94479,0.14480,46.88636,0.17167,8.58338
220.77601,18.39780,5838.00152,0.14482,46.90288,0.17263,8.63151
221.97601,18.49776,5837.27509,0.14480,46.89704,0.17359,8.67957
223.17601,18.59792,5837.82718,0.14480,46.90148,0.17455,8.72772
224.37601,18.69780,5836.65185,0.14481,46.89204,0.17551,8.77574
225.57601,18.79780,5837.17898,0.14480,46.89627,0.17648,8.82382
226.77601,18.89784,5836.62130,0.14481,46.89179,0.17744,8.87192
227.97601,18.99784,5837.77018,0.14481,46.90102,0.17840,8.91999
229.17601,19.09788,5836.85599,0.14481,46.89368,0.17936,8.96809
230.37601,19.19772,5837.52841,0.14479,46.89908,0.18032,9.01609
231.57601,19.29780,5837.00798,0.14481,46.89490,0.18128,9.06420
232.77601,19.39784,5839.14965,0.14482,46.91210,0.18225,9.11230
233.97601,19.49792,5838.47277,0.14479,46.90667,0.18321,9.16042
235.17601,19.59776,5839.13922,0.14479,46.91202,0.18417,9.20842
236.37601,19.69776,5838.24068,0.14482,46.90480,0.18513,9.25649
237.57601,19.79780,5838.69591,0.14480,46.90846,0.18609,9.30459
238.77601,19.89796,5838.42807,0.14481,46.90631,0.18705,9.35274
239.97601,19.99772,5838.55323,0.14477,46.90731,0.18801,9.40070
241.17601,20.09776,5837.31607,0.14483,46.89737,0.18898,9.44880
242.37601,20.19780,5839.86938,0.14480,46.91789,0.18994,9.49690
243.57601,20.29784,5839.66933,0.14480,46.91628,0.19090,9.54499
244.77601,20.39784,5841.20192,0.14481,46.92859,0.19186,9.59307
245.97601,20.49776,5841.14902,0.14481,46.92817,0.19282,9.64111
247.17601,20.59780,5843.02545,0.14479,46.94324,0.19378,9.68920
248.37601,20.69792,5842.09934,0.14481,46.93580,0.19475,9.73734
249.57601,20.79784,5842.23531,0.14480,46.93689,0.19571,9.78538
250.77601,20.89784,5840.76084,0.14481,46.92505,0.19667,9.83345
251.97601,20.99772,5842.85893,0.14483,46.94191,0.19763,9.88147
253.17601,21.09788,5842.13771,0.14481,46.93611,0.19859,9.92963
254.37601,21.19788,5843.61441,0.14482,46.94797,0.19955,9.97770
255.57601,21.29772,5843.72692,0.14479,46.94888,0.20051,10.02570
256.77601,21.39780,5846.50151,0.14482,46.97117,0.20148,10.07382
257.97601,21.49788,5846.05820,0.14480,46.96761,0.20244,10.12194
259.17601,21.59788,5846.91539,0.14483,46.97450,0.20340,10.17001
260.37601,21.69776,5845.89764,0.14481,46.96632,0.20436,10.21803
261.57601,21.79772,5846.18971,0.14482,46.96866,0.20532,10.26609
262.77601,21.89780,5845.16227,0.14480,46.96041,0.20628,10.31420
263.97601,21.99796,5847.02194,0.14482,46.97535,0.20725,10.36236
265.17601,22.09772,5845.41671,0.14481,46.96245,0.20821,10.41032
266.37601,22.19784,5848.60668,0.14480,46.98808,0.20917,10.45845
267.57601,22.29772,5847.47270,0.14481,46.97897,0.21013,10.50647
268.77601,22.39796,5850.65596,0.14480,47.00455,0.21109,10.55467
269.97601,22.49780,5848.40924,0.14481,46.98650,0.21205,10.60267
271.17601,22.59772,5850.14112,0.14479,47.00041,0.21301,10.65070
272.37601,22.69780,5849.89488,0.14485,46.99843,0.21398,10.69882
273.57601,22.79792,5850.78187,0.14481,47.00556,0.21494,10.74695
274.77601,22.89788,5851.42374,0.14483,47.01072,0.21590,10.79501
275.97601,22.99772,5851.68749,0.14481,47.01283,0.21686,10.84301
277.17601,23.09768,5852.63968,0.14483,47.02048,0.21782,10.89107
278.37601,23.19784,5855.04435,0.14483,47.03980,0.21878,10.93922
279.57601,23.29792,5854.09924,0.14481,47.03221,0.21975,10.98734
280.77601,23.39776,5855.89930,0.14482,47.04667,0.22071,11.03534
281.97601,23.49784,5854.56043,0.14482,47.03592,0.22167,11.08345
283.17601,23.59780,5855.13785,0.14480,47.04055,0.22263,11.13151
284.37601,23.69796,5854.20839,0.14482,47.03309,0.22359,11.17967
285.57601,23.79768,5853.25398,0.14484,47.02542,0.22455,11.22761
286.77601,23.89776,5852.70301,0.14480,47.02099,0.22551,11.27572
287.97601,23.99776,5853.39889,0.14482,47.02658,0.22648,11.32380
289.17601,24.09792,5853.00773,0.14480,47.02344,0.22744,11.37195
290.37601,24.19780,5854.63904,0.14484,47.03655,0.22840,11.41997
291.57601,24.29772,5854.67443,0.14481,47.03683,0.22936,11.46801
292.77601,24.39776,5857.37079,0.14482,47.05849,0.23032,11.51611
293.97601,24.49788,5857.37117,0.14471,47.05850,0.23128,11.56424
295.17601,24.59792,5857.09736,0.14488,47.05630,0.23225,11.61234
296.37601,24.69776,5856.30350,0.14480,47.04992,0.23321,11.66034
297.57601,24.79780,5856.81833,0.14482,47.05406,0.23417,11.70843
298.77601,24.89784,5857.36446,0.14482,47.05844,0.23513,11.75653
299.97601,24.99800,5858.44181,0.14482,47.06710,0.23609,11.80468
301.17601,25.09768,5857.48702,0.14482,47.05943,0.23705,11.85261
302.37601,25.19772,5860.09398,0.14481,47.08037,0.23801,11.90070
303.57601,25.29780,5861.88845,0.14482,47.09479,0.23898,11.94882
304.77601,25.39792,5863.67957,0.14480,47.10918,0.23994,11.99695
305.97601,25.49772,5861.91863,0.14485,47.09503,0.24090,12.04494
307.17601,25.59776,5862.94718,0.14473,47.10330,0.24186,12.09303
308.37601,25.69776,5862.61153,0.14490,47.10060,0.24282,12.14111
309.57601,25.79788,5862.72106,0.14475,47.10148,0.24378,12.18924
310.77601,25.89776,5860.79657,0.14486,47.08602,0.24475,12.23726
311.97601,25.99780,5862.31165,0.14478,47.09819,0.24571,12.28536
313.17601,26.09776,5861.63923,0.14485,47.09279,0.24667,12.33342
314.37601,26.19788,5863.62146,0.14480,47.10871,0.24763,12.38155
315.57601,26.29788,5863.82523,0.14483,47.11035,0.24859,12.42963
316.77602,26.39768,5865.06091,0.14480,47.12028,0.24955,12.47761
317.97602,26.49776,5864.63287,0.14482,47.11684,0.25051,12.52572
319.17602,26.59788,5866.73319,0.14488,47.13371,0.25148,12.57386
320.37602,26.69792,5864.94133,0.14478,47.11932,0.25244,12.62195
321.57602,26.79772,5865.56122,0.14482,47.12430,0.25340,12.66993
322.77602,26.89776,5865.46808,0.14483,47.12355,0.25436,12.71803
323.97602,26.99780,5867.32291,0.14481,47.13845,0.25532,12.76613
325.17602,27.09780,5866.06227,0.14488,47.12832,0.25628,12.81420
326.37602,27.19768,5867.65036,0.14482,47.14108,0.25724,12.86222
327.57602,27.29776,5867.46782,0.14481,47.13961,0.25821,12.91034
328.77602,27.39780,5869.28017,0.14482,47.15418,0.25917,12.95843
329.97602,27.49788,5868.97209,0.14482,47.15170,0.26013,13.00655
331.17602,27.59780,5868.29409,0.14482,47.14625,0.26109,13.05459
332.37602,27.69776,5868.53512,0.14482,47.14819,0.26205,13.10265
333.57602,27.79776,5868.79738,0.14483,47.15030,0.26301,13.15072
334.77602,27.89788,5868.39244,0.14482,47.14704,0.26398,13.19886
335.97602,27.99776,5869.19673,0.14481,47.15350,0.26494,13.24688
337.17602,28.09772,5868.29148,0.14482,47.14623,0.26590,13.29493
338.37602,28.19772,5870.37057,0.14482,47.16294,0.26686,13.34301
339.57602,28.29788,5869.63780,0.14482,47.15705,0.26782,13.39117
340.77602,28.39784,5871.42557,0.14480,47.17141,0.26878,13.43922
341.97602,28.49768,5870.59110,0.14493,47.16471,0.26974,13.48722
343.17602,28.59776,5872.17957,0.14477,47.17747,0.27071,13.53534
344.37602,28.69784,5872.46679,0.14484,47.17978,0.27167,13.58346
345.57602,28.79788,5872.09538,0.14482,47.17679,0.27263,13.63155
346.77602,28.89776,5871.43563,0.14483,47.17149,0.27359,13.67957
347.97602,28.99772,5871.97803,0.14481,47.17585,0.27455,13.72763
349.17602,29.09780,5872.67503,0.14481,47.18145,0.27551,13.77574
350.37602,29.19788,5873.34558,0.14482,47.18684,0.27648,13.82386
351.57602,29.29768,5871.97132,0.14482,47.17580,0.27744,13.87184
352.77602,29.39776,5875.26038,0.14485,47.20222,0.27840,13.91995
353.97602,29.49776,5873.58214,0.14485,47.18874,0.27936,13.96803
355.17602,29.59796,5874.93666,0.14481,47.19962,0.28032,14.01620
356.37602,29.69780,5873.78442,0.14484,47.19036,0.28128,14.06420
357.57602,29.79768,5873.71551,0.14482,47.18981,0.28224,14.11222
358.77602,29.89780,5874.05674,0.14482,47.19255,0.28321,14.16036
359.97602,29.99788,5874.62485,0.14479,47.19711,0.28417,14.20847
361.17602,30.09784,5874.74592,0.07973,47.19809,0.28513,14.25653
362.37602,30.19772,5876.12838,-0.05017,47.20919,0.28609,14.30455
363.57602,30.29772,5876.42938,-0.03870,47.21161,0.28705,14.35263
364.77602,30.39788,5877.79619,-0.03103,47.22259,0.28802,14.40078
365.97602,30.49796,5877.29104,0.13150,47.21853,0.28898,14.44890
367.17602,30.59772,5876.93192,0.14265,47.21565,0.28994,14.49686
368.37602,30.69772,5876.70170,0.13667,47.21380,0.29090,14.54493
369.57602,30.79780,5877.45942,0.13984,47.21989,0.29186,14.59305
370.77602,30.89796,5877.33090,0.13814,47.21886,0.29282,14.64120
371.97602,30.99772,5877.06938,0.13909,47.21675,0.29378,14.68917
373.17602,31.09768,5876.14477,0.13859,47.20933,0.29474,14.73722
374.37602,31.19780,5879.41222,0.13888,47.23558,0.29571,14.78536
375.57602,31.29784,5878.07670,0.13880,47.22485,0.29667,14.83345
376.77602,31.39772,5879.68566,0.13876,47.23777,0.29763,14.88147
377.97602,31.49780,5880.41060,0.13878,47.24360,0.29859,14.92959
379.17602,31.59772,5880.86806,0.13876,47.24727,0.29955,14.97763
380.37602,31.69792,5880.84124,0.13877,47.24706,0.30052,15.02580
381.57602,31.79788,5880.70378,0.13877,47.24595,0.30148,15.07386
382.77602,31.89776,5879.65995,0.13877,47.23757,0.30244,15.12188
383.97602,31.99764,5880.13381,0.13878,47.24137,0.30340,15.16990
385.17602,32.09784,5880.82336,0.13877,47.24691,0.30436,15.21807
386.37602,32.19800,5881.65224,0.13884,47.25357,0.30532,15.26622
387.57602,32.29768,5881.28492,0.13875,47.25062,0.30628,15.31415
388.77602,32.39764,5883.55921,0.13879,47.26889,0.30724,15.36220
389.97602,32.49788,5883.43553,0.13878,47.26790,0.30821,15.41040
391.17602,32.59788,5883.50110,0.13877,47.26843,0.30917,15.45847
392.37602,32.69772,5882.29932,0.13878,47.25877,0.31013,15.50647
393.57602,32.79776,5882.30714,0.13878,47.25883,0.31109,15.55457
394.77602,32.89776,5881.26369,0.13886,47.25045,0.31205,15.60265
395.97602,32.99796,5882.18719,0.13872,47.25787,0.31302,15.65082
397.17602,33.09776,5881.00255,0.13881,47.24835,0.31398,15.69880
398.37602,33.19780,5883.23064,0.13877,47.26625,0.31494,15.74690
399.57602,33.29768,5883.14794,0.13880,47.26559,0.31590,15.79491
400.77602,33.39796,5883.87400,0.13878,47.27142,0.31686,15.84313
401.97602,33.49784,5882.98067,0.13877,47.26425,0.31782,15.89115
403.17602,33.59776,5884.15973,0.13878,47.27372,0.31878,15.93918
404.37602,33.69768,5882.79851,0.13877,47.26278,0.31974,15.98722
405.57602,33.79792,5883.68326,0.13879,47.26989,0.32071,16.03542
406.77602,33.89788,5881.56395,0.13879,47.25286,0.32167,16.08347
407.97602,33.99772,5882.87823,0.13879,47.26342,0.32263,16.13147
409.17602,34.09772,5882.94268,0.13879,47.26394,0.32359,16.17955
410.37602,34.19776,5885.13426,0.13878,47.28155,0.32455,16.22765
411.57602,34.29796,5884.48718,0.13880,47.27635,0.32552,16.27582
412.77602,34.39780,5886.25483,0.13875,47.29055,0.32648,16.32382
413.97602,34.49780,5884.58367,0.13884,47.27712,0.32744,16.37190
415.17602,34.59780,5885.49711,0.13876,47.28446,0.32840,16.41997
416.37602,34.69796,5884.51847,0.13880,47.27660,0.32936,16.46813
417.57602,34.79776,5883.86767,0.13878,47.27137,0.33032,16.51611
418.77602,34.89780,5883.34762,0.13880,47.26719,0.33128,16.56420
419.97602,34.99772,5884.46967,0.13878,47.27621,0.33224,16.61224
421.17602,35.09792,5883.75889,0.13882,47.27050,0.33321,16.66042
422.37602,35.19780,5884.11614,0.13875,47.27337,0.33417,16.70843
423.57602,35.29768,5883.53612,0.13879,47.26871,0.33513,16.75645
424.77602,35.39776,5884.67941,0.13879,47.27789,0.33609,16.80457
425.97602,35.49788,5884.22008,0.13879,47.27420,0.33705,16.85270
427.17602,35.59800,5884.77254,0.13880,47.27864,0.33802,16.90084
428.37602,35.69776,5883.21574,0.13863,47.26613,0.33898,16.94880
429.57602,35.79776,5882.47515,0.13885,47.26018,0.33994,16.99688
430.77602,35.89784,5882.00800,0.13877,47.25643,0.34090,17.04499
431.97602,35.99800,5882.20432,0.13881,47.25801,0.34186,17.09315
433.17602,36.09776,5880.54433,0.13879,47.24467,0.34282,17.14111
434.37602,36.19772,5881.48311,0.13880,47.25221,0.34378,17.18917
435.57602,36.29776,5881.26555,0.13879,47.25047,0.34475,17.23726
436.77602,36.39792,5881.39482,0.13880,47.25150,0.34571,17.28542
437.97602,36.49776,5880.43332,0.13878,47.24378,0.34667,17.33341
439.17602,36.59776,5879.91774,0.13881,47.23964,0.34763,17.38149
440.37602,36.69780,5878.97934,0.13877,47.23210,0.34859,17.42959
441.57602,36.79784,5878.32592,0.13880,47.22685,0.34955,17.47768
442.77602,36.89784,5876.49941,0.13879,47.21217,0.35052,17.52576
443.97602,36.99780,5875.92497,0.13879,47.20756,0.35148,17.57382
445.17602,37.09776,5874.18489,0.13880,47.19358,0.35244,17.62188
446.37602,37.19792,5875.74616,0.13880,47.20612,0.35340,17.67003
447.57602,37.29784,5873.43425,0.13879,47.18755,0.35436,17.71807
448.77602,37.39780,5873.53557,0.13881,47.18836,0.35532,17.76613
449.97602,37.49772,5871.59619,0.13879,47.17278,0.35628,17.81417
451.17602,37.59788,5871.36149,0.13878,47.17090,0.35725,17.86232
452.37602,37.69796,5869.54392,0.13883,47.15629,0.35821,17.91044
453.57602,37.79772,5867.42051,0.13879,47.13923,0.35917,17.95840
454.77602,37.89776,5865.07320,0.13881,47.12038,0.36013,18.00649
455.97602,37.99780,5864.77108,0.13879,47.11795,0.36109,18.05459
457.17602,38.09788,5861.84002,0.13882,47.09440,0.36205,18.10270
458.37602,38.19776,5859.94348,0.13879,47.07916,0.36301,18.15072
459.57602,38.29776,5857.11971,0.13881,47.05648,0.36398,18.19880
460.77602,38.39780,5857.23929,0.13878,47.05744,0.36494,18.24690
461.97602,38.49800,5854.13687,0.13882,47.03251,0.36590,18.29507
463.17602,38.59772,5851.86183,0.13879,47.01424,0.36686,18.34301
464.37602,38.69784,5849.54806,0.13881,46.99565,0.36782,18.39115
465.57602,38.79776,5847.21640,0.13880,46.97691,0.36878,18.43919
466.77602,38.89792,5844.34047,0.13869,46.95381,0.36975,18.48734
467.97602,38.99784,5841.16392,0.13890,46.92829,0.37071,18.53538
469.17602,39.09776,5836.51438,0.13875,46.89093,0.37167,18.58342
470.37602,39.19772,5836.04909,0.13884,46.88719,0.37263,18.63147
471.57602,39.29780,5832.10811,0.13877,46.85553,0.37359,18.67959
472.77602,39.39796,5829.90870,0.13882,46.83786,0.37455,18.72774
473.97602,39.49776,5825.52180,0.13880,46.80262,0.37551,18.77573
475.17602,39.59772,5821.88927,0.13881,46.77343,0.37648,18.82378
476.37602,39.69784,5817.26767,0.13881,46.73630,0.37744,18.87192
477.57602,39.79796,5813.27230,0.13868,46.70420,0.37840,18.92005
478.77602,39.89768,5807.45563,0.13887,46.65747,0.37936,18.96799
479.97602,39.99780,5803.99893,0.13868,46.62970,0.38032,19.01613
481.17602,40.09776,5797.31278,0.13887,46.57598,0.38128,19.06419
482.37602,40.19792,5794.20179,0.13877,46.55099,0.38225,19.11234
483.57602,40.29772,5788.46708,0.13882,46.50492,0.38321,19.16032
484.77602,40.39780,5785.41048,0.13881,46.48036,0.38417,19.20844
485.97602,40.49785,5780.89245,0.13880,46.44406,0.38513,19.25653
487.17602,40.59784,5776.96599,0.13880,46.41252,0.38609,19.30461
488.37602,40.69784,5770.34615,0.13880,46.35933,0.38705,19.35269
489.57602,40.79776,5764.87035,0.13881,46.31534,0.38801,19.40073
490.77602,40.89772,5760.06472,0.13878,46.27673,0.38898,19.44878
491.97602,40.99792,5755.76164,0.13872,46.24216,0.38994,19.49696
493.17602,41.09796,5750.57156,0.13887,46.20046,0.39090,19.54505
494.37602,41.19772,5747.18677,0.13879,46.17327,0.39186,19.59301
495.57602,41.29772,5742.94180,0.13882,46.13916,0.39282,19.64109
496.77602,41.39780,5741.59771,0.13880,46.12837,0.39378,19.68920
497.97602,41.49800,5738.10674,0.13880,46.10032,0.39475,19.73738
499.17602,41.59776,5735.46514,0.13881,46.07910,0.39571,19.78534
500.37602,41.69776,5731.33491,0.13881,46.04591,0.39667,19.83342
501.57602,41.79788,5729.20293,0.13880,46.02879,0.39763,19.88155
502.77602,41.89788,5726.67904,0.13890,46.00851,0.39859,19.92963
503.97602,41.99780,5725.24294,0.13872,45.99697,0.39955,19.97767
505.17602,42.09772,5723.14560,0.13885,45.98012,0.40051,20.02571
506.37602,42.19772,5724.91288,0.13879,45.99432,0.40148,20.07378
507.57602,42.29788,5725.39829,0.13883,45.99822,0.40244,20.12194
508.77602,42.39784,5727.56901,0.13879,46.01566,0.40340,20.16999
509.97602,42.49776,5727.75044,0.13880,46.01712,0.40436,20.21803
511.17602,42.59776,5730.50193,0.13881,46.03922,0.40532,20.26611
512.37602,42.69784,5732.02744,0.13865,46.05148,0.40628,20.31422
513.57602,42.79792,5734.14676,0.13885,46.06850,0.40725,20.36234
514.77602,42.89780,5736.55479,0.13879,46.08785,0.40821,20.41036
515.97602,42.99772,5740.42387,0.13890,46.11894,0.40917,20.45840
517.17602,43.09792,5744.68412,0.13867,46.15316,0.41013,20.50657
518.37602,43.19788,5749.65477,0.13884,46.19310,0.41109,20.55463
519.57602,43.29780,5752.92632,0.13879,46.21938,0.41205,20.60267
520.77602,43.39772,5760.11688,0.13883,46.27715,0.41301,20.65070
521.97602,43.49784,5765.14602,0.13879,46.31755,0.41398,20.69884
523.17602,43.59792,5769.79928,0.13882,46.35494,0.41494,20.74695
524.37602,43.69776,5775.23671,0.13881,46.39862,0.41590,20.79495
525.57602,43.79776,5781.38009,0.13882,46.44798,0.41686,20.84303
526.77603,43.89776,5785.70403,0.13881,46.48272,0.41782,20.89111
527.97603,43.99788,5792.35815,0.13881,46.53618,0.41878,20.93924
529.17603,44.09776,5796.15198,0.13881,46.56666,0.41975,20.98726
530.37603,44.19780,5803.13578,0.13892,46.62277,0.42071,21.03536
531.57603,44.29772,5808.11128,0.13873,46.66274,0.42167,21.08340
532.77603,44.39796,5816.28121,0.13886,46.72838,0.42263,21.13159
533.97603,44.49780,5820.20395,0.13879,46.75989,0.42359,21.17959
535.17603,44.59780,5825.47151,0.13881,46.80221,0.42455,21.22767
536.37603,44.69768,5829.67028,0.13880,46.83595,0.42551,21.27568
537.57603,44.79788,5834.96876,0.13887,46.87851,0.42648,21.32386
538.77603,44.89792,5838.89782,0.13880,46.91008,0.42744,21.37195
539.97603,44.99772,5844.65154,0.13885,46.95631,0.42840,21.41993
541.17603,45.09772,5848.53813,0.13882,46.98753,0.42936,21.46801
542.37603,45.19780,5854.51759,0.13881,47.03557,0.43032,21.51613
543.57603,45.29788,5859.12950,0.13882,47.07262,0.43128,21.56424
544.77603,45.39772,5865.06203,0.13880,47.12029,0.43224,21.61224
545.97603,45.49776,5868.45987,0.13897,47.14758,0.43321,21.66034
547.17603,45.59780,5872.51298,0.13874,47.18015,0.43417,21.70844
548.37603,45.69796,5875.47384,0.13883,47.20394,0.43513,21.75659
549.57603,45.79776,5879.40849,0.13880,47.23555,0.43609,21.80457
550.77603,45.89780,5882.31049,0.13884,47.25886,0.43705,21.85267
551.97603,45.99772,5886.85870,0.13881,47.29540,0.43801,21.90070
553.17603,46.09792,5891.13347,0.13882,47.32975,0.43898,21.94888
554.37603,46.19780,5894.64754,0.13881,47.35798,0.43994,21.99690
555.57603,46.29772,5897.33571,0.13879,47.37958,0.44090,22.04494
556.77603,46.39776,5902.19311,0.13881,47.41860,0.44186,22.09303
557.97603,46.49788,5904.82205,0.13883,47.43972,0.44282,22.14117
559.17603,46.59788,5907.95390,0.13882,47.46488,0.44378,22.18924
560.37603,46.69768,5908.66655,0.13882,47.47061,0.44474,22.23722
561.57603,46.79772,5912.28791,0.13880,47.49970,0.44571,22.28532
562.77603,46.89784,5914.78683,0.13882,47.51978,0.44667,22.33345
563.97603,46.99792,5918.08707,0.13881,47.54629,0.44763,22.38157
565.17603,47.09776,5919.62002,0.13882,47.55861,0.44859,22.42957
566.37603,47.19780,5923.75509,0.13869,47.59183,0.44955,22.47766
567.57603,47.29768,5925.42663,0.13886,47.60526,0.45051,22.52568
568.77603,47.39792,5929.71481,0.13881,47.63971,0.45148,22.57388
569.97603,47.49772,5930.45801,0.13883,47.64568,0.45244,22.62186
571.17603,47.59776,5933.35293,0.13881,47.66894,0.45340,22.66995
572.37603,47.69772,5935.74122,0.13881,47.68813,0.45436,22.71801
573.57603,47.79788,5937.84302,0.13881,47.70501,0.45532,22.76617
574.77603,47.89780,5939.58944,0.13885,47.71904,0.45628,22.81420
575.97603,47.99772,5941.64059,0.13882,47.73552,0.45724,22.86224
577.17603,48.09768,5943.03273,0.13876,47.74671,0.45821,22.91030
578.37603,48.19792,5946.03829,0.13877,47.77085,0.45917,22.95849
579.57603,48.29784,5947.84357,0.13885,47.78536,0.46013,23.00653
580.77603,48.39776,5951.33305,0.13879,47.81339,0.46109,23.05457
581.97603,48.49776,5953.70308,0.13882,47.83243,0.46205,23.10265
583.17603,48.59780,5956.72056,0.13884,47.85668,0.46301,23.15074
584.37603,48.69796,5958.15778,0.13880,47.86822,0.46398,23.19890
585.57603,48.79776,5958.86856,0.13881,47.87393,0.46494,23.24688
586.77603,48.89776,5959.84496,0.13883,47.88178,0.46590,23.29496
587.97603,48.99776,5962.25634,0.13880,47.90115,0.46686,23.34303
589.17603,49.09788,5964.42260,0.13885,47.91856,0.46782,23.39117
590.37603,49.19776,5966.32771,0.13877,47.93386,0.46878,23.43919
591.57603,49.29768,5968.20116,0.13882,47.94891,0.46974,23.48722
592.77603,49.39768,5971.47346,0.13881,47.97520,0.47071,23.53530
593.97603,49.49796,5972.90248,0.13882,47.98668,0.47167,23.58351
595.17603,49.59776,5975.61076,0.13882,48.00844,0.47263,23.63149
596.37603,49.69772,5976.27498,0.13880,48.01378,0.47359,23.67955
597.57603,49.79780,5979.31705,0.13882,48.03822,0.47455,23.72767
598.77603,49.89788,5980.86528,0.13879,48.05066,0.47552,23.77578
599.97603,49.99788,5983.95206,0.13885,48.07546,0.47648,23.82386
601.17603,50.09776,5985.23319,0.13877,48.08575,0.47744,23.87188
602.37603,50.19772,5988.51070,0.13882,48.11208,0.47840,23.91993
603.57603,50.29780,5990.53018,0.13880,48.12831,0.47936,23.96805
604.77603,50.39792,5994.28676,0.13879,48.15849,0.48032,24.01619
605.97603,50.49780,5994.68313,0.13883,48.16167,0.48128,24.06420
607.17603,50.59776,5997.48231,0.13880,48.18416,0.48225,24.11226
608.37603,50.69772,5999.33267,0.13878,48.19903,0.48321,24.16032
609.57603,50.79796,6001.69376,0.13884,48.21799,0.48417,24.20851
610.77603,50.89768,6003.19505,0.13879,48.23006,0.48513,24.25645
611.97603,50.99776,6006.41929,0.13881,48.25596,0.48609,24.30457
613.17603,51.09776,6008.16123,0.13881,48.26995,0.48705,24.35265
614.37603,51.19788,6012.11712,0.13882,48.30174,0.48802,24.40078
615.57603,51.29776,6014.26549,0.13881,48.31900,0.48898,24.44880
616.77603,51.39780,6018.46576,0.13882,48.35274,0.48994,24.49689
617.97603,51.49776,6020.30382,0.13882,48.36751,0.49090,24.54496
619.17603,51.59780,6024.27013,0.13885,48.39937,0.49186,24.59305
620.37603,51.69784,6025.84817,0.13879,48.41205,0.49282,24.64115
621.57603,51.79776,6029.23930,0.13882,48.43930,0.49378,24.68919
622.77603,51.89772,6030.91493,0.13879,48.45276,0.49474,24.73724
623.97603,51.99776,6034.25130,0.13890,48.47956,0.49571,24.78534
625.17603,52.09792,6036.52671,0.13886,48.49784,0.49667,24.83349
626.37603,52.19768,6040.42746,0.13880,48.52918,0.49763,24.88145
627.57603,52.29768,6043.30562,0.13881,48.55231,0.49859,24.92953
628.77603,52.39780,6048.57169,0.13885,48.59461,0.49955,24.97767
629.97603,52.49788,6050.20449,0.13878,48.60773,0.50052,25.02578
631.17603,52.59776,6052.80437,0.13882,48.62862,0.50148,25.07380
632.37603,52.69784,6055.76262,0.13879,48.65239,0.50244,25.12192
633.57603,52.79780,6059.39478,0.13880,48.68157,0.50340,25.16997
634.77603,52.89784,6059.88428,0.13881,48.68550,0.50436,25.21807
635.97603,52.99776,6062.36793,0.13865,48.70545,0.50532,25.26611
637.17603,53.09776,6064.95216,0.13889,48.72622,0.50628,25.31418
638.37603,53.19776,6070.90853,0.13876,48.77407,0.50725,25.36226
639.57603,53.29780,6074.10744,0.13883,48.79977,0.50821,25.41036
640.77603,53.39780,6077.63492,0.13880,48.82811,0.50917,25.45843
641.97603,53.49776,6080.64309,0.13881,48.85228,0.51013,25.50649
643.17603,53.59772,6084.98566,0.13882,48.88717,0.51109,25.55455
644.37603,53.69788,6087.91970,0.13892,48.91074,0.51205,25.60270
645.57603,53.79784,6091.00722,0.13876,48.93554,0.51302,25.65076
646.77603,53.89780,6092.44071,0.13883,48.94706,0.51398,25.69882
647.97603,53.99776,6097.48848,0.13880,48.98762,0.51494,25.74688
649.17603,54.09784,6101.31286,0.13882,49.01834,0.51590,25.79499
650.37603,54.19788,6106.08682,0.13882,49.05669,0.51686,25.84309
651.57603,54.29776,6109.17546,0.13881,49.08151,0.51782,25.89111
652.77603,54.39780,6114.09359,0.13882,49.12102,0.51878,25.93921
653.97603,54.49788,6117.65683,0.13863,49.14965,0.51975,25.98732
655.17603,54.59784,6121.60303,0.13886,49.18135,0.52071,26.03538
656.37603,54.69776,6124.25953,0.13877,49.20270,0.52167,26.08342
657.57603,54.79776,6128.59540,0.13883,49.23753,0.52263,26.13149
658.77603,54.89772,6131.17963,0.13879,49.25829,0.52359,26.17955
659.97603,54.99788,6136.13352,0.13881,49.29809,0.52455,26.22770
661.17603,55.09772,6139.53099,0.13881,49.32539,0.52551,26.27570
662.37603,55.19784,6144.90733,0.13882,49.36858,0.52648,26.32384
663.57603,55.29772,6148.04216,0.13879,49.39377,0.52744,26.37186
664.77603,55.39792,6153.80555,0.13884,49.44007,0.52840,26.42003
665.97603,55.49788,6157.55394,0.13879,49.47019,0.52936,26.46809
667.17603,55.59784,6161.67672,0.13882,49.50331,0.53032,26.51615
668.37603,55.69780,6166.29086,0.13883,49.54038,0.53128,26.56420
669.57603,55.79784,6170.26724,0.13879,49.57232,0.53225,26.61230
670.77603,55.89788,6173.89865,0.13881,49.60150,0.53321,26.66040
671.97603,55.99776,6177.79903,0.13880,49.63284,0.53417,26.70842
673.17603,56.09776,6181.52246,0.13884,49.66275,0.53513,26.75649
674.37603,56.19776,6187.28437,0.13880,49.70904,0.53609,26.80457
675.57603,56.29784,6191.56286,0.13881,49.74341,0.53705,26.85268
676.77603,56.39772,6197.33706,0.13880,49.78981,0.53801,26.90070
677.97603,56.49788,6200.65220,0.13882,49.81644,0.53898,26.94886
679.17603,56.59780,6206.41001,0.13871,49.86270,0.53994,26.99690
680.37603,56.69792,6210.23662,0.13888,49.89344,0.54090,27.04503
681.57603,56.79780,6213.57672,0.13878,49.92028,0.54186,27.09305
682.77603,56.89780,6216.29469,0.13883,49.94211,0.54282,27.14113
683.97603,56.99784,6222.00407,0.13880,49.98798,0.54378,27.18922
685.17603,57.09784,6225.39297,0.13881,50.01521,0.54475,27.23730
686.37603,57.19780,6230.06783,0.13879,50.05277,0.54571,27.28536
687.57603,57.29772,6233.14008,0.13874,50.07745,0.54667,27.33340
688.77603,57.39776,6239.37361,0.13891,50.12753,0.54763,27.38149
689.97603,57.49788,6243.25983,0.13877,50.15875,0.54859,27.42963
691.17603,57.59784,6247.30773,0.13883,50.19127,0.54955,27.47769
692.37603,57.69772,6249.87297,0.13881,50.21188,0.55051,27.52570
693.57603,57.79780,6254.31687,0.13881,50.24758,0.55148,27.57382
694.77603,57.89784,6258.09729,0.13881,50.27796,0.55244,27.62191
695.97603,57.99788,6262.22119,0.13880,50.31109,0.55340,27.67001
697.17603,58.09780,6266.45833,0.13882,50.34513,0.55436,27.71805
698.37603,58.19776,6270.66344,0.13881,50.37891,0.55532,27.76611
699.57603,58.29780,6273.57364,0.13864,50.40229,0.55628,27.81420
700.77603,58.39788,6279.22937,0.13891,50.44773,0.55725,27.86232
701.97603,58.49780,6282.23643,0.13876,50.47189,0.55821,27.91036
703.17603,58.59780,6286.00270,0.13885,50.50215,0.55917,27.95844
704.37603,58.69776,6288.12686,0.13880,50.51922,0.56013,28.00649
705.57603,58.79792,6291.11305,0.13879,50.54321,0.56109,28.05465
706.77603,58.89776,6292.32153,0.13878,50.55292,0.56205,28.10264
707.97603,58.99776,6295.40756,0.13882,50.57771,0.56301,28.15072
709.17603,59.09780,6297.63529,0.13882,50.59561,0.56398,28.19882
710.37603,59.19784,6300.13645,0.13882,50.61570,0.56494,28.24692
711.57603,59.29784,6301.95439,0.13882,50.63031,0.56590,28.29499
712.77603,59.39784,6305.16261,0.13882,50.65608,0.56686,28.34307
713.97603,59.49776,6307.25846,0.13889,50.67292,0.56782,28.39111
715.17603,59.59788,6310.10681,0.13879,50.69580,0.56878,28.43924
716.37603,59.69788,6309.98984,0.13884,50.69486,0.56975,28.48732
717.57603,59.79776,6310.58812,0.13880,50.69967,0.57071,28.53534
718.77603,59.89780,6312.57072,0.13881,50.71560,0.57167,28.58344
719.97603,59.99780,6313.50055,0.13881,50.72307,0.57263,28.63151
721.17603,60.09792,6314.03252,0.13890,50.72734,0.57359,28.67965
722.37603,60.19768,6315.31999,0.13878,50.73769,0.57455,28.72761
723.57603,60.29776,6314.98247,0.13881,50.73498,0.57551,28.77572
724.77603,60.39780,6317.85914,0.13884,50.75809,0.57648,28.82382
725.97603,60.49788,6318.14077,0.13884,50.76035,0.57744,28.87194
727.17603,60.59776,6319.55490,0.13882,50.77171,0.57840,28.91995
728.37603,60.69784,6320.79318,0.13880,50.78166,0.57936,28.96807
729.57603,60.79780,6320.61809,0.13891,50.78025,0.58032,29.01613
730.77603,60.89792,6321.18806,0.13881,50.78483,0.58129,29.06426
731.97603,60.99784,6322.76982,0.13881,50.79754,0.58225,29.11230
733.17603,61.09776,6323.27273,0.13883,50.80158,0.58321,29.16034
734.37603,61.19780,6324.62204,0.13880,50.81242,0.58417,29.20844
735.57603,61.29784,6325.95345,0.13884,50.82312,0.58513,29.25653
736.77603,61.39800,6329.20414,0.13882,50.84923,0.58609,29.30469
737.97604,61.49772,6329.76741,0.13882,50.85376,0.58705,29.35263
739.17604,61.59784,6332.36319,0.13883,50.87461,0.58802,29.40076
740.37604,61.69784,6333.96730,0.13882,50.88750,0.58898,29.44884
741.57604,61.79788,6336.14734,0.13893,50.90502,0.58994,29.49693
742.77604,61.89772,6337.33496,0.13876,50.91456,0.59090,29.54494
743.97604,61.99784,6339.48371,0.13884,50.93182,0.59186,29.59307
745.17604,62.09780,6341.40149,0.13882,50.94723,0.59282,29.64113
746.37604,62.19784,6345.12305,0.13882,50.97713,0.59378,29.68922
747.57604,62.29768,6347.26286,0.13884,50.99432,0.59474,29.73722
748.77604,62.39780,6350.95984,0.13885,51.02402,0.59571,29.78536
749.97604,62.49788,6353.20842,0.13883,51.04209,0.59667,29.83347
751.17604,62.59784,6356.50232,0.13881,51.06855,0.59763,29.88153
752.37604,62.69784,6357.76445,0.13883,51.07869,0.59859,29.92961
753.57604,62.79776,6360.07488,0.13880,51.09725,0.59955,29.97765
754.77604,62.89784,6363.61241,0.13882,51.12567,0.60052,30.02576
755.97604,62.99784,6366.30282,0.13875,51.14729,0.60148,30.07384
757.17604,63.09784,6370.04226,0.13884,51.17733,0.60244,30.12192
758.37604,63.19768,6373.39354,0.13881,51.20425,0.60340,30.16992
759.57604,63.29776,6376.24562,0.13885,51.22717,0.60436,30.21803
760.77604,63.39788,6381.86559,0.13882,51.27232,0.60532,30.26617
761.97604,63.49784,6383.97038,0.13882,51.28923,0.60628,30.31422
763.17604,63.59772,6387.28812,0.13879,51.31588,0.60724,30.36224
764.37604,63.69776,6389.96214,0.13886,51.33737,0.60821,30.41034
765.57604,63.79785,6393.82228,0.13881,51.36838,0.60917,30.45846
766.77604,63.89784,6396.73844,0.13884,51.39181,0.61013,30.50653
767.97604,63.99781,6401.33917,0.13882,51.42877,0.61109,30.55459
769.17604,64.09776,6404.80518,0.13885,51.45662,0.61205,30.60265
770.37604,64.19780,6411.06591,0.13874,51.50692,0.61301,30.65074
771.57604,64.29780,6414.58184,0.13887,51.53516,0.61398,30.69882
772.77604,64.39780,6419.25931,0.13880,51.57274,0.61494,30.74690
773.97604,64.49776,6423.54861,0.13884,51.60720,0.61590,30.79495
775.17604,64.59780,6429.25724,0.13882,51.65307,0.61686,30.84305
776.37604,64.69784,6432.84097,0.13883,51.68186,0.61782,30.89115
777.57604,64.79784,6436.78755,0.13882,51.71357,0.61878,30.93922
778.77604,64.89772,6440.73561,0.13888,51.74528,0.61974,30.98724
779.97604,64.99772,6444.69857,0.13880,51.77712,0.62071,31.03532
781.17604,65.09788,6449.29633,0.13884,51.81406,0.62167,31.08348
782.37604,65.19784,6454.68086,0.13882,51.85732,0.62263,31.13153
783.57604,65.29772,6458.63265,0.13883,51.88907,0.62359,31.17955
784.77604,65.39776,6464.89486,0.13884,51.93938,0.62455,31.22765
785.97604,65.49792,6468.87869,0.13882,51.97139,0.62552,31.27580
787.17604,65.59780,6473.27825,0.13878,52.00673,0.62648,31.32382
788.37604,65.69772,6476.37695,0.13883,52.03163,0.62744,31.37186
789.57604,65.79776,6482.30240,0.13882,52.07924,0.62840,31.41995
790.77604,65.89780,6486.54625,0.13881,52.11333,0.62936,31.46805
791.97604,65.99788,6491.25949,0.13884,52.15120,0.63032,31.51617
793.17604,66.09777,6494.83055,0.13872,52.17989,0.63128,31.56419
794.37604,66.19776,6501.93244,0.13887,52.23694,0.63225,31.61226
795.57604,66.29772,6505.93862,0.13880,52.26913,0.63321,31.66032
796.77604,66.39788,6512.60838,0.13883,52.32272,0.63417,31.70847
797.97604,66.49784,6516.47747,0.13882,52.35380,0.63513,31.75653
799.17604,66.59772,6522.02740,0.13898,52.39839,0.63609,31.80455
800.37604,66.69780,6526.98055,0.13875,52.43818,0.63705,31.85267
801.57604,66.79788,6531.43302,0.13886,52.47395,0.63802,31.90078
802.77604,66.89785,6535.65675,0.13882,52.50789,0.63898,31.94884
803.97604,66.99776,6540.95933,0.13884,52.55049,0.63994,31.99688
805.17604,67.09772,6545.53473,0.13882,52.58725,0.64090,32.04494
806.37604,67.19780,6551.69487,0.13885,52.63674,0.64186,32.09305
807.57604,67.29780,6555.66230,0.13884,52.66861,0.64282,32.14112
808.77604,67.39777,6562.44382,0.13884,52.72310,0.64378,32.18919
809.97604,67.49780,6567.65401,0.13881,52.76496,0.64475,32.23728
811.17604,67.59776,6572.27337,0.13883,52.80207,0.64571,32.28534
812.37604,67.69780,6577.42620,0.13883,52.84347,0.64667,32.33344
813.57604,67.79776,6582.05524,0.13884,52.88066,0.64763,32.38149
814.77604,67.89776,6586.77593,0.13879,52.91858,0.64859,32.42957
815.97604,67.99780,6592.20591,0.13888,52.96221,0.64955,32.47767
817.17604,68.09788,6596.92287,0.13882,53.00010,0.65052,32.52578
818.37604,68.19772,6602.10177,0.13883,53.04171,0.65148,32.57378
819.57604,68.29776,6606.48793,0.13883,53.07695,0.65244,32.62188
820.77604,68.39780,6612.81347,0.13882,53.12777,0.65340,32.66997
821.97604,68.49784,6618.15628,0.13883,53.17069,0.65436,32.71807
823.17604,68.59784,6622.71902,0.13895,53.20735,0.65532,32.76615
824.37604,68.69772,6626.73190,0.13875,53.23959,0.65628,32.81417
825.57604,68.79780,6631.40416,0.13885,53.27713,0.65725,32.86228
826.77604,68.89781,6636.18818,0.13881,53.31556,0.65821,32.91036
827.97604,68.99780,6640.55794,0.13882,53.35067,0.65917,32.95843
829.17604,69.09776,6645.83594,0.13877,53.39307,0.66013,33.00650
830.37604,69.19772,6651.19886,0.13891,53.43616,0.66109,33.05455
831.57604,69.29776,6655.87634,0.13878,53.47374,0.66205,33.10265
832.77604,69.39788,6662.89702,0.13884,53.53014,0.66302,33.15078
833.97604,69.49773,6666.77281,0.13882,53.56128,0.66398,33.19878
835.17604,69.59780,6672.45612,0.13882,53.60694,0.66494,33.24690
836.37604,69.69784,6676.98383,0.13882,53.64332,0.66590,33.29499
837.57604,69.79784,6681.62331,0.13882,53.68059,0.66686,33.34307
838.77604,69.89772,6685.10273,0.13896,53.70855,0.66782,33.39109
839.97604,69.99776,6691.24052,0.13875,53.75786,0.66878,33.43919
841.17604,70.09784,6695.19305,0.13886,53.78961,0.66975,33.48730
842.37604,70.19784,6700.42485,0.13880,53.83164,0.67071,33.53538
843.57604,70.29768,6704.42656,0.13883,53.86379,0.67167,33.58338
844.77604,70.39780,6711.41967,0.13881,53.91998,0.67263,33.63151
845.97604,70.49777,6714.49378,0.13883,53.94468,0.67359,33.67957
847.17604,70.59780,6720.21732,0.13885,53.99066,0.67455,33.72767
848.37604,70.69788,6724.41572,0.13881,54.02439,0.67552,33.77578
849.57604,70.79773,6728.10599,0.13883,54.05404,0.67648,33.82378
850.77604,70.89780,6732.52270,0.13880,54.08952,0.67744,33.87190
851.97604,70.99780,6737.23370,0.13885,54.12737,0.67840,33.91997
853.17604,71.09784,6741.67201,0.13880,54.16303,0.67936,33.96807
854.37604,71.19764,6746.62217,0.13885,54.20280,0.68032,34.01605
855.57604,71.29776,6751.48666,0.13891,54.24188,0.68128,34.06419
856.77604,71.39784,6758.23390,0.13874,54.29609,0.68225,34.11230
857.97604,71.49784,6762.01582,0.13884,54.32647,0.68321,34.16038
859.17604,71.59768,6767.10382,0.13884,54.36735,0.68417,34.20837
860.37604,71.69780,6771.13608,0.13883,54.39974,0.68513,34.25651
861.57604,71.79780,6776.26282,0.13880,54.44093,0.68609,34.30459
862.77604,71.89784,6779.98215,0.13875,54.47081,0.68705,34.35269
863.97604,71.99784,6784.87942,0.13889,54.51016,0.68802,34.40076
865.17604,72.09772,6789.05621,0.13881,54.54372,0.68898,34.44878
866.37604,72.19780,6794.29546,0.13884,54.58581,0.68994,34.49690
867.57604,72.29784,6798.02150,0.13882,54.61574,0.69090,34.54499
868.77604,72.39788,6804.63314,0.13882,54.66886,0.69186,34.59309
869.97604,72.49768,6807.91140,0.13888,54.69520,0.69282,34.64107
871.17604,72.59780,6813.94711,0.13880,54.74369,0.69378,34.68920
872.37604,72.69789,6818.58435,0.13883,54.78095,0.69475,34.73732
873.57604,72.79788,6823.14634,0.13882,54.81760,0.69571,34.78539
874.77604,72.89764,6826.18245,0.13868,54.84199,0.69667,34.83336
875.97604,72.99780,6832.05500,0.13888,54.88917,0.69763,34.88151
877.17604,73.09780,6836.03808,0.13878,54.92117,0.69859,34.92959
878.37604,73.19780,6841.59696,0.13885,54.96583,0.69955,34.97767
879.57604,73.29772,6846.33926,0.13882,55.00393,0.70051,35.02571
880.77604,73.39776,6852.13506,0.13882,55.05049,0.70148,35.07380
881.97604,73.49784,6857.69543,0.13883,55.09517,0.70244,35.12192
883.17604,73.59792,6862.45561,0.13883,55.13341,0.70340,35.17003
884.37604,73.69788,6865.80464,0.13884,55.16032,0.70436,35.21809
885.57604,73.79776,6869.50386,0.13883,55.19004,0.70532,35.26611
886.77604,73.89784,6873.68885,0.13882,55.22366,0.70628,35.31422
887.97604,73.99788,6878.42295,0.13884,55.26169,0.70725,35.36232
889.17604,74.09789,6882.32929,0.13881,55.29308,0.70821,35.41040
890.37604,74.19768,6887.30255,0.13882,55.33303,0.70917,35.45838
891.57604,74.29776,6891.11948,0.13879,55.36370,0.71013,35.50649
892.77604,74.39788,6897.53592,0.13893,55.41525,0.71109,35.55463
893.97604,74.49784,6900.96319,0.13874,55.44278,0.71205,35.60268
895.17604,74.59769,6906.02586,0.13886,55.48346,0.71301,35.65069
896.37604,74.69776,6910.12889,0.13882,55.51642,0.71398,35.69880
897.57604,74.79788,6915.01871,0.13886,55.55571,0.71494,35.74694
898.77604,74.89788,6918.61212,0.13881,55.58458,0.71590,35.79501
899.97604,74.99776,6922.06249,0.13883,55.61230,0.71686,35.84303
901.17604,75.09781,6926.05972,0.13873,55.64441,0.71782,35.89113
902.37604,75.19784,6932.38974,0.13888,55.69527,0.71878,35.93923
903.57604,75.29784,6936.69319,0.13881,55.72984,0.71975,35.98730
904.77604,75.39784,6941.37067,0.13885,55.76742,0.72071,36.03538
905.97604,75.49776,6945.35375,0.13885,55.79942,0.72167,36.08341
907.17604,75.59780,6950.34564,0.13880,55.83952,0.72263,36.13151
908.37604,75.69792,6954.02250,0.13885,55.86906,0.72359,36.17964
909.57604,75.79784,6959.16787,0.13881,55.91040,0.72455,36.22768
910.77604,75.89772,6962.76724,0.13884,55.93932,0.72551,36.27571
911.97604,75.99772,6967.99830,0.13884,55.98135,0.72648,36.32378
913.17604,76.09788,6971.84354,0.13884,56.01224,0.72744,36.37194
914.37604,76.19784,6977.19753,0.13889,56.05525,0.72840,36.41999
915.57604,76.29772,6980.78573,0.13882,56.08408,0.72936,36.46801
916.77604,76.39781,6985.93035,0.13884,56.12541,0.73032,36.51613
917.97604,76.49784,6990.21891,0.13882,56.15987,0.73128,36.56422
919.17604,76.59792,6995.80312,0.13884,56.20473,0.73225,36.61234
920.37604,76.69772,6998.07554,0.13895,56.22299,0.73321,36.66032
921.57604,76.79780,7002.84839,0.13880,56.26134,0.73417,36.70844
922.77604,76.89776,7006.06704,0.13884,56.28719,0.73513,36.75649
923.97604,76.99788,7010.08365,0.13882,56.31946,0.73609,36.80463
925.17604,77.09780,7011.95076,0.13883,56.33446,0.73705,36.85267
926.37604,77.19772,7016.39578,0.13884,56.37018,0.73801,36.90070
927.57604,77.29768,7018.86266,0.13883,56.38999,0.73898,36.94876
928.77604,77.39796,7023.58112,0.13884,56.42790,0.73994,36.99698
929.97604,77.49788,7026.77742,0.13882,56.45358,0.74090,37.04501
931.17604,77.59772,7029.88952,0.13885,56.47859,0.74186,37.09301
932.37604,77.69780,7032.63953,0.13889,56.50068,0.74282,37.14113
933.57604,77.79785,7035.00137,0.13880,56.51965,0.74378,37.18923
934.77604,77.89792,7037.51296,0.13884,56.53983,0.74475,37.23734
935.97604,77.99772,7040.50213,0.13883,56.56385,0.74571,37.28532
937.17604,78.09781,7042.43034,0.13862,56.57934,0.74667,37.33344
938.37604,78.19785,7045.12969,0.13892,56.60103,0.74763,37.38153
939.57604,78.29784,7039.94036,0.13879,56.55933,0.74859,37.42961
940.77604,78.39777,7030.68823,0.13886,56.48500,0.74955,37.47765
941.97604,78.49776,7012.04240,0.13882,56.33520,0.75051,37.52572
943.17604,78.59780,6966.61249,0.13884,55.97021,0.75148,37.57382
944.02004,78.66857,718.11886,0.13881,5.76941,0.75216,37.60784