File: Calibration Data/test_PC_ASTM638.is_tens_RawData/Specimen_RawData_3.csv
Operator,"Quentin Govignon"
Our Reference Number,""
Customer Reference,""
Temperature (°C),21.0
Humidity (%),50.
Load Frame,"Instron Model 1185"
Crosshead Speed 1,5.00,mm/min
Extensometer G.L.,"50 mm"
Specimen Name,"PC #3"
Geometry,Rectangular
Length,104.00,mm
Maximum Load,8128.22357,N
Maximum Tensile stress,65.00322,MPa
Modulus (Chord 0.05 % - 0.25 %),2426.41485,MPa
Modulus (Young's 0.025 % - 0.5 %),2518.69052,MPa
Extension at Break (Standard),57.68228,mm
Specimen note 1,""
Specimen note 2,""
Specimen note 3,""

Time,Extension,Load,Strain 1,Tensile stress,Tensile strain,Tensile extension
(sec),(mm),(N),(mm/mm),(MPa),(mm/mm),(mm)
0.00000,-0.00004,0.84260,0.00000,0.00674,0.00000,0.00002
0.90000,0.07392,148.45129,0.00050,1.18720,0.00050,0.02482
1.80000,0.14980,318.77928,0.00103,2.54935,0.00103,0.05143
2.70000,0.22504,493.84516,0.00160,3.94939,0.00160,0.08020
3.60000,0.29996,662.12541,0.00217,5.29516,0.00217,0.10837
4.50000,0.37504,828.23113,0.00275,6.62355,0.00275,0.13757
5.40000,0.45000,1007.59454,0.00337,8.05796,0.00337,0.16864
6.30000,0.52488,1173.10304,0.00396,9.38157,0.00396,0.19779
7.20000,0.60016,1349.19062,0.00458,10.78978,0.00458,0.22886
8.10000,0.67500,1512.00481,0.00515,12.09184,0.00515,0.25741
9.00000,0.75008,1682.45584,0.00577,13.45498,0.00577,0.28852
9.90000,0.82500,1843.41464,0.00635,14.74220,0.00635,0.31754
10.80000,0.89992,2008.92165,0.00695,16.06580,0.00695,0.34767
11.70000,0.97496,2167.04737,0.00754,17.33036,0.00754,0.37708
12.60000,1.04988,2329.42887,0.00815,18.62896,0.00815,0.40736
13.50000,1.12500,2483.28280,0.00873,19.85937,0.00873,0.43649
14.40000,1.19988,2636.71428,0.00932,21.08639,0.00932,0.46590
15.30000,1.27520,2794.18416,0.00992,22.34571,0.00992,0.49617
16.20000,1.34988,2942.98474,0.01051,23.53571,0.01051,0.52572
17.10000,1.42496,3091.16114,0.01110,24.72071,0.01110,0.55501
18.00000,1.49992,3239.96171,0.01170,25.91070,0.01170,0.58511
18.90000,1.57488,3381.10365,0.01228,27.03944,0.01228,0.61385
19.80000,1.65016,3527.05717,0.01290,28.20666,0.01290,0.64476
20.70000,1.72488,3661.66458,0.01346,29.28315,0.01346,0.67313
21.60000,1.80004,3794.61683,0.01404,30.34640,0.01404,0.70183
22.50000,1.87496,3933.49119,0.01464,31.45701,0.01464,0.73213
23.40000,1.94992,4060.54035,0.01521,32.47305,0.01521,0.76057
24.30000,2.02496,4196.58273,0.01583,33.56101,0.01583,0.79143
25.20000,2.09992,4320.00831,0.01640,34.54807,0.01640,0.82015
26.10000,2.17512,4440.76173,0.01698,35.51376,0.01698,0.84902
27.00000,2.25000,4570.23829,0.01760,36.54922,0.01760,0.87993
27.90000,2.32496,4673.89897,0.01812,37.37821,0.01812,0.90585
28.80000,2.39996,4799.20544,0.01875,38.38032,0.01875,0.93735
29.70000,2.47504,4890.82113,0.01923,39.11299,0.01923,0.96148
30.60000,2.54992,4978.04731,0.01970,39.81056,0.01970,0.98500
31.50000,2.62488,5097.06959,0.02033,40.76240,0.02033,1.01632
32.40000,2.70008,5174.70837,0.02078,41.38330,0.02078,1.03885
33.30000,2.77504,5292.49236,0.02141,42.32524,0.02141,1.07049
34.20000,2.85008,5365.64514,0.02185,42.91026,0.02185,1.09233
35.10000,2.92492,5477.74062,0.02248,43.80672,0.02248,1.12400
36.00000,2.99992,5540.84517,0.02289,44.31138,0.02289,1.14431
36.90000,3.07504,5618.39379,0.02336,44.93155,0.02336,1.16807
37.80000,3.14992,5699.97914,0.02388,45.58401,0.02388,1.19388
38.70000,3.22512,5782.84897,0.02440,46.24673,0.02440,1.22022
39.60000,3.29992,5862.00431,0.02492,46.87976,0.02492,1.24592
40.50000,3.37504,5943.32851,0.02545,47.53013,0.02545,1.27256
41.40000,3.45004,6022.03757,0.02599,48.15958,0.02599,1.29929
42.30000,3.52488,6099.33585,0.02653,48.77775,0.02653,1.32636
43.20000,3.59996,6175.07212,0.02707,49.38343,0.02707,1.35347
44.10000,3.67496,6249.22030,0.02761,49.97641,0.02761,1.38050
45.00000,3.75016,6324.94763,0.02816,50.58202,0.02816,1.40812
45.90000,3.82496,6396.65574,0.02873,51.15548,0.02873,1.43625
46.80000,3.90008,6466.39317,0.02928,51.71319,0.02928,1.46391
47.70000,3.97496,6536.07845,0.02984,52.27048,0.02984,1.49218
48.60000,4.05004,6606.47079,0.03042,52.83342,0.03042,1.52088
49.50000,4.12488,6672.20280,0.03099,53.35910,0.03099,1.54949
50.40000,4.19988,6738.56884,0.03158,53.88984,0.03158,1.57881
51.30000,4.27520,6803.09832,0.03217,54.40590,0.03217,1.60829
52.20000,4.34996,6866.66965,0.03277,54.91429,0.03277,1.63828
53.10000,4.42504,6928.73299,0.03337,55.41063,0.03337,1.66844
54.00000,4.49996,6988.27952,0.03396,55.88683,0.03396,1.69816
54.90000,4.57496,7047.98624,0.03458,56.36432,0.03458,1.72897
55.80000,4.65012,7105.91450,0.03520,56.82759,0.03520,1.76018
56.70000,4.72488,7162.60001,0.03582,57.28091,0.03582,1.79125
57.60000,4.80004,7218.91746,0.03646,57.73130,0.03646,1.82293
58.50000,4.87504,7270.77574,0.03709,58.14602,0.03709,1.85452
59.40000,4.94996,7322.28085,0.03774,58.55792,0.03774,1.88689
60.30000,5.02496,7372.92767,0.03838,58.96295,0.03838,1.91919
61.20000,5.09992,7420.63820,0.03903,59.34450,0.03903,1.95160
62.10000,5.17504,7467.33397,0.03969,59.71794,0.03969,1.98462
63.00000,5.24992,7513.88222,0.04036,60.09019,0.04036,2.01804
63.90000,5.32496,7558.52386,0.04105,60.44720,0.04105,2.05266
64.80000,5.40000,7602.14329,0.04175,60.79604,0.04175,2.08733
65.70000,5.47508,7642.07989,0.04243,61.11542,0.04243,2.12156
66.60000,5.55004,7680.31850,0.04312,61.42122,0.04312,2.15625
67.50000,5.62496,7718.41258,0.04384,61.72587,0.04384,2.19179
68.40000,5.70000,7754.11427,0.04455,62.01138,0.04455,2.22725
69.30000,5.77496,7788.41153,0.04527,62.28567,0.04527,2.26339
70.20000,5.85016,7822.67749,0.04602,62.55970,0.04602,2.30085
71.10000,5.92488,7851.65727,0.04675,62.79146,0.04675,2.33741
72.00000,6.00000,7888.01089,0.04755,63.08218,0.04755,2.37736
72.90000,6.07504,7920.88434,0.04836,63.34508,0.04836,2.41794
73.80000,6.14992,7951.90111,0.04920,63.59313,0.04920,2.45989
74.70000,6.22508,7980.35413,0.05005,63.82067,0.05005,2.50261
75.60000,6.29988,8003.96204,0.05091,64.00947,0.05091,2.54543
76.50000,6.37516,7991.82206,0.05153,63.91239,0.05153,2.57657
77.40000,6.45000,8024.81994,0.05242,64.17628,0.05242,2.62114
78.30000,6.52504,8049.08276,0.05331,64.37031,0.05331,2.66564
79.20000,6.59992,8065.33247,0.05420,64.50027,0.05420,2.71023
80.10000,6.67500,8082.97843,0.05512,64.64138,0.05512,2.75608
81.00000,6.75004,8098.61496,0.05607,64.76643,0.05607,2.80342
81.90000,6.82496,8110.31386,0.05704,64.85999,0.05704,2.85194
82.80000,6.90004,8117.26600,0.05803,64.91559,0.05803,2.90130
83.70000,6.97500,8123.27191,0.05902,64.96362,0.05902,2.95118
84.60000,7.05012,8126.71557,0.06006,64.99116,0.06006,3.00292
85.50000,7.12496,8127.14994,0.06110,64.99463,0.06110,3.05494
86.40000,7.19984,8127.05159,0.06217,64.99385,0.06217,3.10865
87.30000,7.27520,8122.97165,0.06327,64.96122,0.06327,3.16374
88.20000,7.34996,8118.86936,0.06440,64.92841,0.06440,3.21993
89.10000,7.42504,8110.50087,0.06555,64.86149,0.06555,3.27773
90.00000,7.49992,8098.61571,0.06672,64.76644,0.06672,3.33612
90.90000,7.57496,8085.65021,0.06793,64.66275,0.06793,3.39638
91.80000,7.65004,8069.93470,0.06915,64.53707,0.06915,3.45759
92.68800,7.72376,8051.10708,0.07039,64.38650,0.07027,3.51364
93.58800,7.79888,8031.62307,0.07165,64.23068,0.07100,3.54976
94.48800,7.87376,8008.17013,0.07614,64.04313,0.07172,3.58576
95.38800,7.94888,7982.99462,0.26884,63.84179,0.07244,3.62188
96.28800,8.02384,7956.72387,0.14149,63.63170,0.07316,3.65791
97.18800,8.09880,7926.44396,0.11926,63.38954,0.07388,3.69395
98.08800,8.17388,7895.97258,0.21113,63.14586,0.07460,3.73005
98.98800,8.24880,7862.91510,0.14933,62.88149,0.07532,3.76607
99.88800,8.32380,7824.55578,0.14706,62.57472,0.07604,3.80213
100.78800,8.39872,7783.56045,0.14376,62.24687,0.07676,3.83814
101.68800,8.47392,7737.95843,0.14209,61.88218,0.07749,3.87430
102.58800,8.54880,7689.42460,0.14278,61.49405,0.07821,3.91030
103.48800,8.62388,7634.65986,0.14486,61.05608,0.07893,3.94639
104.38800,8.69884,7568.37428,0.14661,60.52598,0.07965,3.98243
105.28801,8.77376,7490.78915,0.14683,59.90551,0.08037,4.01845
106.18801,8.84904,7393.18281,0.14573,59.12493,0.08109,4.05464
107.08801,8.92372,7259.27576,0.14434,58.05405,0.08181,4.09055
107.98801,8.99892,7065.34833,0.14372,56.50317,0.08253,4.12670
108.88801,9.07388,6780.41801,0.14417,54.22452,0.08325,4.16274
109.78801,9.14888,6448.07145,0.14516,51.56667,0.08398,4.19880
110.68801,9.22376,6178.53105,0.14584,49.41109,0.08470,4.23480
111.58801,9.29876,6003.78960,0.14580,48.01365,0.08542,4.27086
112.48801,9.37396,5898.21525,0.14518,47.16934,0.08614,4.30701
113.38801,9.44888,5833.63585,0.14460,46.65289,0.08686,4.34303
114.28801,9.52384,5791.91782,0.14448,46.31926,0.08758,4.37907
115.18801,9.59880,5766.47855,0.14480,46.11582,0.08830,4.41511
116.08801,9.67392,5750.15470,0.14523,45.98527,0.08902,4.45122
116.98801,9.74884,5740.01409,0.14544,45.90417,0.08974,4.48724
117.88801,9.82372,5734.95924,0.14531,45.86375,0.09046,4.52324
118.78801,9.89888,5731.22948,0.14501,45.83392,0.09119,4.55938
119.68801,9.97384,5732.11312,0.14479,45.84099,0.09191,4.59541
120.58801,10.04892,5733.08691,0.14482,45.84878,0.09263,4.63151
121.48801,10.12368,5733.25045,0.14501,45.85008,0.09335,4.66745
122.38801,10.19868,5736.81705,0.14520,45.87861,0.09407,4.70351
123.28801,10.27388,5738.18944,0.14520,45.88958,0.09479,4.73966
124.18801,10.34872,5742.00302,0.14512,45.92008,0.09551,4.77564
125.08801,10.42400,5744.36598,0.14498,45.93898,0.09624,4.81184
125.98801,10.49876,5745.10843,0.14492,45.94492,0.09696,4.84778
126.88801,10.57392,5749.21556,0.14497,45.97776,0.09768,4.88391
127.78801,10.64888,5751.20002,0.14508,45.99363,0.09840,4.91995
128.68801,10.72372,5751.90149,0.14515,45.99924,0.09912,4.95593
129.58801,10.79880,5753.88260,0.14514,46.01508,0.09984,4.99203
130.48801,10.87388,5755.29113,0.14507,46.02635,0.10056,5.02813
131.38801,10.94888,5758.45949,0.14497,46.05169,0.10128,5.06418
132.28801,11.02380,5759.47016,0.14504,46.05977,0.10200,5.10020
133.18801,11.09880,5760.82617,0.14512,46.07061,0.10273,5.13626
134.08801,11.17388,5763.75760,0.14512,46.09406,0.10345,5.17236
134.98801,11.24888,5766.52139,0.14505,46.11616,0.10417,5.20841
135.88801,11.32372,5766.20586,0.14502,46.11364,0.10489,5.24439
136.78801,11.39872,5769.19951,0.14503,46.13758,0.10561,5.28045
137.68801,11.47396,5769.74489,0.14507,46.14194,0.10633,5.31663
138.58801,11.54884,5772.45578,0.14509,46.16362,0.10705,5.35263
139.48801,11.62392,5774.23312,0.14511,46.17783,0.10777,5.38872
140.38801,11.69880,5773.67172,0.14507,46.17334,0.10849,5.42472
141.28801,11.77380,5775.61297,0.14506,46.18887,0.10922,5.46078
142.18801,11.84884,5777.44097,0.14504,46.20349,0.10994,5.49686
143.08801,11.92376,5777.68683,0.14504,46.20545,0.11066,5.53288
143.98801,11.99888,5780.29156,0.14506,46.22628,0.11138,5.56899
144.88801,12.07396,5780.74083,0.14508,46.22988,0.11210,5.60509
145.78801,12.14884,5782.27378,0.14509,46.24214,0.11282,5.64109
146.68801,12.22380,5783.78811,0.14511,46.25425,0.11354,5.67713
147.58801,12.29876,5784.45718,0.14510,46.25960,0.11426,5.71316
148.48801,12.37388,5786.02441,0.14505,46.27213,0.11499,5.74928
149.38801,12.44880,5787.67955,0.14505,46.28537,0.11571,5.78530
150.28801,12.52380,5787.95485,0.14505,46.28757,0.11643,5.82136
151.18801,12.59884,5789.37978,0.14508,46.29896,0.11715,5.85743
152.08801,12.67396,5790.55920,0.14509,46.30840,0.11787,5.89355
152.98801,12.74884,5789.95794,0.14506,46.30359,0.11859,5.92955
153.88801,12.82376,5790.39976,0.14500,46.30712,0.11931,5.96557
154.78801,12.89884,5789.63682,0.14507,46.30102,0.12003,6.00166
155.68801,12.97380,5789.87487,0.14512,46.30292,0.12075,6.03770
156.58801,13.04900,5792.61668,0.14514,46.32485,0.12148,6.07386
157.48801,13.12372,5792.05379,0.14509,46.32035,0.12220,6.10978
158.38801,13.19884,5794.03713,0.14504,46.33621,0.12292,6.14589
159.28801,13.27392,5794.45586,0.14504,46.33956,0.12364,6.18199
160.18801,13.34876,5795.60213,0.14512,46.34872,0.12436,6.21797
161.08801,13.42384,5797.09560,0.14511,46.36067,0.12508,6.25407
161.98801,13.49880,5796.95553,0.14495,46.35955,0.12580,6.29011
162.88801,13.57396,5798.29141,0.14497,46.37023,0.12652,6.32624
163.78801,13.64888,5797.96992,0.14501,46.36766,0.12725,6.36226
164.68801,13.72376,5797.33141,0.14510,46.36255,0.12797,6.39826
165.58801,13.79884,5797.62608,0.14517,46.36491,0.12869,6.43436
166.48801,13.87392,5798.31600,0.14516,46.37043,0.12941,6.47045
167.38801,13.94880,5797.30757,0.14511,46.36236,0.13013,6.50645
168.28801,14.02376,5798.63787,0.14505,46.37300,0.13085,6.54249
169.18801,14.09880,5798.25044,0.14505,46.36990,0.13157,6.57857
170.08801,14.17384,5800.21739,0.14510,46.38563,0.13229,6.61464
170.98801,14.24892,5802.33149,0.14509,46.40254,0.13301,6.65074
171.88801,14.32368,5800.65884,0.14511,46.38916,0.13373,6.68668
172.78801,14.39872,5802.68428,0.14512,46.40536,0.13446,6.72276
173.68801,14.47388,5802.81131,0.14510,46.40638,0.13518,6.75889
174.58801,14.54884,5804.00862,0.14510,46.41595,0.13590,6.79493
175.48801,14.62384,5803.51651,0.14507,46.41202,0.13662,6.83099
176.38801,14.69888,5803.10188,0.14505,46.40870,0.13734,6.86707
177.28801,14.77388,5803.01061,0.14507,46.40797,0.13806,6.90313
178.18801,14.84884,5803.99185,0.14510,46.41582,0.13878,6.93916
179.08801,14.92368,5803.34105,0.14513,46.41061,0.13950,6.97515
179.98801,14.99884,5803.34626,0.14513,46.41066,0.14023,7.01128
180.88801,15.07388,5804.15465,0.14509,46.41712,0.14095,7.04736
181.78801,15.14888,5804.13677,0.14506,46.41698,0.14167,7.08341
182.68801,15.22384,5804.76671,0.14508,46.42202,0.14239,7.11945
183.58801,15.29884,5804.82632,0.14510,46.42249,0.14311,7.15551
184.48801,15.37384,5805.98526,0.14508,46.43176,0.14383,7.19157
185.38801,15.44884,5807.41055,0.14509,46.44316,0.14455,7.22763
186.28801,15.52388,5806.43564,0.14509,46.43536,0.14527,7.26370
187.18801,15.59880,5806.78657,0.14511,46.43817,0.14599,7.29972
188.08801,15.67400,5807.36436,0.14515,46.44279,0.14672,7.33588
188.98801,15.74876,5806.67965,0.14515,46.43731,0.14744,7.37182
189.88801,15.82384,5807.74806,0.14501,46.44586,0.14816,7.40791
190.78801,15.89876,5806.33543,0.14499,46.43456,0.14888,7.44393
191.68801,15.97380,5807.31146,0.14505,46.44237,0.14960,7.48001
192.58801,16.04896,5808.51175,0.14515,46.45197,0.15032,7.51615
193.48801,16.12368,5808.06062,0.14518,46.44836,0.15104,7.55207
194.38801,16.19888,5808.92414,0.14515,46.45526,0.15176,7.58822
195.28801,16.27396,5808.40260,0.14508,46.45109,0.15249,7.62432
196.18801,16.34880,5809.53173,0.14505,46.46012,0.15321,7.66030
197.08801,16.42380,5810.69700,0.14506,46.46944,0.15393,7.69636
197.98801,16.49880,5810.62101,0.14510,46.46883,0.15465,7.73241
198.88801,16.57388,5811.96472,0.14512,46.47958,0.15537,7.76851
199.78801,16.64880,5811.49049,0.14513,46.47579,0.15609,7.80453
200.68801,16.72368,5810.83074,0.14509,46.47051,0.15681,7.84053
201.58801,16.79880,5811.04346,0.14505,46.47221,0.15753,7.87664
202.48801,16.87392,5811.56760,0.14508,46.47640,0.15826,7.91276
203.38801,16.94876,5810.92052,0.14511,46.47123,0.15897,7.94874
204.28801,17.02376,5812.36146,0.14514,46.48275,0.15970,7.98480
205.18801,17.09888,5811.83843,0.14515,46.47857,0.16042,8.02091
206.08801,17.17384,5814.30644,0.14512,46.49831,0.16114,8.05695
206.98801,17.24884,5815.26943,0.14510,46.50601,0.16186,8.09301
207.88801,17.32376,5814.19282,0.14509,46.49740,0.16258,8.12903
208.78801,17.39884,5816.33709,0.14509,46.51455,0.16330,8.16513
209.68801,17.47384,5816.78823,0.14511,46.51815,0.16402,8.20118
210.58801,17.54876,5816.36839,0.14512,46.51480,0.16474,8.23720
211.48801,17.62384,5817.60220,0.14509,46.52466,0.16547,8.27330
212.38801,17.69880,5816.18212,0.14509,46.51331,0.16619,8.30934
213.28801,17.77392,5817.08401,0.14510,46.52052,0.16691,8.34545
214.18801,17.84888,5817.86335,0.14513,46.52675,0.16763,8.38149
215.08801,17.92376,5817.50758,0.14516,46.52391,0.16835,8.41749
215.98801,17.99880,5818.29399,0.14512,46.53020,0.16907,8.45357
216.88801,18.07388,5820.29931,0.14509,46.54623,0.16979,8.48966
217.78801,18.14896,5820.96428,0.14510,46.55155,0.17052,8.52576
218.68801,18.22380,5822.51996,0.14511,46.56399,0.17123,8.56174
219.58801,18.29884,5821.87772,0.14513,46.55886,0.17196,8.59782
220.48801,18.37380,5824.17063,0.14511,46.57719,0.17268,8.63386
221.38801,18.44892,5825.43574,0.14511,46.58731,0.17340,8.66997
222.28801,18.52368,5824.37254,0.14511,46.57881,0.17412,8.70591
223.18801,18.59880,5825.41190,0.14512,46.58712,0.17484,8.74203
224.08801,18.67404,5826.39948,0.14511,46.59502,0.17556,8.77820
224.98801,18.74880,5826.31044,0.14513,46.59431,0.17628,8.81415
225.88801,18.82392,5826.59431,0.14512,46.59658,0.17701,8.85026
226.78801,18.89884,5826.29852,0.14513,46.59421,0.17773,8.88628
227.68801,18.97384,5828.18240,0.14511,46.60928,0.17845,8.92234
228.58801,19.04880,5828.76392,0.14511,46.61393,0.17917,8.95838
229.48801,19.12372,5828.76541,0.14512,46.61394,0.17989,8.99439
230.38801,19.19888,5829.33836,0.14525,46.61852,0.18061,9.03053
231.28801,19.27392,5831.22969,0.14514,46.63365,0.18133,9.06661
232.18801,19.34876,5831.88273,0.14504,46.63887,0.18205,9.10259
233.08801,19.42380,5832.85205,0.14503,46.64662,0.18277,9.13866
233.98801,19.49880,5832.62108,0.14508,46.64477,0.18349,9.17472
234.88801,19.57384,5833.63138,0.14512,46.65285,0.18422,9.21080
235.78801,19.64880,5834.70725,0.14538,46.66146,0.18494,9.24684
236.68801,19.72384,5833.56582,0.14534,46.65233,0.18566,9.28291
237.58801,19.79876,5833.70440,0.14513,46.65344,0.18638,9.31893
238.48801,19.87392,5833.97858,0.14494,46.65563,0.18710,9.35507
239.38801,19.94876,5833.42165,0.14493,46.65118,0.18782,9.39105
240.28801,20.02388,5835.53873,0.14509,46.66811,0.18854,9.42716
241.18801,20.09876,5833.87725,0.14528,46.65482,0.18926,9.46316
242.08801,20.17380,5836.19811,0.14529,46.67338,0.18998,9.49924
242.98801,20.24884,5838.45973,0.14517,46.69147,0.19071,9.53532
243.88801,20.32376,5838.54392,0.14503,46.69214,0.19143,9.57134
244.78801,20.39892,5840.99628,0.14500,46.71175,0.19215,9.60747
245.68801,20.47388,5841.65603,0.14507,46.71703,0.19287,9.64351
246.58801,20.54876,5843.09064,0.14517,46.72850,0.19359,9.67951
247.48801,20.62380,5843.89865,0.14520,46.73496,0.19431,9.71559
248.38801,20.69880,5844.08417,0.14513,46.73645,0.19503,9.75164
249.28801,20.77396,5843.99179,0.14508,46.73571,0.19576,9.78778
250.18801,20.84884,5845.27068,0.14510,46.74594,0.19648,9.82378
251.08801,20.92376,5844.49954,0.14508,46.73977,0.19720,9.85980
251.98801,20.99876,5845.75608,0.14498,46.74982,0.19792,9.89586
252.88801,21.07392,5847.36951,0.14502,46.76272,0.19864,9.93199
253.78801,21.14880,5847.18138,0.14503,46.76122,0.19936,9.96799
254.68801,21.22384,5849.62368,0.14529,46.78075,0.20008,10.00407
255.58801,21.29888,5848.73967,0.14535,46.77368,0.20080,10.04015
256.48801,21.37384,5851.27659,0.14541,46.79397,0.20152,10.07618
257.38801,21.44888,5852.88666,0.14519,46.80684,0.20225,10.11226
258.28801,21.52376,5852.20493,0.14511,46.80139,0.20297,10.14826
259.18801,21.59880,5853.96104,0.14506,46.81543,0.20369,10.18434
260.08801,21.67388,5854.21249,0.14531,46.81744,0.20441,10.22043
260.98801,21.74880,5855.00859,0.14523,46.82381,0.20513,10.25645
261.88801,21.82392,5855.29432,0.14518,46.82610,0.20585,10.29257
262.78801,21.89880,5854.25496,0.14516,46.81778,0.20657,10.32857
263.68801,21.97388,5855.43998,0.14500,46.82726,0.20729,10.36466
264.58801,22.04888,5856.56278,0.14499,46.83624,0.20801,10.40072
265.48801,22.12372,5856.62499,0.14484,46.83674,0.20873,10.43670
266.38801,22.19888,5858.97081,0.14513,46.85550,0.20946,10.47284
267.28801,22.27388,5860.35289,0.14517,46.86655,0.21018,10.50889
268.18801,22.34888,5860.84835,0.14517,46.87051,0.21090,10.54495
269.08801,22.42380,5862.50275,0.14509,46.88374,0.21162,10.58097
269.98801,22.49884,5861.98233,0.14519,46.87958,0.21234,10.61705
270.88801,22.57376,5863.07310,0.14514,46.88831,0.21306,10.65307
271.78801,22.64888,5863.99250,0.14505,46.89566,0.21378,10.68918
272.68801,22.72380,5863.09396,0.14510,46.88847,0.21450,10.72520
273.58801,22.79880,5864.42463,0.14517,46.89911,0.21523,10.76126
274.48801,22.87392,5865.70650,0.14518,46.90937,0.21595,10.79738
275.38801,22.94884,5865.83130,0.14516,46.91036,0.21667,10.83339
276.28801,23.02392,5867.58293,0.14512,46.92437,0.21739,10.86949
277.18801,23.09872,5865.10375,0.14511,46.90454,0.21811,10.90545
278.08801,23.17380,5868.03965,0.14513,46.92802,0.21883,10.94155
278.98801,23.24880,5868.77316,0.14515,46.93389,0.21955,10.97761
279.88801,23.32372,5868.46508,0.14515,46.93143,0.22027,11.01363
280.78801,23.39888,5870.55348,0.14515,46.94813,0.22100,11.04976
281.68801,23.47384,5870.17909,0.14514,46.94513,0.22172,11.08580
282.58801,23.54880,5870.96773,0.14512,46.95144,0.22244,11.12184
283.48801,23.62376,5870.78631,0.14512,46.94999,0.22316,11.15788
284.38801,23.69884,5871.50715,0.14513,46.95575,0.22388,11.19397
285.28801,23.77388,5872.09500,0.14514,46.96046,0.22460,11.23005
286.18801,23.84888,5874.35700,0.14512,46.97855,0.22532,11.26611
287.08801,23.92380,5873.23345,0.14512,46.96956,0.22604,11.30213
287.98801,23.99876,5874.82452,0.14513,46.98228,0.22676,11.33816
288.88801,24.07388,5876.71772,0.14514,46.99742,0.22749,11.37428
289.78801,24.14876,5877.14612,0.14516,47.00085,0.22821,11.41028
290.68801,24.22380,5879.82833,0.14514,47.02230,0.22893,11.44636
291.58801,24.29884,5879.72850,0.14516,47.02150,0.22965,11.48243
292.48801,24.37384,5883.57039,0.14511,47.05223,0.23037,11.51849
293.38801,24.44892,5883.50184,0.14513,47.05168,0.23109,11.55459
294.28801,24.52372,5884.00215,0.14515,47.05568,0.23181,11.59055
295.18801,24.59888,5885.24565,0.14515,47.06562,0.23253,11.62668
296.08801,24.67384,5885.04709,0.14510,47.06404,0.23325,11.66272
296.98801,24.74880,5885.79960,0.14518,47.07005,0.23398,11.69876
297.88801,24.82396,5886.24999,0.14508,47.07366,0.23470,11.73489
298.78801,24.89872,5884.84518,0.14512,47.06242,0.23542,11.77084
299.68801,24.97392,5885.94973,0.14514,47.07125,0.23614,11.80699
300.58801,25.04880,5886.98499,0.14513,47.07953,0.23686,11.84299
301.48801,25.12380,5887.43277,0.14516,47.08311,0.23758,11.87905
302.38801,25.19868,5888.60586,0.14518,47.09250,0.23830,11.91505
303.28801,25.27392,5890.34371,0.14516,47.10639,0.23902,11.95122
304.18801,25.34892,5891.64086,0.14513,47.11677,0.23975,11.98728
305.08801,25.42384,5892.86312,0.14511,47.12654,0.24047,12.02330
305.98801,25.49892,5892.83556,0.14513,47.12632,0.24119,12.05939
306.88801,25.57384,5893.65177,0.14517,47.13285,0.24191,12.09541
307.78801,25.64892,5893.44501,0.14524,47.13120,0.24263,12.13151
308.68801,25.72364,5892.65078,0.14515,47.12484,0.24335,12.16743
309.58801,25.79876,5892.64296,0.14508,47.12478,0.24407,12.20355
310.48801,25.87384,5892.48277,0.14506,47.12350,0.24479,12.23964
311.38801,25.94876,5892.25665,0.14508,47.12169,0.24551,12.27566
312.28801,26.02392,5893.57354,0.14513,47.13222,0.24624,12.31180
313.18801,26.09876,5892.66941,0.14518,47.12499,0.24696,12.34778
314.08801,26.17384,5894.51306,0.14594,47.13974,0.24768,12.38388
314.98801,26.24880,5895.63772,0.14189,47.14873,0.24840,12.41991
315.88802,26.32376,5895.57439,0.13258,47.14823,0.24912,12.45595
316.78802,26.39884,5897.84645,0.14140,47.16640,0.24984,12.49205
317.68802,26.47388,5897.70451,0.14112,47.16526,0.25056,12.52813
318.58802,26.54888,5898.91635,0.14441,47.17495,0.25128,12.56418
319.48802,26.62376,5899.48073,0.14176,47.17947,0.25200,12.60018
320.38802,26.69880,5898.76771,0.14103,47.17376,0.25273,12.63626
321.28802,26.77372,5898.64030,0.14274,47.17274,0.25345,12.67228
322.18802,26.84888,5900.10732,0.14238,47.18448,0.25417,12.70841
323.08802,26.92384,5899.85363,0.14139,47.18245,0.25489,12.74445
323.98802,26.99876,5901.24130,0.14229,47.19354,0.25561,12.78047
324.88802,27.07396,5901.40373,0.14233,47.19484,0.25633,12.81662
325.78802,27.14880,5902.90837,0.14165,47.20688,0.25705,12.85261
326.68802,27.22388,5903.89036,0.14218,47.21473,0.25777,12.88870
327.58802,27.29876,5903.05887,0.14222,47.20808,0.25849,12.92470
328.48802,27.37380,5905.05525,0.14181,47.22405,0.25922,12.96078
329.38802,27.44892,5906.79124,0.14216,47.23793,0.25994,12.99689
330.28802,27.52372,5906.24660,0.14211,47.23357,0.26066,13.03286
331.18802,27.59892,5907.92447,0.14191,47.24699,0.26138,13.06901
332.08802,27.67380,5907.54040,0.14212,47.24392,0.26210,13.10501
332.98802,27.74888,5909.59229,0.14207,47.26033,0.26282,13.14111
333.88802,27.82380,5909.36467,0.14196,47.25851,0.26354,13.17712
334.78802,27.89872,5908.85170,0.14210,47.25441,0.26426,13.21314
335.68802,27.97392,5910.08589,0.14205,47.26428,0.26499,13.24930
336.58802,28.04892,5911.55328,0.14201,47.27601,0.26571,13.28536
337.48802,28.12384,5910.96655,0.14208,47.27132,0.26643,13.32138
338.38802,28.19872,5911.08613,0.14204,47.27228,0.26715,13.35738
339.28802,28.27400,5912.80274,0.14207,47.28600,0.26787,13.39357
340.18802,28.34876,5913.57760,0.14240,47.29220,0.26859,13.42951
341.08802,28.42380,5914.02017,0.14152,47.29574,0.26931,13.46559
341.98802,28.49884,5913.16149,0.14215,47.28887,0.27003,13.50166
342.88802,28.57388,5914.88816,0.14240,47.30268,0.27075,13.53774
343.78802,28.64896,5914.96304,0.14179,47.30328,0.27148,13.57384
344.68802,28.72376,5914.67284,0.14200,47.30096,0.27220,13.60980
345.58802,28.79880,5915.19810,0.14229,47.30516,0.27292,13.64587
346.48802,28.87384,5915.24728,0.14195,47.30555,0.27364,13.68195
347.38802,28.94876,5915.75578,0.14204,47.30962,0.27436,13.71797
348.28802,29.02384,5916.46880,0.14220,47.31532,0.27508,13.75407
349.18802,29.09876,5915.60602,0.14199,47.30842,0.27580,13.79009
350.08802,29.17400,5917.78308,0.14199,47.32583,0.27653,13.82626
350.98802,29.24880,5918.48008,0.14216,47.33141,0.27724,13.86222
351.88802,29.32372,5918.24539,0.14203,47.32953,0.27796,13.89824
352.78802,29.39876,5919.84168,0.14200,47.34230,0.27869,13.93432
353.68802,29.47392,5920.68434,0.14212,47.34904,0.27941,13.97045
354.58802,29.54896,5921.55233,0.14207,47.35598,0.28013,14.00653
355.48802,29.62376,5921.45175,0.14202,47.35517,0.28085,14.04249
356.38802,29.69888,5920.89370,0.14209,47.35071,0.28157,14.07861
357.28802,29.77376,5920.98311,0.14207,47.35142,0.28229,14.11461
358.18802,29.84888,5922.03215,0.14203,47.35981,0.28301,14.15072
359.08802,29.92372,5920.31106,0.14208,47.34605,0.28373,14.18670
359.98802,29.99876,5922.14167,0.14205,47.36069,0.28446,14.22278
360.88802,30.07392,5923.95328,0.14202,47.37518,0.28518,14.25891
361.78802,30.14876,5923.06517,0.14207,47.36808,0.28590,14.29489
362.68802,30.22396,5925.30295,0.14208,47.38597,0.28662,14.33105
363.58802,30.29872,5924.47147,0.14203,47.37932,0.28734,14.36699
364.48802,30.37392,5927.26171,0.14207,47.40164,0.28806,14.40315
365.38802,30.44884,5927.13468,0.14207,47.40062,0.28878,14.43916
366.28802,30.52368,5927.06986,0.14204,47.40010,0.28950,14.47515
367.18802,30.59884,5928.24966,0.14207,47.40954,0.29023,14.51128
368.08802,30.67388,5928.33199,0.14210,47.41020,0.29095,14.54736
368.98802,30.74888,5928.80473,0.14202,47.41398,0.29167,14.58341
369.88802,30.82372,5928.16211,0.14206,47.40884,0.29239,14.61939
370.78802,30.89884,5928.96305,0.14207,47.41524,0.29311,14.65551
371.68802,30.97392,5929.80571,0.14203,47.42198,0.29383,14.69161
372.58802,31.04888,5931.20642,0.14206,47.43318,0.29455,14.72765
373.48802,31.12380,5931.17736,0.14207,47.43295,0.29527,14.76366
374.38802,31.19880,5933.13016,0.14203,47.44857,0.29599,14.79972
375.28802,31.27400,5933.23894,0.14206,47.44944,0.29672,14.83588
376.18802,31.34880,5935.08258,0.14206,47.46418,0.29744,14.87184
377.08802,31.42384,5936.78355,0.14204,47.47778,0.29816,14.90791
377.98802,31.49884,5936.03514,0.14206,47.47180,0.29888,14.94397
378.88802,31.57380,5937.51818,0.14205,47.48366,0.29960,14.98001
379.78802,31.64896,5937.51296,0.14205,47.48362,0.30032,15.01614
380.68802,31.72368,5937.32446,0.14205,47.48211,0.30104,15.05207
381.58802,31.79888,5937.98235,0.14206,47.48737,0.30176,15.08822
382.48802,31.87384,5937.80018,0.14205,47.48591,0.30249,15.12426
383.38802,31.94884,5938.03488,0.14204,47.48779,0.30321,15.16032
384.28802,32.02384,5938.36755,0.14208,47.49045,0.30393,15.19638
385.18802,32.09876,5937.00930,0.14205,47.47959,0.30465,15.23240
386.08802,32.17396,5939.07125,0.14203,47.49608,0.30537,15.26855
386.98802,32.24876,5939.90758,0.14209,47.50277,0.30609,15.30451
387.88802,32.32376,5939.18525,0.14204,47.49699,0.30681,15.34057
388.78802,32.39864,5940.00593,0.14203,47.50355,0.30753,15.37657
389.68802,32.47388,5941.11793,0.14207,47.51245,0.30825,15.41274
390.58802,32.54888,5941.79928,0.14205,47.51790,0.30898,15.44880
391.48802,32.62376,5941.78513,0.14205,47.51778,0.30970,15.48480
392.38802,32.69884,5941.73968,0.14207,47.51742,0.31042,15.52089
393.28802,32.77380,5942.48027,0.14203,47.52334,0.31114,15.55693
394.18802,32.84896,5943.66081,0.14208,47.53278,0.31186,15.59307
395.08802,32.92364,5941.18945,0.14206,47.51302,0.31258,15.62897
395.98802,32.99884,5942.63598,0.14202,47.52459,0.31330,15.66513
396.88802,33.07396,5942.29959,0.14207,47.52190,0.31402,15.70124
397.78802,33.14876,5942.36888,0.14205,47.52245,0.31474,15.73720
398.68802,33.22384,5944.50757,0.14203,47.53955,0.31547,15.77330
399.58802,33.29868,5942.83938,0.14204,47.52621,0.31619,15.80928
400.48802,33.37392,5945.04513,0.14205,47.54385,0.31691,15.84545
401.38802,33.44876,5945.28131,0.14205,47.54574,0.31763,15.88143
402.28802,33.52376,5945.16732,0.14235,47.54483,0.31835,15.91749
403.18802,33.59888,5946.39070,0.14198,47.55461,0.31907,15.95361
404.08802,33.67388,5945.59126,0.14189,47.54822,0.31979,15.98966
404.98802,33.74896,5946.77851,0.14222,47.55772,0.32052,16.02576
405.88802,33.82384,5946.00178,0.14206,47.55150,0.32124,16.06176
406.78802,33.89880,5945.76523,0.14194,47.54961,0.32196,16.09780
407.68802,33.97384,5947.13986,0.14216,47.56061,0.32268,16.13388
408.58802,34.04884,5947.83388,0.14210,47.56616,0.32340,16.16993
409.48802,34.12380,5947.46321,0.14197,47.56319,0.32412,16.20597
410.38802,34.19872,5948.83822,0.14212,47.57419,0.32484,16.24199
411.28802,34.27404,5949.95171,0.14211,47.58309,0.32556,16.27820
412.18802,34.34876,5950.06309,0.14199,47.58398,0.32628,16.31413
413.08802,34.42388,5951.63181,0.14209,47.59653,0.32700,16.35024
413.98802,34.49880,5950.45127,0.14209,47.58709,0.32773,16.38626
414.88802,34.57388,5951.48839,0.14202,47.59538,0.32845,16.42236
415.78802,34.64896,5951.96672,0.14209,47.59921,0.32917,16.45845
416.68802,34.72372,5950.26202,0.14209,47.58557,0.32989,16.49439
417.58802,34.79892,5950.73290,0.14203,47.58934,0.33061,16.53055
418.48802,34.87380,5950.85397,0.14207,47.59031,0.33133,16.56655
419.38802,34.94884,5951.04098,0.14208,47.59180,0.33205,16.60262
420.28802,35.02364,5950.84988,0.14204,47.59028,0.33277,16.63859
421.18802,35.09880,5951.09835,0.14206,47.59226,0.33349,16.67472
422.08802,35.17392,5951.80653,0.14209,47.59793,0.33422,16.71084
422.98802,35.24884,5953.38382,0.14203,47.61054,0.33494,16.74686
423.88802,35.32380,5952.88835,0.14205,47.60658,0.33566,16.78289
424.78802,35.39876,5954.07858,0.14210,47.61610,0.33638,16.81893
425.68802,35.47396,5954.62210,0.14204,47.62044,0.33710,16.85509
426.58802,35.54872,5953.73064,0.14205,47.61331,0.33782,16.89103
427.48802,35.62380,5954.77968,0.14208,47.62170,0.33854,16.92712
428.38802,35.69892,5955.13545,0.14206,47.62455,0.33926,16.96324
429.28802,35.77380,5954.91529,0.14206,47.62279,0.33998,16.99924
430.18802,35.84896,5954.91752,0.14207,47.62281,0.34071,17.03538
431.08802,35.92356,5952.83508,0.14205,47.60615,0.34142,17.07124
431.98802,35.99888,5953.71574,0.14207,47.61319,0.34215,17.10745
432.88802,36.07388,5953.98657,0.14208,47.61536,0.34287,17.14351
433.78802,36.14872,5955.29824,0.14205,47.62585,0.34359,17.17949
434.68802,36.22392,5956.64270,0.14207,47.63660,0.34431,17.21565
435.58802,36.29872,5955.26025,0.14208,47.62555,0.34503,17.25161
436.48802,36.37396,5956.46054,0.14205,47.63515,0.34576,17.28778
437.38802,36.44880,5958.13170,0.14205,47.64851,0.34648,17.32376
438.28802,36.52376,5956.86100,0.14207,47.63835,0.34720,17.35980
439.18802,36.59876,5957.22273,0.14205,47.64124,0.34792,17.39586
440.08802,36.67380,5957.24210,0.14207,47.64140,0.34864,17.43193
440.98802,36.74892,5957.17989,0.14207,47.64090,0.34936,17.46805
441.88802,36.82376,5956.63227,0.14206,47.63652,0.35008,17.50403
442.78802,36.89896,5956.31264,0.14207,47.63396,0.35080,17.54018
443.68802,36.97380,5955.45843,0.14207,47.62713,0.35152,17.57616
444.58802,37.04888,5956.03846,0.14206,47.63177,0.35225,17.61226
445.48802,37.12372,5955.58174,0.14207,47.62812,0.35296,17.64824
446.38802,37.19876,5957.17691,0.14206,47.64087,0.35369,17.68432
447.28802,37.27396,5956.57825,0.14207,47.63609,0.35441,17.72047
448.18802,37.34880,5957.27377,0.14206,47.64165,0.35513,17.75645
449.08802,37.42396,5958.40774,0.14205,47.65072,0.35585,17.79259
449.98802,37.49872,5956.56820,0.14208,47.63601,0.35657,17.82853
450.88802,37.57388,5958.14362,0.14205,47.64861,0.35729,17.86466
451.78802,37.64884,5957.15046,0.14206,47.64066,0.35801,17.90070
452.68802,37.72372,5955.73969,0.14209,47.62938,0.35873,17.93670
453.58802,37.79884,5956.41881,0.14208,47.63481,0.35946,17.97282
454.48802,37.87392,5956.17443,0.14202,47.63286,0.36018,18.00891
455.38802,37.94892,5955.15482,0.14211,47.62470,0.36090,18.04497
456.28802,38.02376,5955.56721,0.14206,47.62800,0.36162,18.08095
457.18802,38.09876,5955.05238,0.14206,47.62388,0.36234,18.11701
458.08802,38.17380,5955.03263,0.14206,47.62373,0.36306,18.15309
458.98802,38.24880,5956.79171,0.14205,47.63779,0.36378,18.18915
459.88802,38.32388,5955.65252,0.14207,47.62868,0.36450,18.22524
460.78802,38.39876,5956.16810,0.14207,47.63281,0.36522,18.26124
461.68802,38.47404,5956.57639,0.14206,47.63607,0.36595,18.29743
462.58802,38.54872,5955.24982,0.14210,47.62546,0.36667,18.33334
463.48802,38.62388,5956.17257,0.14204,47.63284,0.36739,18.36947
464.38802,38.69888,5954.59975,0.14208,47.62026,0.36811,18.40553
465.28802,38.77376,5955.37014,0.14208,47.62643,0.36883,18.44153
466.18802,38.84896,5955.74267,0.14204,47.62940,0.36955,18.47768
467.08802,38.92364,5953.82303,0.14205,47.61405,0.37027,18.51359
467.98802,38.99892,5954.33824,0.14207,47.61817,0.37100,18.54978
468.88802,39.07380,5954.01227,0.14209,47.61557,0.37172,18.58578
469.78802,39.14880,5954.83072,0.14201,47.62211,0.37244,18.62184
470.68802,39.22380,5953.69153,0.14207,47.61300,0.37316,18.65790
471.58802,39.29868,5952.92673,0.14212,47.60688,0.37388,18.69390
472.48802,39.37400,5954.51109,0.14202,47.61956,0.37460,18.73011
473.38802,39.44876,5953.99961,0.14208,47.61546,0.37532,18.76605
474.28802,39.52392,5953.07983,0.14209,47.60811,0.37604,18.80219
475.18802,39.59876,5952.24686,0.14203,47.60145,0.37676,18.83817
476.08802,39.67384,5952.63354,0.14207,47.60454,0.37749,18.87426
476.98802,39.74884,5952.71327,0.14206,47.60518,0.37821,18.91032
477.88802,39.82376,5952.38321,0.14204,47.60254,0.37893,18.94634
478.78802,39.89888,5951.63666,0.14208,47.59657,0.37965,18.98245
479.68802,39.97380,5952.10195,0.14207,47.60029,0.38037,19.01847
480.58802,40.04900,5952.75611,0.14206,47.60552,0.38109,19.05463
481.48802,40.12368,5951.43996,0.14207,47.59499,0.38181,19.09053
482.38802,40.19880,5953.02023,0.14206,47.60763,0.38253,19.12665
483.28802,40.27400,5951.90115,0.14206,47.59868,0.38326,19.16280
484.18802,40.34876,5952.85632,0.14206,47.60632,0.38397,19.19874
485.08802,40.42392,5953.53581,0.14207,47.61176,0.38470,19.23488
485.98802,40.49884,5953.29292,0.14207,47.60981,0.38542,19.27090
486.88802,40.57392,5954.31589,0.14207,47.61799,0.38614,19.30699
487.78802,40.64880,5953.17185,0.14206,47.60885,0.38686,19.34299
488.68802,40.72368,5951.55880,0.14205,47.59595,0.38758,19.37899
489.58802,40.79888,5951.32262,0.14206,47.59406,0.38830,19.41515
490.48802,40.87384,5950.53397,0.14209,47.58775,0.38902,19.45118
491.38802,40.94892,5950.58128,0.14204,47.58813,0.38975,19.48728
492.28802,41.02380,5951.20713,0.14207,47.59313,0.39047,19.52328
493.18802,41.09888,5950.63567,0.14210,47.58856,0.39119,19.55938
494.08802,41.17376,5950.98510,0.14205,47.59136,0.39191,19.59538
494.98802,41.24884,5953.23592,0.14206,47.60936,0.39263,19.63147
495.88802,41.32388,5952.35750,0.14208,47.60233,0.39335,19.66755
496.78802,41.39868,5953.49036,0.14206,47.61139,0.39407,19.70351
497.68802,41.47392,5954.22685,0.14208,47.61728,0.39479,19.73968
498.58802,41.54864,5953.92324,0.14208,47.61485,0.39551,19.77561
499.48802,41.62384,5954.82811,0.14205,47.62209,0.39624,19.81176
500.38802,41.69880,5953.70047,0.14206,47.61307,0.39696,19.84780
501.28802,41.77380,5953.39611,0.14206,47.61064,0.39768,19.88386
502.18802,41.84896,5953.72692,0.14206,47.61328,0.39840,19.91999
503.08802,41.92364,5951.61542,0.14207,47.59640,0.39912,19.95590
503.98802,41.99896,5951.56848,0.14206,47.59602,0.39984,19.99211
504.88802,42.07380,5951.18143,0.14206,47.59293,0.40056,20.02809
505.78802,42.14888,5951.89631,0.14206,47.59864,0.40128,20.06418
506.68802,42.22376,5952.30348,0.14207,47.60190,0.40200,20.10018
507.58802,42.29872,5951.79759,0.14206,47.59785,0.40272,20.13622
508.48802,42.37396,5954.30620,0.14207,47.61792,0.40345,20.17240
509.38802,42.44872,5954.42913,0.14207,47.61890,0.40417,20.20834
510.28802,42.52384,5953.67439,0.14206,47.61286,0.40489,20.24445
511.18802,42.59876,5953.62559,0.14207,47.61247,0.40561,20.28047
512.08802,42.67392,5954.77596,0.14208,47.62167,0.40633,20.31661
512.98802,42.74880,5954.31216,0.14206,47.61796,0.40705,20.35261
513.88802,42.82380,5954.87170,0.14207,47.62244,0.40777,20.38867
514.78802,42.89896,5954.64744,0.14209,47.62065,0.40850,20.42480
515.68802,42.97384,5955.62309,0.14204,47.62845,0.40922,20.46080
516.58802,43.04896,5957.16871,0.14207,47.64081,0.40994,20.49692
517.48802,43.12368,5955.55454,0.14208,47.62790,0.41066,20.53284
518.38802,43.19880,5957.13779,0.14205,47.64056,0.41138,20.56895
519.28802,43.27388,5957.65412,0.14206,47.64469,0.41210,20.60505
520.18802,43.34876,5960.02229,0.14207,47.66363,0.41282,20.64105
521.08802,43.42404,5961.67967,0.14207,47.67688,0.41354,20.67724
521.98802,43.49876,5960.90034,0.14206,47.67065,0.41426,20.71317
522.88802,43.57396,5962.37779,0.14207,47.68247,0.41499,20.74932
523.78802,43.64884,5963.56504,0.14208,47.69196,0.41571,20.78532
524.68802,43.72384,5964.54181,0.14206,47.69977,0.41643,20.82138
525.58802,43.79876,5964.30898,0.14207,47.69791,0.41715,20.85740
526.48803,43.87380,5965.46270,0.14207,47.70714,0.41787,20.89347
527.38803,43.94896,5966.51100,0.14206,47.71552,0.41859,20.92961
528.28803,44.02376,5966.90252,0.14207,47.71865,0.41931,20.96557
529.18803,44.09888,5966.78369,0.14207,47.71770,0.42003,21.00168
530.08803,44.17368,5967.27282,0.14205,47.72161,0.42075,21.03765
530.98803,44.24888,5970.62893,0.14208,47.74845,0.42148,21.07380
531.88803,44.32372,5969.73859,0.14206,47.74133,0.42220,21.10978
532.78803,44.39876,5971.44924,0.14205,47.75501,0.42292,21.14586
533.68803,44.47400,5972.47593,0.14208,47.76322,0.42364,21.18203
534.58803,44.54876,5973.83901,0.14206,47.77412,0.42436,21.21797
535.48803,44.62388,5974.95213,0.14206,47.78303,0.42508,21.25409
536.38803,44.69868,5974.36987,0.14208,47.77837,0.42580,21.29005
537.28803,44.77388,5975.91959,0.14206,47.79076,0.42652,21.32620
538.18803,44.84888,5976.16844,0.14206,47.79275,0.42725,21.36226
539.08803,44.92368,5976.53836,0.14209,47.79571,0.42796,21.39822
539.98803,44.99892,5977.86941,0.14205,47.80636,0.42869,21.43440
540.88803,45.07376,5977.93907,0.14207,47.80691,0.42941,21.47038
541.78803,45.14896,5979.81736,0.14209,47.82194,0.43013,21.50653
542.68803,45.22380,5981.85025,0.14204,47.83819,0.43085,21.54251
543.58803,45.29876,5982.48765,0.14206,47.84329,0.43157,21.57855
544.48803,45.37384,5984.24375,0.14207,47.85733,0.43229,21.61464
545.38803,45.44872,5985.84190,0.14206,47.87011,0.43301,21.65064
546.28803,45.52388,5986.07622,0.14206,47.87199,0.43374,21.68678
547.18803,45.59876,5986.88349,0.14207,47.87844,0.43446,21.72278
548.08803,45.67396,5986.76838,0.14206,47.87752,0.43518,21.75893
548.98803,45.74872,5987.82711,0.14207,47.88599,0.43590,21.79488
549.88803,45.82380,5988.53454,0.14206,47.89165,0.43662,21.83097
550.78803,45.89884,5988.83592,0.14206,47.89406,0.43734,21.86705
551.68803,45.97376,5990.26196,0.14207,47.90546,0.43806,21.90307
552.58803,46.04904,5992.62267,0.14207,47.92434,0.43879,21.93926
553.48803,46.12368,5992.78435,0.14206,47.92564,0.43950,21.97515
554.38803,46.19884,5994.96439,0.14206,47.94307,0.44023,22.01128
555.28803,46.27388,5996.07825,0.14207,47.95198,0.44095,22.04736
556.18803,46.34884,5998.72358,0.14206,47.97313,0.44167,22.08340
557.08803,46.42384,5999.76294,0.14206,47.98144,0.44239,22.11945
557.98803,46.49872,6000.30832,0.14208,47.98581,0.44311,22.15545
558.88803,46.57400,6002.44068,0.14203,48.00286,0.44383,22.19164
559.78803,46.64884,6003.72329,0.14207,48.01312,0.44455,22.22762
560.68803,46.72384,6003.31649,0.14210,48.00986,0.44527,22.26369
561.58803,46.79872,6003.68306,0.14204,48.01279,0.44599,22.29968
562.48803,46.87392,6005.59264,0.14205,48.02807,0.44672,22.33584
563.38803,46.94884,6007.00602,0.14208,48.03937,0.44744,22.37186
564.28803,47.02380,6008.61311,0.14205,48.05222,0.44816,22.40790
565.18803,47.09888,6009.07467,0.14207,48.05591,0.44888,22.44399
566.08803,47.17384,6012.17933,0.14208,48.08074,0.44960,22.48003
566.98803,47.24888,6014.72966,0.14205,48.10114,0.45032,22.51611
567.88803,47.32364,6014.19099,0.14208,48.09683,0.45104,22.55205
568.78803,47.39880,6016.51333,0.14205,48.11540,0.45176,22.58818
569.68803,47.47396,6017.24125,0.14207,48.12122,0.45249,22.62432
570.58803,47.54876,6018.41882,0.14209,48.13064,0.45321,22.66028
571.48803,47.62400,6020.78028,0.14205,48.14952,0.45393,22.69645
572.38803,47.69872,6020.44910,0.14207,48.14688,0.45465,22.73238
573.28803,47.77396,6021.94928,0.14207,48.15887,0.45537,22.76855
574.18803,47.84884,6023.39096,0.14206,48.17040,0.45609,22.80455
575.08803,47.92368,6023.80261,0.14207,48.17369,0.45681,22.84053
575.98803,47.99880,6024.71605,0.14205,48.18100,0.45753,22.87664
576.88803,48.07376,6024.72126,0.14207,48.18104,0.45825,22.91268
577.78803,48.14892,6026.25906,0.14207,48.19334,0.45898,22.94882
578.68803,48.22380,6028.30462,0.14206,48.20970,0.45970,22.98482
579.58803,48.29880,6028.07142,0.14208,48.20783,0.46042,23.02088
580.48803,48.37372,6031.68271,0.14205,48.23671,0.46114,23.05690
581.38803,48.44880,6032.86959,0.14204,48.24621,0.46186,23.09299
582.28803,48.52388,6033.71784,0.14207,48.25299,0.46258,23.12909
583.18803,48.59868,6034.82202,0.14206,48.26182,0.46330,23.16505
584.08803,48.67404,6036.03832,0.14207,48.27155,0.46403,23.20128
584.98803,48.74880,6037.41258,0.14206,48.28254,0.46474,23.23722
585.88803,48.82384,6038.79616,0.14205,48.29360,0.46547,23.27330
586.78803,48.89868,6038.16062,0.14205,48.28852,0.46619,23.30928
587.68803,48.97384,6039.88729,0.14210,48.30233,0.46691,23.34541
588.58803,49.04896,6042.13700,0.14205,48.32032,0.46763,23.38153
589.48803,49.12368,6042.27036,0.14204,48.32139,0.46835,23.41745
590.38803,49.19892,6046.08878,0.14208,48.35192,0.46907,23.45363
591.28803,49.27392,6046.70309,0.14206,48.35684,0.46979,23.48968
592.18803,49.34888,6048.37611,0.14203,48.37021,0.47051,23.52572
593.08803,49.42380,6050.85306,0.14208,48.39002,0.47123,23.56174
593.98803,49.49880,6051.13059,0.14206,48.39224,0.47196,23.59780
594.88803,49.57400,6052.99659,0.14204,48.40717,0.47268,23.63395
595.78803,49.64888,6054.68415,0.14208,48.42066,0.47340,23.66995
596.68803,49.72384,6054.14547,0.14204,48.41635,0.47412,23.70599
597.58803,49.79876,6055.26678,0.14208,48.42532,0.47484,23.74201
598.48803,49.87388,6057.03667,0.14205,48.43948,0.47556,23.77813
599.38803,49.94876,6057.89386,0.14205,48.44633,0.47628,23.81413
600.28803,50.02376,6060.14505,0.14205,48.46433,0.47700,23.85018
601.18803,50.09892,6060.81560,0.14205,48.46970,0.47773,23.88632
602.08803,50.17384,6063.55332,0.14205,48.49159,0.47845,23.92234
602.98803,50.24900,6066.28396,0.14204,48.51343,0.47917,23.95847
603.88803,50.32372,6067.65486,0.14208,48.52439,0.47989,23.99439
604.78803,50.39880,6070.25325,0.14204,48.54517,0.48061,24.03049
605.68803,50.47388,6071.16222,0.14205,48.55244,0.48133,24.06659
606.58803,50.54876,6073.67307,0.14209,48.57252,0.48205,24.10259
607.48803,50.62388,6076.25470,0.14204,48.59317,0.48277,24.13870
608.38803,50.69864,6076.16939,0.14206,48.59248,0.48349,24.17465
609.28803,50.77396,6079.24983,0.14209,48.61712,0.48422,24.21086
610.18803,50.84880,6081.36915,0.14204,48.63407,0.48494,24.24684
611.08803,50.92372,6082.64543,0.14207,48.64427,0.48566,24.28286
611.98803,50.99872,6084.45145,0.14207,48.65872,0.48638,24.31891
612.88803,51.07384,6086.56742,0.14203,48.67564,0.48710,24.35503
613.78803,51.14900,6090.16828,0.14210,48.70444,0.48782,24.39117
614.68803,51.22376,6092.49622,0.14205,48.72305,0.48854,24.42711
615.58803,51.29888,6094.19793,0.14203,48.73666,0.48926,24.46322
616.48803,51.37380,6096.11608,0.14209,48.75200,0.48998,24.49924
617.38803,51.44888,6100.02242,0.14205,48.78324,0.49071,24.53534
618.28803,51.52368,6099.47741,0.14206,48.77888,0.49143,24.57130
619.18803,51.59864,6102.28665,0.14205,48.80135,0.49215,24.60734
620.08803,51.67404,6104.64364,0.14206,48.82020,0.49287,24.64359
620.98803,51.74876,6106.57334,0.14207,48.83563,0.49359,24.67951
621.88803,51.82392,6108.21210,0.14205,48.84874,0.49431,24.71564
622.78803,51.89872,6108.95567,0.14206,48.85468,0.49503,24.75161
623.68803,51.97388,6111.64197,0.14207,48.87617,0.49575,24.78774
624.58803,52.04888,6113.85964,0.14206,48.89390,0.49648,24.82380
625.48803,52.12368,6115.64927,0.14206,48.90821,0.49720,24.85976
626.38803,52.19888,6118.83961,0.14208,48.93373,0.49792,24.89591
627.28803,52.27388,6120.89671,0.14205,48.95018,0.49864,24.93197
628.18803,52.34888,6124.54824,0.14206,48.97938,0.49936,24.96803
629.08803,52.42380,6126.31626,0.14207,48.99352,0.50008,25.00405
629.98803,52.49876,6128.63563,0.14205,49.01207,0.50080,25.04009
630.88803,52.57388,6132.60642,0.14206,49.04382,0.50152,25.07620
631.78803,52.64880,6134.33272,0.14207,49.05763,0.50224,25.11222
632.68803,52.72388,6134.91051,0.14203,49.06225,0.50297,25.14832
633.58803,52.79876,6136.82196,0.14205,49.07754,0.50369,25.18432
634.48803,52.87404,6139.44419,0.14206,49.09851,0.50441,25.22051
635.38803,52.94872,6140.46790,0.14204,49.10669,0.50513,25.25641
636.28803,53.02384,6144.06168,0.14206,49.13543,0.50585,25.29253
637.18803,53.09880,6144.68753,0.14207,49.14044,0.50657,25.32857
638.08803,53.17376,6148.01794,0.14204,49.16707,0.50729,25.36461
638.98803,53.24896,6151.93807,0.14206,49.19842,0.50802,25.40076
639.88803,53.32360,6152.88392,0.14206,49.20599,0.50873,25.43665
640.78803,53.39892,6156.95566,0.14203,49.23855,0.50946,25.47286
641.68803,53.47384,6158.60373,0.14206,49.25173,0.51018,25.50888
642.58803,53.54884,6160.92235,0.14206,49.27027,0.51090,25.54493
643.48803,53.62384,6163.70291,0.14204,49.29251,0.51162,25.58099
644.38803,53.69872,6164.55413,0.14208,49.29932,0.51234,25.61699
645.28803,53.77396,6167.17860,0.14205,49.32030,0.51306,25.65316
646.18803,53.84880,6169.38137,0.14206,49.33792,0.51378,25.68915
647.08803,53.92384,6171.66795,0.14205,49.35621,0.51450,25.72522
647.98803,53.99876,6173.49707,0.14205,49.37083,0.51522,25.76124
648.88803,54.07388,6175.56721,0.14207,49.38739,0.51595,25.79736
649.78803,54.14880,6178.00690,0.14207,49.40690,0.51667,25.83337
650.68803,54.22368,6181.12907,0.14207,49.43187,0.51739,25.86938
651.58803,54.29892,6184.16853,0.14209,49.45618,0.51811,25.90555
652.48803,54.37388,6187.37340,0.14204,49.48181,0.51883,25.94159
653.38803,54.44892,6190.50227,0.09588,49.50683,0.51955,25.97766
654.28803,54.52368,6192.20883,0.05869,49.52048,0.52027,26.01361
655.18803,54.59872,6194.45406,0.13316,49.53843,0.52099,26.04968
656.08803,54.67392,6196.87364,0.13978,49.55778,0.52172,26.08584
656.98803,54.74876,6198.88529,0.14608,49.57387,0.52244,26.12182
657.88803,54.82392,6201.84653,0.14100,49.59755,0.52316,26.15795
658.78803,54.89872,6202.76295,0.13811,49.60488,0.52388,26.19391
659.68803,54.97392,6206.22709,0.14245,49.63258,0.52460,26.23007
660.58803,55.04884,6209.24942,0.14288,49.65675,0.52532,26.26609
661.48803,55.12368,6210.64305,0.13965,49.66790,0.52604,26.30207
662.38803,55.19892,6213.78310,0.14074,49.69301,0.52676,26.33824
663.28803,55.27384,6217.04422,0.14256,49.71909,0.52749,26.37426
664.18803,55.34888,6219.64782,0.14094,49.73991,0.52821,26.41034
665.08803,55.42380,6222.66904,0.14038,49.76407,0.52893,26.44636
665.98803,55.49888,6223.10229,0.14186,49.76754,0.52965,26.48245
666.88803,55.57376,6226.02515,0.14150,49.79091,0.53037,26.51845
667.78803,55.64880,6228.54643,0.14061,49.81108,0.53109,26.55453
668.68803,55.72388,6228.94764,0.14135,49.81429,0.53181,26.59063
669.58803,55.79872,6231.42049,0.14163,49.83406,0.53253,26.62661
670.48803,55.87400,6234.12505,0.14091,49.85569,0.53326,26.66280
671.38803,55.94876,6235.20277,0.14110,49.86431,0.53397,26.69874
672.28803,56.02396,6238.32904,0.14156,49.88931,0.53470,26.73490
673.18803,56.09872,6237.67972,0.14113,49.88412,0.53542,26.77084
674.08803,56.17388,6241.41358,0.14103,49.91398,0.53614,26.80697
674.98803,56.24892,6243.40549,0.14142,49.92991,0.53686,26.84305
675.88803,56.32368,6244.34426,0.14126,49.93742,0.53758,26.87899
676.78803,56.39892,6246.91248,0.14103,49.95795,0.53830,26.91516
677.68803,56.47384,6247.00896,0.14129,49.95873,0.53902,26.95118
678.58803,56.54888,6248.61345,0.14141,49.97156,0.53975,26.98726
679.48803,56.62376,6249.43785,0.14112,49.97815,0.54047,27.02326
680.38803,56.69880,6249.83087,0.14112,49.98129,0.54119,27.05934
681.28803,56.77400,6249.04521,0.14135,49.97501,0.54191,27.09549
682.18803,56.84872,6248.75315,0.14126,49.97267,0.54263,27.13141
683.08803,56.92384,6247.12966,0.14111,49.95969,0.54335,27.16753
683.98803,56.99880,6245.22828,0.14125,49.94449,0.54407,27.20357
684.88803,57.07388,6242.70737,0.14127,49.92433,0.54479,27.23966
685.78803,57.14868,6237.46365,0.14115,49.88239,0.54551,27.27562
686.68803,57.22372,6231.75763,0.14125,49.83676,0.54623,27.31171
687.58803,57.29884,6221.13831,0.14128,49.75183,0.54696,27.34782
688.48803,57.37380,6207.45532,0.14120,49.64241,0.54768,27.38386
689.38803,57.44892,6184.69492,0.14121,49.46039,0.54840,27.41997
690.28803,57.52368,6144.02033,0.14123,49.13510,0.54912,27.45592
691.18803,57.59884,6068.98293,0.14125,48.53501,0.54984,27.49205
692.08803,57.67388,5815.87330,0.14121,46.51084,0.55056,27.52813
692.24003,57.68688,735.88458,0.14111,5.88503,0.55069,27.53437