File: Calibration Data/test_PC_ASTM638.is_tens_RawData/Specimen_RawData_1.csv
Operator,"Quentin Govignon"
Our Reference Number,""
Customer Reference,""
Temperature (°C),21.0
Humidity (%),50.
Load Frame,"Instron Model 1185"
Crosshead Speed 1,5.00,mm/min
Extensometer G.L.,"50 mm"
Specimen Name,"PC #1"
Geometry,Rectangular
Length,104.00,mm
Maximum Load,7998.80102,N
Maximum Tensile stress,64.12780,MPa
Modulus (Chord 0.05 % - 0.25 %),2428.19693,MPa
Modulus (Young's 0.025 % - 0.5 %),2672.65816,MPa
Extension at Break (Standard),55.42844,mm
Specimen note 1,""
Specimen note 2,""
Specimen note 3,""

Time,Extension,Load,Strain 1,Tensile stress,Tensile strain,Tensile extension
(sec),(mm),(N),(mm/mm),(MPa),(mm/mm),(mm)
0.00000,-0.08404,0.65438,0.00000,0.00525,0.00000,-0.00011
0.85000,-0.01460,136.83756,0.00044,1.09705,0.00044,0.02180
1.70000,0.05752,295.87471,0.00092,2.37208,0.00092,0.04616
2.55000,0.12836,457.52465,0.00146,3.66806,0.00146,0.07277
3.40000,0.19932,625.78828,0.00204,5.01705,0.00204,0.10183
4.25000,0.27012,779.89316,0.00255,6.25254,0.00255,0.12735
5.10000,0.34108,943.95317,0.00314,7.56784,0.00314,0.15695
5.95000,0.41176,1109.53720,0.00372,8.89536,0.00372,0.18609
6.80000,0.48280,1264.85648,0.00427,10.14058,0.00427,0.21363
7.65000,0.55344,1425.71153,0.00486,11.43018,0.00486,0.24291
8.50000,0.62448,1586.66540,0.00544,12.72058,0.00544,0.27188
9.35000,0.69512,1736.61262,0.00599,13.92273,0.00599,0.29935
10.20000,0.76604,1895.66202,0.00657,15.19786,0.00657,0.32835
11.05000,0.83684,2043.17346,0.00711,16.38048,0.00711,0.35562
11.90000,0.90756,2195.47879,0.00768,17.60154,0.00768,0.38408
12.75000,0.97844,2339.64771,0.00823,18.75737,0.00823,0.41136
13.60000,1.04916,2490.17328,0.00880,19.96416,0.00880,0.44008
14.45000,1.12012,2630.95051,0.00934,21.09279,0.00934,0.46720
15.30000,1.19096,2778.31629,0.00992,22.27425,0.00992,0.49593
16.15000,1.26184,2915.53400,0.01047,23.37435,0.01047,0.52351
17.00000,1.33256,3058.02636,0.01104,24.51674,0.01104,0.55186
17.85000,1.40348,3194.21180,0.01159,25.60856,0.01159,0.57973
18.70000,1.47436,3324.27248,0.01214,26.65128,0.01214,0.60677
19.55000,1.54520,3462.62679,0.01272,27.76049,0.01272,0.63576
20.40000,1.61604,3588.39668,0.01326,28.76881,0.01326,0.66310
21.25000,1.68684,3722.01316,0.01383,29.84003,0.01383,0.69164
22.10000,1.75768,3843.67481,0.01438,30.81542,0.01438,0.71885
22.95000,1.82848,3974.91939,0.01495,31.86763,0.01495,0.74748
23.80000,1.89932,4089.95003,0.01549,32.78985,0.01549,0.77434
24.65000,1.97008,4216.96566,0.01606,33.80816,0.01606,0.80321
25.50000,2.04112,4330.54492,0.01661,34.71874,0.01661,0.83070
26.35000,2.11176,4451.47976,0.01719,35.68830,0.01719,0.85939
27.20000,2.18272,4560.02317,0.01772,36.55851,0.01772,0.88609
28.05000,2.25352,4678.35926,0.01832,37.50723,0.01832,0.91576
28.90000,2.32432,4775.19892,0.01883,38.28361,0.01883,0.94138
29.75000,2.39512,4880.63842,0.01937,39.12894,0.01937,0.96837
30.60000,2.46616,4992.75401,0.01996,40.02779,0.01996,0.99809
31.45000,2.53672,5066.49390,0.02038,40.61897,0.02038,1.01901
32.30000,2.60768,5175.59722,0.02098,41.49367,0.02098,1.04893
33.15000,2.67856,5241.16419,0.02138,42.01934,0.02138,1.06891
34.00000,2.74924,5347.67695,0.02198,42.87327,0.02198,1.09883
34.85000,2.82020,5409.54024,0.02237,43.36924,0.02237,1.11859
35.70000,2.89088,5511.71042,0.02297,44.18835,0.02297,1.14826
36.55000,2.96188,5565.22422,0.02333,44.61738,0.02333,1.16666
37.40000,3.03264,5639.88388,0.02381,45.21594,0.02381,1.19026
38.25000,3.10356,5713.43824,0.02428,45.80564,0.02428,1.21417
39.10000,3.17432,5788.40710,0.02477,46.40668,0.02477,1.23849
39.95000,3.24524,5863.02876,0.02527,47.00493,0.02527,1.26346
40.80000,3.31588,5935.04831,0.02576,47.58233,0.02576,1.28806
41.65000,3.38684,6008.56356,0.02627,48.17171,0.02627,1.31332
42.50000,3.45776,6079.65924,0.02678,48.74170,0.02678,1.33890
43.35000,3.52836,6149.50061,0.02729,49.30163,0.02729,1.36439
44.20000,3.59928,6218.74221,0.02781,49.85675,0.02781,1.39047
45.05000,3.67008,6287.31474,0.02833,50.40651,0.02833,1.41661
45.90000,3.74104,6354.34687,0.02886,50.94392,0.02886,1.44275
46.75000,3.81176,6419.56702,0.02938,51.46680,0.02938,1.46911
47.60000,3.88272,6482.39478,0.02992,51.97050,0.02992,1.49578
48.45000,3.95348,6546.24104,0.03045,52.48237,0.03045,1.52269
49.30000,4.02436,6609.34895,0.03100,52.98831,0.03100,1.55007
50.15000,4.09516,6668.61385,0.03154,53.46345,0.03154,1.57706
51.00000,4.16608,6728.94344,0.03210,53.94712,0.03210,1.60506
51.85000,4.23692,6787.37909,0.03266,54.41561,0.03266,1.63298
52.70000,4.30760,6843.64662,0.03322,54.86672,0.03322,1.66102
53.55000,4.37844,6900.44016,0.03379,55.32204,0.03379,1.68944
54.40000,4.44932,6955.09315,0.03437,55.76021,0.03437,1.71844
55.25000,4.52020,7007.75161,0.03494,56.18238,0.03494,1.74700
56.10000,4.59088,7058.91475,0.03552,56.59256,0.03552,1.77587
56.95000,4.66204,7108.95360,0.03610,56.99373,0.03610,1.80490
57.80000,4.73264,7156.90106,0.03668,57.37814,0.03668,1.83382
58.65000,4.80348,7204.12061,0.03727,57.75670,0.03727,1.86337
59.50000,4.87436,7248.81142,0.03786,58.11500,0.03786,1.89318
60.35000,4.94516,7292.80040,0.03847,58.46766,0.03847,1.92347
61.20000,5.01596,7336.24101,0.03907,58.81594,0.03907,1.95368
62.05000,5.08692,7377.79215,0.03968,59.14906,0.03968,1.98395
62.90000,5.15760,7418.50361,0.04030,59.47545,0.04030,2.01493
63.75000,5.22856,7460.01974,0.04093,59.80829,0.04093,2.04656
64.60000,5.29924,7496.39198,0.04156,60.09989,0.04156,2.07793
65.45000,5.37012,7532.79030,0.04219,60.39171,0.04219,2.10951
66.30000,5.44104,7575.52087,0.04288,60.73428,0.04288,2.14391
67.15000,5.51164,7615.95517,0.04359,61.05845,0.04359,2.17937
68.00000,5.58272,7654.97014,0.04432,61.37124,0.04432,2.21581
68.85000,5.65356,7690.91919,0.04505,61.65945,0.04505,2.25247
69.70000,5.72432,7685.67473,0.04557,61.61741,0.04557,2.27842
70.55000,5.79508,7726.37278,0.04629,61.94369,0.04629,2.31470
71.40000,5.86608,7762.14674,0.04704,62.23050,0.04704,2.35216
72.25000,5.93676,7791.84625,0.04779,62.46860,0.04779,2.38955
73.10000,6.00764,7821.72009,0.04856,62.70811,0.04856,2.42807
73.95000,6.07856,7848.32984,0.04935,62.92144,0.04935,2.46731
74.80000,6.14924,7872.45631,0.05015,63.11487,0.05015,2.50728
75.65000,6.22016,7894.18593,0.05096,63.28908,0.05096,2.54822
76.50000,6.29084,7879.51946,0.05152,63.17149,0.05152,2.57583
77.35000,6.36196,7908.86804,0.05235,63.40679,0.05235,2.61762
78.20000,6.43268,7927.93781,0.05317,63.55967,0.05317,2.65865
79.05000,6.50352,7943.72931,0.05401,63.68628,0.05401,2.70052
79.90000,6.57432,7960.01777,0.05488,63.81686,0.05488,2.74386
80.75000,6.64524,7973.54877,0.05577,63.92534,0.05577,2.78836
81.60000,6.71596,7982.50660,0.05667,63.99716,0.05667,2.83330
82.45000,6.78684,7989.69194,0.05758,64.05477,0.05758,2.87914
83.30000,6.85780,7994.72257,0.05852,64.09510,0.05852,2.92581
84.15000,6.92844,7997.36157,0.05946,64.11626,0.05946,2.97312
85.00000,6.99924,7998.00009,0.06043,64.12137,0.06043,3.02174
85.85000,7.07016,7997.06057,0.06143,64.11384,0.06143,3.07143
86.70000,7.14108,7994.08853,0.06244,64.09001,0.06244,3.12180
87.55000,7.21168,7989.16221,0.06347,64.05052,0.06347,3.17373
88.40000,7.28280,7980.46812,0.06452,63.98082,0.06452,3.22612
89.25000,7.35348,7972.49600,0.06559,63.91690,0.06559,3.27968
90.10000,7.42436,7961.20837,0.06668,63.82641,0.06668,3.33423
90.95000,7.49512,7945.44965,0.06779,63.70007,0.06779,3.38952
91.80000,7.56604,7930.58202,0.06892,63.58087,0.06892,3.44597
92.65000,7.63688,7912.98002,0.07006,63.43975,0.07006,3.50310
93.45200,7.70352,7894.05629,0.07115,63.28804,0.07072,3.53610
94.30200,7.77428,7872.22907,0.07232,63.11305,0.07140,3.57012
95.15200,7.84524,7850.64548,0.07347,62.94001,0.07208,3.60423
96.00200,7.91588,7824.07373,0.04511,62.72698,0.07276,3.63820
96.85200,7.98680,7797.76350,0.24111,62.51604,0.07345,3.67229
97.70200,8.05776,7769.47439,0.04247,62.28924,0.07413,3.70641
98.55200,8.12832,7739.06112,0.13451,62.04542,0.07481,3.74033
99.40200,8.19936,7708.23210,0.04945,61.79825,0.07549,3.77448
100.25200,8.27024,7674.32600,0.12427,61.52642,0.07617,3.80856
101.10200,8.34104,7637.71459,0.12555,61.23290,0.07685,3.84260
101.95200,8.41172,7596.33780,0.12701,60.90118,0.07753,3.87658
102.80200,8.48268,7548.92305,0.12573,60.52104,0.07821,3.91070
103.65200,8.55348,7494.05473,0.12486,60.08116,0.07889,3.94473
104.50200,8.62436,7422.92479,0.12581,59.51089,0.07958,3.97881
105.35201,8.69520,7318.18676,0.12636,58.67119,0.08026,4.01287
106.20201,8.76600,7147.67501,0.12560,57.30417,0.08094,4.04691
107.05201,8.83688,6834.71709,0.12525,54.79513,0.08162,4.08098
107.90201,8.90752,6411.25068,0.12586,51.40013,0.08230,4.11495
108.75201,8.97860,6100.94815,0.12610,48.91238,0.08298,4.14912
109.60201,9.04936,5930.30937,0.12561,47.54433,0.08366,4.18314
110.45201,9.12016,5835.22618,0.12552,46.78204,0.08434,4.21718
111.30201,9.19092,5782.20487,0.12585,46.35695,0.08502,4.25120
112.15201,9.26200,5753.27352,0.12590,46.12501,0.08571,4.28537
113.00201,9.33264,5735.42193,0.12569,45.98189,0.08639,4.31933
113.85201,9.40348,5727.55374,0.12566,45.91881,0.08707,4.35339
114.70201,9.47448,5723.75134,0.12580,45.88832,0.08775,4.38752
115.55201,9.54516,5723.28381,0.12579,45.88457,0.08843,4.42150
116.40201,9.61592,5726.20519,0.13804,45.90799,0.08911,4.45552
117.25201,9.68680,5727.58876,0.13268,45.91909,0.08979,4.48960
118.10201,9.75780,5731.87582,0.12938,45.95346,0.09047,4.52373
118.95201,9.82844,5735.33103,0.11285,45.98116,0.09115,4.55770
119.80201,9.89940,5737.53975,0.12424,45.99887,0.09184,4.59181
120.65201,9.97016,5741.74710,0.12418,46.03260,0.09252,4.62583
121.50201,10.04104,5746.95133,0.12407,46.07432,0.09320,4.65991
122.35201,10.11168,5747.75748,0.12419,46.08078,0.09388,4.69387
123.20201,10.18268,5752.41335,0.12426,46.11811,0.09456,4.72800
124.05201,10.25360,5756.48062,0.12418,46.15072,0.09524,4.76210
124.90201,10.32432,5757.75355,0.12422,46.16092,0.09592,4.79610
125.75201,10.39508,5760.57695,0.12419,46.18356,0.09660,4.83012
126.60201,10.46608,5764.80143,0.12423,46.21743,0.09729,4.86425
127.45201,10.53672,5765.28907,0.12417,46.22134,0.09796,4.89821
128.30201,10.60756,5768.35945,0.12419,46.24595,0.09865,4.93227
129.15201,10.67864,5769.65325,0.12419,46.25633,0.09933,4.96645
130.00201,10.74924,5771.92679,0.12424,46.27455,0.10001,5.00039
130.85201,10.82020,5774.79266,0.12422,46.29753,0.10069,5.03450
131.70201,10.89100,5775.77166,0.12417,46.30538,0.10137,5.06854
132.55201,10.96192,5777.76246,0.12420,46.32134,0.10205,5.10264
133.40201,11.03264,5779.95814,0.12423,46.33894,0.10273,5.13664
134.25201,11.10340,5780.38320,0.12421,46.34235,0.10341,5.17066
135.10201,11.17440,5782.86871,0.12417,46.36228,0.10410,5.20479
135.95201,11.24520,5786.34590,0.12422,46.39015,0.10478,5.23883
136.80201,11.31592,5785.12922,0.12423,46.38040,0.10546,5.27283
137.65201,11.38680,5788.44287,0.12421,46.40697,0.10614,5.30691
138.50201,11.45776,5789.90094,0.12419,46.41865,0.10682,5.34102
139.35201,11.52836,5790.44148,0.12418,46.42299,0.10750,5.37496
140.20201,11.59944,5791.49351,0.12422,46.43142,0.10818,5.40914
141.05201,11.67016,5793.23731,0.12415,46.44540,0.10886,5.44314
141.90201,11.74104,5794.51211,0.12420,46.45562,0.10954,5.47722
142.75201,11.81172,5794.11723,0.12417,46.45246,0.11022,5.51120
143.60201,11.88276,5795.07872,0.12425,46.46017,0.11091,5.54535
144.45201,11.95352,5796.22835,0.12422,46.46938,0.11159,5.57937
145.30201,12.02432,5797.17346,0.12421,46.47696,0.11227,5.61341
146.15201,12.09520,5797.17271,0.12422,46.47695,0.11295,5.64748
147.00201,12.16604,5798.53803,0.12423,46.48790,0.11363,5.68154
147.85201,12.23680,5799.27228,0.12421,46.49379,0.11431,5.71556
148.70201,12.30752,5799.18921,0.12421,46.49312,0.11499,5.74956
149.55201,12.37860,5800.65735,0.12423,46.50489,0.11567,5.78373
150.40201,12.44928,5801.52720,0.12421,46.51186,0.11635,5.81771
151.25201,12.52020,5802.73606,0.12423,46.52156,0.11704,5.85181
152.10201,12.59096,5803.35930,0.12421,46.52655,0.11772,5.88583
152.95201,12.66196,5803.67036,0.12424,46.52905,0.11840,5.91996
153.80201,12.73252,5803.13653,0.12422,46.52477,0.11908,5.95389
154.65201,12.80340,5803.25872,0.12419,46.52575,0.11976,5.98796
155.50201,12.87436,5803.47851,0.12421,46.52751,0.12044,6.02208
156.35201,12.94520,5803.98366,0.12424,46.53156,0.12112,6.05614
157.20201,13.01588,5804.19749,0.12422,46.53327,0.12180,6.09012
158.05201,13.08684,5804.74995,0.12422,46.53770,0.12248,6.12423
158.90201,13.15760,5805.57548,0.12421,46.54432,0.12317,6.15825
159.75201,13.22848,5807.16915,0.12423,46.55710,0.12385,6.19233
160.60201,13.29932,5806.42037,0.12422,46.55109,0.12453,6.22639
161.45201,13.37016,5808.32250,0.12422,46.56634,0.12521,6.26045
162.30201,13.44108,5810.49547,0.12423,46.58376,0.12589,6.29454
163.15201,13.51176,5808.45885,0.12424,46.56744,0.12657,6.32852
164.00201,13.58276,5810.16317,0.12421,46.58110,0.12725,6.36266
164.85201,13.65356,5809.88340,0.12422,46.57886,0.12793,6.39670
165.70201,13.72424,5809.26836,0.12423,46.57393,0.12861,6.43068
166.55201,13.79516,5809.02137,0.12423,46.57195,0.12930,6.46477
167.40201,13.86608,5809.38160,0.12424,46.57483,0.12998,6.49887
168.25201,13.93680,5808.72260,0.12422,46.56955,0.13066,6.53287
169.10201,14.00764,5809.57718,0.12420,46.57640,0.13134,6.56693
169.95201,14.07864,5809.48368,0.12420,46.57565,0.13202,6.60106
170.80201,14.14924,5809.60251,0.12426,46.57661,0.13270,6.63500
171.65201,14.22028,5811.63056,0.12426,46.59287,0.13338,6.66916
172.50201,14.29092,5811.58400,0.12420,46.59249,0.13406,6.70312
173.35201,14.36192,5813.35388,0.12419,46.60668,0.13475,6.73725
174.20201,14.43264,5815.28433,0.12423,46.62216,0.13543,6.77125
175.05201,14.50352,5813.85233,0.12426,46.61068,0.13611,6.80533
175.90201,14.57436,5814.79445,0.12421,46.61823,0.13679,6.83939
176.75201,14.64516,5814.86747,0.12420,46.61882,0.13747,6.87343
177.60201,14.71592,5814.46178,0.12424,46.61556,0.13815,6.90745
178.45201,14.78684,5814.89317,0.12423,46.61902,0.13883,6.94154
179.30201,14.85768,5815.00493,0.12423,46.61992,0.13951,6.97560
180.15201,14.92840,5813.60348,0.12423,46.60868,0.14019,7.00960
181.00201,14.99940,5814.99413,0.12424,46.61983,0.14087,7.04373
181.85201,15.07016,5815.59800,0.12423,46.62467,0.14156,7.07775
182.70201,15.14100,5815.90869,0.12425,46.62716,0.14224,7.11181
183.55201,15.21176,5817.51466,0.12423,46.64004,0.14292,7.14583
184.40201,15.28276,5816.40191,0.12422,46.63112,0.14360,7.17997
185.25201,15.35340,5817.73296,0.12421,46.64179,0.14428,7.21393
186.10201,15.42424,5819.41046,0.12425,46.65524,0.14496,7.24798
186.95201,15.49512,5818.13678,0.12424,46.64503,0.14564,7.28206
187.80201,15.56608,5820.40325,0.12425,46.66320,0.14632,7.31618
188.65201,15.63680,5819.56655,0.12422,46.65649,0.14700,7.35018
189.50201,15.70764,5819.52818,0.12422,46.65618,0.14768,7.38423
190.35201,15.77848,5819.90518,0.12424,46.65920,0.14837,7.41829
191.20201,15.84936,5820.98067,0.12427,46.66783,0.14905,7.45237
192.05201,15.92016,5819.82136,0.12423,46.65853,0.14973,7.48641
192.90201,15.99100,5820.68823,0.12423,46.66548,0.15041,7.52046
193.75201,16.06196,5821.52680,0.12424,46.67220,0.15109,7.55458
194.60201,16.13256,5821.67432,0.12422,46.67339,0.15177,7.58852
195.45201,16.20356,5822.60899,0.12423,46.68088,0.15245,7.62266
196.30201,16.27444,5822.61309,0.12426,46.68091,0.15313,7.65673
197.15201,16.34512,5823.38311,0.12427,46.68709,0.15381,7.69072
198.00201,16.41600,5824.66088,0.12419,46.69733,0.15450,7.72479
198.85201,16.48692,5825.06359,0.12420,46.70056,0.15518,7.75889
199.70201,16.55760,5825.55234,0.12427,46.70448,0.15586,7.79287
200.55201,16.62852,5826.33950,0.12426,46.71079,0.15654,7.82696
201.40201,16.69936,5825.25469,0.12422,46.70209,0.15722,7.86102
202.25201,16.77016,5825.17348,0.12422,46.70144,0.15790,7.89506
203.10201,16.84116,5826.52166,0.12423,46.71225,0.15858,7.92920
203.95201,16.91172,5824.72943,0.12424,46.69788,0.15926,7.96312
204.80201,16.98280,5826.71165,0.12424,46.71377,0.15995,7.99729
205.65201,17.05352,5826.79138,0.12423,46.71441,0.16063,8.03129
206.50201,17.12432,5826.29777,0.12423,46.71045,0.16131,8.06533
207.35201,17.19508,5827.34086,0.12424,46.71882,0.16199,8.09935
208.20201,17.26604,5827.93318,0.12423,46.72357,0.16267,8.13347
209.05201,17.33676,5827.89183,0.12427,46.72323,0.16335,8.16746
209.90201,17.40764,5829.25528,0.12426,46.73417,0.16403,8.20154
210.75201,17.47852,5829.64197,0.12421,46.73727,0.16471,8.23562
211.60201,17.54924,5829.27689,0.12423,46.73434,0.16539,8.26962
212.45201,17.62020,5830.12216,0.12425,46.74112,0.16607,8.30373
213.30201,17.69092,5828.81682,0.12426,46.73065,0.16675,8.33773
214.15201,17.76192,5829.34134,0.12425,46.73486,0.16744,8.37187
215.00201,17.83264,5829.94223,0.12425,46.73967,0.16812,8.40587
215.85201,17.90348,5829.76639,0.12424,46.73826,0.16880,8.43993
216.70201,17.97432,5829.60472,0.12426,46.73697,0.16948,8.47398
217.55201,18.04516,5830.88100,0.12423,46.74720,0.17016,8.50804
218.40201,18.11588,5830.41720,0.12426,46.74348,0.17084,8.54204
219.25201,18.18688,5832.10476,0.12424,46.75701,0.17152,8.57618
220.10201,18.25772,5833.43729,0.12424,46.76769,0.17220,8.61023
220.95201,18.32840,5832.76674,0.12424,46.76232,0.17288,8.64421
221.80201,18.39924,5834.33025,0.12423,46.77485,0.17357,8.67827
222.65201,18.47024,5834.99074,0.12426,46.78015,0.17425,8.71241
223.50201,18.54100,5834.36787,0.12426,46.77515,0.17493,8.74643
224.35201,18.61176,5833.77257,0.12424,46.77038,0.17561,8.78045
225.20201,18.68276,5832.85391,0.12426,46.76302,0.17629,8.81458
226.05201,18.75344,5834.31050,0.12428,46.77469,0.17697,8.84856
226.90201,18.82440,5835.03023,0.12424,46.78046,0.17765,8.88268
227.75201,18.89520,5833.49206,0.12422,46.76813,0.17833,8.91672
228.60201,18.96604,5834.76610,0.12426,46.77835,0.17902,8.95077
229.45201,19.03684,5836.31396,0.12427,46.79076,0.17970,8.98481
230.30201,19.10768,5835.68476,0.12427,46.78571,0.18038,9.01887
231.15201,19.17848,5836.40076,0.12424,46.79145,0.18106,9.05291
232.00201,19.24936,5838.43775,0.12425,46.80778,0.18174,9.08698
232.85201,19.32008,5836.84631,0.12427,46.79502,0.18242,9.12098
233.70201,19.39092,5839.08893,0.12424,46.81300,0.18310,9.15504
234.55201,19.46200,5839.46109,0.12427,46.81599,0.18378,9.18921
235.40201,19.53252,5839.66188,0.12429,46.81760,0.18446,9.22312
236.25201,19.60356,5839.42942,0.12425,46.81573,0.18515,9.25727
237.10201,19.67436,5839.50356,0.12426,46.81633,0.18583,9.29131
237.95201,19.74520,5839.65704,0.12425,46.81756,0.18651,9.32537
238.80201,19.81592,5839.66337,0.12425,46.81761,0.18719,9.35937
239.65201,19.88684,5839.04535,0.12426,46.81265,0.18787,9.39347
240.50201,19.95764,5839.78407,0.12427,46.81858,0.18855,9.42750
241.35201,20.02856,5841.17770,0.12424,46.82975,0.18923,9.46160
242.20201,20.09928,5839.37094,0.12421,46.81526,0.18991,9.49560
243.05201,20.17016,5841.09239,0.12427,46.82907,0.19059,9.52968
243.90201,20.24100,5842.10865,0.12428,46.83721,0.19127,9.56373
244.75201,20.31168,5840.74929,0.12424,46.82632,0.19195,9.59772
245.60201,20.38272,5842.45436,0.12427,46.83998,0.19264,9.63187
246.45201,20.45360,5844.05698,0.12428,46.85283,0.19332,9.66594
247.30201,20.52432,5843.08393,0.12424,46.84503,0.19400,9.69995
248.15201,20.59512,5843.97130,0.12425,46.85215,0.19468,9.73398
249.00201,20.66604,5844.38555,0.12427,46.85547,0.19536,9.76808
249.85201,20.73680,5844.20003,0.12427,46.85398,0.19604,9.80210
250.70201,20.80768,5845.99078,0.12426,46.86834,0.19672,9.83618
251.55201,20.87848,5844.67687,0.12425,46.85780,0.19740,9.87021
252.40201,20.94928,5844.90374,0.12426,46.85962,0.19809,9.90425
253.25201,21.02008,5846.31599,0.12426,46.87094,0.19877,9.93829
254.10201,21.09100,5846.31003,0.12429,46.87090,0.19945,9.97239
254.95201,21.16188,5846.96867,0.12426,46.87618,0.20013,10.00647
255.80201,21.23272,5848.43047,0.12424,46.88790,0.20081,10.04052
256.65201,21.30352,5848.03782,0.12426,46.88475,0.20149,10.07456
257.50201,21.37432,5850.13516,0.12429,46.90156,0.20217,10.10860
258.35201,21.44528,5850.90593,0.12426,46.90774,0.20285,10.14272
259.20201,21.51596,5850.75580,0.12424,46.90654,0.20353,10.17669
260.05201,21.58684,5851.83948,0.12427,46.91523,0.20422,10.21077
260.90201,21.65776,5852.72834,0.12429,46.92235,0.20490,10.24487
261.75201,21.72852,5852.95521,0.12427,46.92417,0.20558,10.27889
262.60201,21.79920,5851.87674,0.12427,46.91553,0.20626,10.31287
263.45201,21.87016,5853.02189,0.12426,46.92471,0.20694,10.34698
264.30201,21.94096,5851.65881,0.12427,46.91378,0.20762,10.38102
265.15201,22.01172,5852.69891,0.12424,46.92212,0.20830,10.41504
266.00201,22.08280,5852.47055,0.12424,46.92029,0.20898,10.44921
266.85201,22.15340,5853.68648,0.12428,46.93003,0.20966,10.48316
267.70201,22.22440,5854.41776,0.12427,46.93590,0.21035,10.51729
268.55201,22.29508,5852.97085,0.12425,46.92430,0.21103,10.55127
269.40201,22.36608,5855.21385,0.12426,46.94228,0.21171,10.58541
270.25201,22.43680,5855.56254,0.12425,46.94508,0.21239,10.61941
271.10201,22.50764,5855.16840,0.12424,46.94192,0.21307,10.65347
271.95201,22.57840,5855.38670,0.12426,46.94367,0.21375,10.68749
272.80201,22.64940,5855.81809,0.12427,46.94712,0.21443,10.72162
273.65201,22.72008,5854.69604,0.12424,46.93813,0.21511,10.75560
274.50201,22.79092,5855.53311,0.12427,46.94484,0.21579,10.78966
275.35201,22.86184,5855.89074,0.12428,46.94771,0.21648,10.82375
276.20201,22.93256,5856.07588,0.12427,46.94919,0.21716,10.85775
277.05201,23.00352,5856.88353,0.12427,46.95567,0.21784,10.89187
277.90201,23.07440,5857.79920,0.12430,46.96301,0.21852,10.92595
278.75201,23.14524,5858.11138,0.12426,46.96551,0.21920,10.96000
279.60201,23.21596,5858.92051,0.12426,46.97200,0.21988,10.99400
280.45201,23.28684,5858.85867,0.12427,46.97150,0.22056,11.02808
281.30201,23.35768,5860.07163,0.12429,46.98123,0.22124,11.06214
282.15201,23.42856,5861.88696,0.12426,46.99578,0.22192,11.09621
283.00201,23.49924,5859.81496,0.12425,46.97917,0.22260,11.13020
283.85201,23.57016,5861.21567,0.12426,46.99040,0.22329,11.16429
284.70201,23.64100,5860.85804,0.12429,46.98753,0.22397,11.19835
285.55201,23.71176,5860.51717,0.12426,46.98480,0.22465,11.23237
286.40201,23.78268,5860.49967,0.12426,46.98466,0.22533,11.26647
287.25201,23.85360,5862.49605,0.12427,47.00066,0.22601,11.30056
288.10201,23.92432,5860.52351,0.12425,46.98485,0.22669,11.33456
288.95201,23.99512,5862.29563,0.12428,46.99906,0.22737,11.36860
289.80201,24.06612,5862.85815,0.12426,47.00357,0.22805,11.40273
290.65201,24.13680,5862.05609,0.12424,46.99714,0.22873,11.43672
291.50201,24.20768,5863.89117,0.12426,47.01185,0.22942,11.47079
292.35201,24.27852,5862.74676,0.12428,47.00267,0.23010,11.50485
293.20201,24.34936,5864.98939,0.12426,47.02065,0.23078,11.53891
294.05201,24.42004,5865.55600,0.12425,47.02519,0.23146,11.57289
294.90201,24.49092,5865.57761,0.12427,47.02537,0.23214,11.60696
295.75201,24.56180,5865.96206,0.12430,47.02845,0.23282,11.64104
296.60201,24.63264,5866.71121,0.12427,47.03446,0.23350,11.67510
297.45201,24.70356,5866.13677,0.12426,47.02985,0.23418,11.70920
298.30201,24.77424,5865.76723,0.12427,47.02689,0.23486,11.74318
299.15201,24.84528,5866.79988,0.12428,47.03517,0.23555,11.77733
300.00201,24.91588,5864.58482,0.12425,47.01741,0.23623,11.81127
300.85201,24.98692,5866.10548,0.12426,47.02960,0.23691,11.84543
301.70201,25.05768,5867.08114,0.12426,47.03742,0.23759,11.87945
302.55201,25.12848,5867.39592,0.12426,47.03995,0.23827,11.91348
303.40201,25.19920,5868.08845,0.12427,47.04550,0.23895,11.94748
304.25201,25.27028,5869.55845,0.12429,47.05728,0.23963,11.98166
305.10201,25.34096,5869.55100,0.12426,47.05722,0.24031,12.01564
305.95201,25.41176,5871.13053,0.12426,47.06989,0.24099,12.04968
306.80201,25.48268,5870.13811,0.12427,47.06193,0.24168,12.08377
307.65201,25.55348,5871.25495,0.12427,47.07088,0.24236,12.11781
308.50201,25.62440,5871.87819,0.12429,47.07588,0.24304,12.15191
309.35201,25.69516,5870.48717,0.12426,47.06473,0.24372,12.18593
310.20201,25.76608,5871.21099,0.12424,47.07053,0.24440,12.22002
311.05201,25.83684,5870.82915,0.12425,47.06747,0.24508,12.25404
311.90201,25.90764,5870.57769,0.12430,47.06545,0.24576,12.28808
312.75201,25.97852,5870.17015,0.12429,47.06219,0.24644,12.32216
313.60201,26.04944,5871.72769,0.12426,47.07467,0.24713,12.35625
314.45201,26.12008,5869.84903,0.12425,47.05961,0.24780,12.39022
315.30201,26.19096,5871.44494,0.12425,47.07241,0.24849,12.42429
316.15202,26.26196,5873.20291,0.12427,47.08650,0.24917,12.45843
317.00202,26.33256,5872.75475,0.12430,47.08291,0.24985,12.49237
317.85202,26.40344,5873.19732,0.12426,47.08646,0.25053,12.52645
318.70202,26.47440,5874.79062,0.12425,47.09923,0.25121,12.56056
319.55202,26.54520,5874.53209,0.12428,47.09716,0.25189,12.59460
320.40202,26.61592,5875.01489,0.12428,47.10103,0.25257,12.62860
321.25202,26.68688,5874.37227,0.12428,47.09588,0.25325,12.66271
322.10202,26.75768,5875.12292,0.12428,47.10189,0.25394,12.69675
322.95202,26.82856,5875.78416,0.12428,47.10720,0.25462,12.73083
323.80202,26.89928,5874.00869,0.12426,47.09296,0.25530,12.76483
324.65202,26.97024,5875.62919,0.12426,47.10595,0.25598,12.79895
325.50202,27.04096,5875.96148,0.12429,47.10862,0.25666,12.83295
326.35202,27.11168,5874.45349,0.12428,47.09653,0.25734,12.86695
327.20202,27.18260,5876.75832,0.12428,47.11501,0.25802,12.90104
328.05202,27.25356,5877.56410,0.12429,47.12147,0.25870,12.93516
328.90202,27.32436,5877.86250,0.12424,47.12386,0.25938,12.96920
329.75202,27.39504,5878.48313,0.12426,47.12883,0.26006,13.00318
330.60202,27.46608,5880.35956,0.12429,47.14388,0.26075,13.03733
331.45202,27.53672,5879.70763,0.12428,47.13865,0.26143,13.07129
332.30202,27.60772,5879.94978,0.12428,47.14059,0.26211,13.10543
333.15202,27.67848,5879.82871,0.12426,47.13962,0.26279,13.13945
334.00202,27.74944,5881.46150,0.12428,47.15271,0.26347,13.17356
334.85202,27.82012,5880.88706,0.12430,47.14811,0.26415,13.20754
335.70202,27.89100,5880.93400,0.12425,47.14848,0.26483,13.24162
336.55202,27.96184,5880.83155,0.12427,47.14766,0.26551,13.27568
337.40202,28.03268,5882.42598,0.12429,47.16044,0.26619,13.30973
338.25202,28.10344,5881.82732,0.12425,47.15564,0.26688,13.34375
339.10202,28.17436,5883.84382,0.12422,47.17181,0.26756,13.37785
339.95202,28.24532,5884.13440,0.12428,47.17414,0.26824,13.41196
340.80202,28.31588,5883.40536,0.12432,47.16830,0.26892,13.44589
341.65202,28.38684,5884.98004,0.12428,47.18092,0.26960,13.48000
342.50202,28.45772,5885.74298,0.12423,47.18704,0.27028,13.51408
343.35202,28.52856,5886.00449,0.12427,47.18913,0.27096,13.54814
344.20202,28.59928,5885.25720,0.12431,47.18314,0.27164,13.58214
345.05202,28.67028,5885.34288,0.12426,47.18383,0.27233,13.61627
345.90202,28.74100,5885.40882,0.12428,47.18436,0.27301,13.65027
346.75202,28.81176,5885.21026,0.12429,47.18277,0.27369,13.68429
347.60202,28.88268,5885.14805,0.12428,47.18227,0.27437,13.71839
348.45202,28.95344,5885.64128,0.12428,47.18622,0.27505,13.75241
349.30202,29.02432,5885.80333,0.12427,47.18752,0.27573,13.78648
350.15202,29.09508,5885.04039,0.12427,47.18140,0.27641,13.82050
351.00202,29.16612,5887.43687,0.12427,47.20062,0.27709,13.85466
351.85202,29.23680,5888.16591,0.12428,47.20646,0.27777,13.88864
352.70202,29.30760,5886.57185,0.12427,47.19368,0.27845,13.92268
353.55202,29.37844,5888.67851,0.12426,47.21057,0.27913,13.95673
354.40202,29.44940,5889.48019,0.12428,47.21700,0.27982,13.99085
355.25202,29.52008,5888.75711,0.12426,47.21120,0.28050,14.02483
356.10202,29.59104,5889.13225,0.12426,47.21421,0.28118,14.05895
356.95202,29.66184,5889.03464,0.12426,47.21343,0.28186,14.09298
357.80202,29.73260,5888.20688,0.12425,47.20679,0.28254,14.12700
358.65202,29.80340,5887.56315,0.12431,47.20163,0.28322,14.16104
359.50202,29.87436,5887.14853,0.12428,47.19831,0.28390,14.19516
360.35202,29.94524,5888.51459,0.12426,47.20926,0.28458,14.22923
361.20202,30.01588,5887.87831,0.12425,47.20416,0.28526,14.26319
362.05202,30.08688,5888.32349,0.12428,47.20773,0.28595,14.29733
362.90202,30.15756,5888.97206,0.12428,47.21293,0.28663,14.33131
363.75202,30.22864,5890.82614,0.12427,47.22779,0.28731,14.36548
364.60202,30.29920,5889.32298,0.12425,47.21574,0.28799,14.39941
365.45202,30.37032,5892.20934,0.12429,47.23888,0.28867,14.43360
366.30202,30.44096,5892.04058,0.12430,47.23753,0.28935,14.46756
367.15202,30.51180,5891.42628,0.12427,47.23260,0.29003,14.50162
368.00202,30.58268,5891.95751,0.12425,47.23686,0.29071,14.53570
368.85202,30.65360,5891.82600,0.12427,47.23581,0.29140,14.56979
369.70202,30.72432,5891.34991,0.12429,47.23199,0.29208,14.60379
370.55202,30.79512,5890.16452,0.12428,47.22249,0.29276,14.63783
371.40202,30.86616,5890.72108,0.12427,47.22695,0.29344,14.67198
372.25202,30.93672,5889.75884,0.12427,47.21923,0.29412,14.70591
373.10202,31.00768,5890.63764,0.12427,47.22628,0.29480,14.74002
373.95202,31.07848,5890.75163,0.12430,47.22719,0.29548,14.77406
374.80202,31.14944,5891.59131,0.12425,47.23392,0.29616,14.80818
375.65202,31.22012,5892.60608,0.12421,47.24206,0.29684,14.84216
376.50202,31.29096,5891.82787,0.12425,47.23582,0.29752,14.87622
377.35202,31.36184,5893.54225,0.12430,47.24957,0.29821,14.91029
378.20202,31.43268,5894.97127,0.12428,47.26102,0.29889,14.94435
379.05202,31.50348,5894.84386,0.12427,47.26000,0.29957,14.97839
379.90202,31.57428,5897.26306,0.12425,47.27940,0.30025,15.01243
380.75202,31.64524,5897.58940,0.12426,47.28201,0.30093,15.04654
381.60202,31.71584,5897.89227,0.12420,47.28444,0.30161,15.08048
382.45202,31.78692,5900.20008,0.12424,47.30294,0.30229,15.11466
383.30202,31.85768,5900.48097,0.12429,47.30519,0.30297,15.14868
384.15202,31.92848,5900.06672,0.12430,47.30187,0.30365,15.18272
385.00202,31.99920,5901.00363,0.12427,47.30938,0.30433,15.21672
385.85202,32.07028,5901.69579,0.12426,47.31493,0.30502,15.25089
386.70202,32.14088,5900.54728,0.12426,47.30573,0.30570,15.28483
387.55202,32.21184,5902.84653,0.12427,47.32416,0.30638,15.31895
388.40202,32.28264,5900.98090,0.12427,47.30920,0.30706,15.35299
389.25202,32.35344,5901.51176,0.12427,47.31346,0.30774,15.38702
390.10202,32.42432,5901.60303,0.12426,47.31419,0.30842,15.42110
390.95202,32.49512,5900.41280,0.12428,47.30465,0.30910,15.45514
391.80202,32.56608,5900.84791,0.12429,47.30814,0.30979,15.48925
392.65202,32.63676,5901.16009,0.12426,47.31064,0.31046,15.52323
393.50202,32.70768,5900.26006,0.12424,47.30342,0.31115,15.55733
394.35202,32.77844,5899.07952,0.12431,47.29396,0.31183,15.59135
395.20202,32.84952,5900.95706,0.12432,47.30901,0.31251,15.62552
396.05202,32.92004,5897.83899,0.12426,47.28401,0.31319,15.65943
396.90202,32.99108,5898.89623,0.12423,47.29249,0.31387,15.69358
397.75202,33.06188,5899.41666,0.12428,47.29666,0.31455,15.72762
398.60202,33.13260,5899.02885,0.12432,47.29355,0.31523,15.76162
399.45202,33.20348,5899.86481,0.12429,47.30025,0.31591,15.79570
400.30202,33.27440,5901.10756,0.12424,47.31022,0.31660,15.82979
401.15202,33.34520,5901.36647,0.12426,47.31229,0.31728,15.86383
402.00202,33.41592,5902.76085,0.12429,47.32347,0.31796,15.89783
402.85202,33.48696,5902.41551,0.12428,47.32070,0.31864,15.93198
403.70202,33.55760,5902.68187,0.12429,47.32284,0.31932,15.96595
404.55202,33.62856,5903.21682,0.12426,47.32713,0.32000,16.00006
405.40202,33.69920,5901.78333,0.12428,47.31564,0.32068,16.03402
406.25202,33.77028,5903.22167,0.12430,47.32717,0.32136,16.06820
407.10202,33.84100,5903.05962,0.12427,47.32587,0.32204,16.10220
407.95202,33.91176,5902.37193,0.12425,47.32035,0.32272,16.13621
408.80202,33.98268,5903.42060,0.12427,47.32876,0.32341,16.17031
409.65202,34.05352,5903.85348,0.12429,47.33223,0.32409,16.20437
410.50202,34.12428,5903.49808,0.12425,47.32938,0.32477,16.23839
411.35202,34.19504,5904.27034,0.12428,47.33557,0.32545,16.27241
412.20202,34.26616,5904.55271,0.12433,47.33784,0.32613,16.30660
413.05202,34.33672,5904.03154,0.12428,47.33366,0.32681,16.34052
413.90202,34.40772,5905.28920,0.12422,47.34374,0.32749,16.37466
414.75202,34.47848,5903.68584,0.12424,47.33089,0.32817,16.40868
415.60202,34.54936,5904.67080,0.12430,47.33879,0.32886,16.44275
416.45202,34.61996,5903.98982,0.12435,47.33333,0.32953,16.47670
417.30202,34.69108,5903.69515,0.12428,47.33096,0.33022,16.51089
418.15202,34.76180,5903.82330,0.12422,47.33199,0.33090,16.54489
419.00202,34.83268,5904.96995,0.12427,47.34118,0.33158,16.57897
419.85202,34.90344,5903.41985,0.12431,47.32876,0.33226,16.61298
420.70202,34.97436,5904.71104,0.12428,47.33911,0.33294,16.64708
421.55202,35.04528,5906.37438,0.12425,47.35244,0.33362,16.68118
422.40202,35.11592,5904.81944,0.12426,47.33998,0.33430,16.71514
423.25202,35.18692,5907.27963,0.12428,47.35970,0.33499,16.74927
424.10202,35.25772,5907.25504,0.12430,47.35950,0.33567,16.78331
424.95202,35.32848,5906.89704,0.12427,47.35663,0.33635,16.81733
425.80202,35.39924,5907.13173,0.12426,47.35851,0.33703,16.85135
426.65202,35.47032,5908.01761,0.12428,47.36562,0.33771,16.88552
427.50202,35.54088,5907.42193,0.12429,47.36084,0.33839,16.91945
428.35202,35.61192,5908.62148,0.12427,47.37046,0.33907,16.95360
429.20202,35.68268,5907.52810,0.12428,47.36169,0.33975,16.98762
430.05202,35.75344,5908.26273,0.12429,47.36758,0.34043,17.02164
430.90202,35.82436,5907.66929,0.12427,47.36282,0.34111,17.05573
431.75202,35.89516,5905.45386,0.12426,47.34506,0.34180,17.08977
432.60202,35.96612,5904.68645,0.12428,47.33891,0.34248,17.12389
433.45202,36.03676,5905.96646,0.12427,47.34917,0.34316,17.15785
434.30202,36.10772,5904.07141,0.12430,47.33398,0.34384,17.19197
435.15202,36.17836,5904.86042,0.12430,47.34031,0.34452,17.22593
436.00202,36.24940,5906.61950,0.12426,47.35441,0.34520,17.26008
436.85202,36.31992,5904.47262,0.12427,47.33720,0.34588,17.29399
437.70202,36.39104,5906.18998,0.12430,47.35096,0.34656,17.32818
438.55202,36.46188,5905.61144,0.12429,47.34633,0.34724,17.36223
439.40202,36.53260,5905.33502,0.12426,47.34411,0.34792,17.39623
440.25202,36.60344,5905.46466,0.12428,47.34515,0.34861,17.43029
441.10202,36.67436,5905.04333,0.12430,47.34177,0.34929,17.46439
441.95202,36.74524,5904.28412,0.12429,47.33568,0.34997,17.49847
442.80202,36.81584,5904.24389,0.12430,47.33536,0.35065,17.53241
443.65202,36.88696,5903.42954,0.12429,47.32883,0.35133,17.56660
444.50202,36.95760,5903.51559,0.12427,47.32952,0.35201,17.60056
445.35202,37.02860,5903.99913,0.12428,47.33340,0.35269,17.63470
446.20202,37.09924,5902.53770,0.12429,47.32168,0.35337,17.66866
447.05202,37.17032,5903.96933,0.12429,47.33316,0.35406,17.70283
447.90202,37.24084,5903.75513,0.12427,47.33144,0.35473,17.73673
448.75202,37.31188,5903.49734,0.12426,47.32938,0.35542,17.77089
449.60202,37.38260,5904.47634,0.12429,47.33723,0.35610,17.80489
450.45202,37.45356,5905.87892,0.12430,47.34847,0.35678,17.83900
451.30202,37.52428,5904.09562,0.12427,47.33417,0.35746,17.87300
452.15202,37.59516,5904.54563,0.12428,47.33778,0.35814,17.90708
453.00202,37.66616,5904.14889,0.12429,47.33460,0.35882,17.94121
453.85202,37.73680,5902.94115,0.12431,47.32492,0.35950,17.97518
454.70202,37.80768,5902.61631,0.12428,47.32231,0.36019,18.00925
455.55202,37.87852,5902.64797,0.12427,47.32257,0.36087,18.04331
456.40202,37.94940,5901.95321,0.12427,47.31700,0.36155,18.07739
457.25202,38.02008,5901.96140,0.12429,47.31706,0.36223,18.11137
458.10202,38.09112,5901.84107,0.12428,47.31610,0.36291,18.14552
458.95202,38.16172,5902.23521,0.12429,47.31926,0.36359,18.17946
459.80202,38.23276,5902.71577,0.12428,47.32311,0.36427,18.21362
460.65202,38.30344,5902.56415,0.12427,47.32190,0.36495,18.24760
461.50202,38.37428,5903.48206,0.12429,47.32925,0.36563,18.28166
462.35202,38.44520,5903.98014,0.12429,47.33325,0.36632,18.31575
463.20202,38.51592,5902.37454,0.12429,47.32038,0.36700,18.34975
464.05202,38.58692,5902.90241,0.12427,47.32461,0.36768,18.38389
464.90202,38.65764,5902.32834,0.12428,47.32001,0.36836,18.41789
465.75202,38.72856,5901.95283,0.12431,47.31699,0.36904,18.45198
466.60202,38.79920,5901.85188,0.12429,47.31619,0.36972,18.48595
467.45202,38.87028,5901.15748,0.12426,47.31062,0.37040,18.52012
468.30202,38.94080,5900.13377,0.12427,47.30241,0.37108,18.55402
469.15202,39.01184,5901.26775,0.12430,47.31150,0.37176,18.58818
470.00202,39.08264,5899.96800,0.12430,47.30108,0.37244,18.62222
470.85202,39.15344,5901.08410,0.12428,47.31003,0.37313,18.65625
471.70202,39.22424,5900.96004,0.12429,47.30904,0.37381,18.69029
472.55202,39.29504,5899.39952,0.12428,47.29652,0.37449,18.72433
473.40202,39.36608,5900.44074,0.12428,47.30487,0.37517,18.75849
474.25202,39.43676,5900.69965,0.12428,47.30695,0.37585,18.79247
475.10202,39.50776,5899.02066,0.12429,47.29349,0.37653,18.82660
475.95202,39.57844,5898.16831,0.12429,47.28665,0.37721,18.86058
476.80202,39.64944,5898.67756,0.12430,47.29074,0.37789,18.89472
477.65202,39.72004,5896.28555,0.12429,47.27156,0.37857,18.92866
478.50202,39.79112,5895.86161,0.12430,47.26816,0.37926,18.96283
479.35202,39.86176,5894.78537,0.12428,47.25953,0.37994,18.99679
480.20202,39.93272,5894.17778,0.12424,47.25466,0.38062,19.03091
481.05202,40.00348,5893.92334,0.12430,47.25262,0.38130,19.06493
481.90202,40.07436,5893.61936,0.12434,47.25018,0.38198,19.09900
482.75202,40.14512,5893.24757,0.12430,47.24720,0.38266,19.13302
483.60202,40.21596,5894.21540,0.12426,47.25496,0.38334,19.16708
484.45202,40.28696,5892.23281,0.12429,47.23907,0.38402,19.20121
485.30202,40.35764,5892.61390,0.12431,47.24212,0.38470,19.23520
486.15202,40.42860,5892.72976,0.12429,47.24305,0.38539,19.26931
487.00202,40.49932,5890.67787,0.12429,47.22660,0.38607,19.30331
487.85202,40.57028,5892.24733,0.12430,47.23918,0.38675,19.33743
488.70202,40.64092,5890.20997,0.12431,47.22285,0.38743,19.37139
489.55202,40.71184,5887.49163,0.12430,47.20106,0.38811,19.40549
490.40202,40.78252,5886.56254,0.12429,47.19361,0.38879,19.43947
491.25202,40.85356,5886.76408,0.12430,47.19522,0.38947,19.47362
492.10202,40.92424,5884.20965,0.12430,47.17474,0.39015,19.50760
492.95202,40.99512,5884.81948,0.12429,47.17963,0.39083,19.54168
493.80202,41.06608,5883.84494,0.12428,47.17182,0.39152,19.57579
494.65202,41.13672,5883.09802,0.12432,47.16583,0.39220,19.60976
495.50202,41.20772,5884.01407,0.12430,47.17318,0.39288,19.64389
496.35202,41.27848,5882.82794,0.12427,47.16367,0.39356,19.67791
497.20202,41.34944,5883.73020,0.12428,47.17090,0.39424,19.71202
498.05202,41.42008,5882.32130,0.12431,47.15961,0.39492,19.74598
498.90202,41.49104,5881.72972,0.12431,47.15486,0.39560,19.78010
499.75202,41.56168,5880.78797,0.12428,47.14731,0.39628,19.81406
500.60202,41.63276,5880.60282,0.12428,47.14583,0.39696,19.84823
501.45202,41.70344,5878.24583,0.12428,47.12693,0.39764,19.88222
502.30202,41.77432,5876.77695,0.12431,47.11516,0.39833,19.91629
503.15202,41.84516,5876.30533,0.12429,47.11137,0.39901,19.95035
504.00202,41.91584,5874.11076,0.12429,47.09378,0.39969,19.98433
504.85202,41.98700,5874.93330,0.12429,47.10037,0.40037,20.01854
505.70202,42.05764,5873.30237,0.12431,47.08730,0.40105,20.05250
506.55202,42.12860,5872.93878,0.12429,47.08438,0.40173,20.08662
507.40202,42.19920,5873.20961,0.12430,47.08656,0.40241,20.12056
508.25202,42.27032,5872.98498,0.12431,47.08475,0.40310,20.15475
509.10202,42.34092,5871.97542,0.12431,47.07666,0.40377,20.18870
509.95202,42.41192,5872.71415,0.12428,47.08258,0.40446,20.22283
510.80202,42.48261,5870.80494,0.12430,47.06728,0.40514,20.25681
511.65202,42.55356,5870.59371,0.12429,47.06558,0.40582,20.29093
512.50202,42.62436,5869.69815,0.12429,47.05840,0.40650,20.32497
513.35202,42.69508,5868.32948,0.12430,47.04743,0.40718,20.35897
514.20202,42.76604,5868.51053,0.12429,47.04888,0.40786,20.39308
515.05202,42.83680,5868.36040,0.12429,47.04768,0.40854,20.42710
515.90202,42.90776,5867.14670,0.12430,47.03795,0.40922,20.46122
516.75202,42.97848,5867.64254,0.12430,47.04192,0.40990,20.49521
517.60202,43.04940,5867.78484,0.12430,47.04306,0.41059,20.52931
518.45202,43.12008,5865.95573,0.12430,47.02840,0.41127,20.56329
519.30202,43.19104,5865.83465,0.12429,47.02743,0.41195,20.59741
520.15202,43.26192,5865.85850,0.12430,47.02762,0.41263,20.63148
521.00202,43.33264,5865.87861,0.12430,47.02778,0.41331,20.66548
521.85202,43.40336,5865.50757,0.12431,47.02481,0.41399,20.69948
522.70202,43.47440,5866.95857,0.12428,47.03644,0.41467,20.73364
523.55202,43.54512,5865.64578,0.12428,47.02591,0.41535,20.76764
524.40202,43.61592,5866.50670,0.12431,47.03282,0.41603,20.80168
525.25202,43.68688,5865.34925,0.12434,47.02354,0.41672,20.83579
526.10202,43.75756,5865.76313,0.12431,47.02686,0.41740,20.86977
526.95203,43.82860,5866.27126,0.12426,47.03093,0.41808,20.90393
527.80203,43.89920,5865.60965,0.12428,47.02562,0.41876,20.93787
528.65203,43.97032,5866.73655,0.12431,47.03466,0.41944,20.97206
529.50203,44.04096,5867.54233,0.12431,47.04112,0.42012,21.00602
530.35203,44.11184,5867.20780,0.12430,47.03844,0.42080,21.04010
531.20203,44.18252,5866.79727,0.12430,47.03515,0.42148,21.07408
532.05203,44.25368,5869.21722,0.12430,47.05455,0.42217,21.10829
532.90203,44.32424,5867.60938,0.12430,47.04166,0.42284,21.14221
533.75203,44.39512,5870.58216,0.12429,47.06549,0.42353,21.17629
534.60203,44.46604,5871.05677,0.12430,47.06930,0.42421,21.21039
535.45203,44.53668,5870.95879,0.12430,47.06851,0.42489,21.24435
536.30203,44.60776,5873.02893,0.12429,47.08511,0.42557,21.27852
537.15203,44.67844,5873.49534,0.12429,47.08885,0.42625,21.31250
538.00203,44.74952,5874.58238,0.12430,47.09756,0.42693,21.34667
538.85203,44.82008,5876.13732,0.12430,47.11003,0.42761,21.38060
539.70203,44.89108,5876.82202,0.12428,47.11552,0.42829,21.41473
540.55203,44.96180,5878.12103,0.12431,47.12593,0.42897,21.44874
541.40203,45.03280,5880.91165,0.12432,47.14830,0.42966,21.48287
542.25203,45.10340,5879.98703,0.12430,47.14089,0.43034,21.51681
543.10203,45.17444,5882.92740,0.12429,47.16446,0.43102,21.55097
543.95203,45.24520,5885.20579,0.12431,47.18273,0.43170,21.58498
544.80203,45.31584,5885.89385,0.12431,47.18825,0.43238,21.61895
545.65203,45.38680,5888.02956,0.12429,47.20537,0.43306,21.65306
546.50203,45.45764,5889.46715,0.12428,47.21689,0.43374,21.68712
547.35203,45.52856,5890.43684,0.12429,47.22467,0.43442,21.72122
548.20203,45.59924,5891.95043,0.12433,47.23680,0.43510,21.75519
549.05203,45.67028,5893.06243,0.12430,47.24572,0.43579,21.78935
549.90203,45.74096,5893.98555,0.12428,47.25312,0.43647,21.82333
550.75203,45.81180,5896.24196,0.12429,47.27121,0.43715,21.85739
551.60203,45.88264,5896.65361,0.12430,47.27451,0.43783,21.89144
552.45203,45.95352,5898.86978,0.12431,47.29228,0.43851,21.92552
553.30203,46.02424,5900.77825,0.12430,47.30758,0.43919,21.95952
554.15203,46.09516,5902.54217,0.12427,47.32172,0.43987,21.99362
555.00203,46.16600,5904.35565,0.12428,47.33626,0.44055,22.02768
555.85203,46.23680,5907.61378,0.12430,47.36238,0.44123,22.06172
556.70203,46.30764,5908.67028,0.12428,47.37085,0.44192,22.09577
557.55203,46.37832,5910.70428,0.12428,47.38716,0.44260,22.12975
558.40203,46.44944,5913.95386,0.12428,47.41321,0.44328,22.16395
559.25203,46.52004,5914.13341,0.12434,47.41465,0.44396,22.19789
560.10203,46.59104,5917.29581,0.12429,47.44000,0.44464,22.23202
560.95203,46.66188,5919.08731,0.12427,47.45436,0.44532,22.26608
561.80203,46.73272,5920.61915,0.12431,47.46665,0.44600,22.30014
562.65203,46.80332,5921.27815,0.12434,47.47193,0.44668,22.33408
563.50203,46.87444,5923.23206,0.12429,47.48759,0.44737,22.36828
564.35203,46.94508,5924.74863,0.12427,47.49975,0.44804,22.40223
565.20203,47.01596,5927.78623,0.12429,47.52411,0.44873,22.43631
566.05203,47.08680,5928.55588,0.12431,47.53028,0.44941,22.47037
566.90203,47.15760,5931.74659,0.12430,47.55586,0.45009,22.50441
567.75203,47.22864,5934.66237,0.12429,47.57923,0.45077,22.53856
568.60203,47.29912,5935.15038,0.12429,47.58315,0.45145,22.57245
569.45203,47.37036,5939.74628,0.12433,47.61999,0.45213,22.60670
570.30203,47.44096,5941.22298,0.12428,47.63183,0.45281,22.64064
571.15203,47.51184,5942.34765,0.12430,47.64085,0.45349,22.67472
572.00203,47.58264,5944.57984,0.12430,47.65874,0.45418,22.70875
572.85203,47.65368,5947.36375,0.12430,47.68106,0.45486,22.74291
573.70203,47.72420,5947.90801,0.12431,47.68543,0.45554,22.77681
574.55203,47.79516,5950.30673,0.12431,47.70466,0.45622,22.81093
575.40203,47.86608,5952.08257,0.12429,47.71889,0.45690,22.84502
576.25203,47.93668,5953.34619,0.12428,47.72902,0.45758,22.87897
577.10203,48.00764,5955.32246,0.12430,47.74487,0.45826,22.91308
577.95203,48.07840,5956.61774,0.12430,47.75525,0.45894,22.94710
578.80203,48.14940,5958.95313,0.12428,47.77398,0.45962,22.98123
579.65203,48.22008,5960.59449,0.12428,47.78714,0.46030,23.01522
580.50203,48.29104,5962.09168,0.12429,47.79914,0.46099,23.04933
581.35203,48.36180,5964.57049,0.12431,47.81901,0.46167,23.08335
582.20203,48.43272,5966.80753,0.12429,47.83695,0.46235,23.11745
583.05203,48.50344,5967.59468,0.12429,47.84326,0.46303,23.15145
583.90203,48.57436,5970.21207,0.12429,47.86424,0.46371,23.18554
584.75203,48.64520,5971.70703,0.12431,47.87623,0.46439,23.21960
585.60203,48.71592,5972.65363,0.12431,47.88382,0.46507,23.25360
586.45203,48.78684,5973.49443,0.12429,47.89056,0.46575,23.28770
587.30203,48.85768,5974.69173,0.12430,47.90016,0.46644,23.32175
588.15203,48.92852,5975.89798,0.12429,47.90983,0.46712,23.35581
589.00203,48.99912,5976.40797,0.12427,47.91391,0.46780,23.38975
589.85203,49.07036,5978.96166,0.12428,47.93439,0.46848,23.42400
590.70203,49.14092,5980.32214,0.12433,47.94530,0.46916,23.45793
591.55203,49.21192,5983.18726,0.12431,47.96827,0.46984,23.49206
592.40203,49.28268,5984.02135,0.12429,47.97495,0.47052,23.52608
593.25203,49.35356,5986.88759,0.12429,47.99793,0.47120,23.56016
594.10203,49.42428,5987.86399,0.12429,48.00576,0.47188,23.59416
594.95203,49.49520,5989.50610,0.12431,48.01892,0.47257,23.62825
595.80203,49.56596,5991.69843,0.12430,48.03650,0.47325,23.66227
596.65203,49.63684,5992.49154,0.12430,48.04286,0.47393,23.69635
597.50203,49.70764,5993.37742,0.12430,48.04996,0.47461,23.73039
598.35203,49.77844,5994.67456,0.12429,48.06036,0.47529,23.76443
599.20203,49.84952,5997.18615,0.12430,48.08050,0.47597,23.79860
600.05203,49.91996,5996.96822,0.12429,48.07875,0.47665,23.83247
600.90203,49.99116,5999.71972,0.12429,48.10081,0.47733,23.86670
601.75203,50.06184,6001.55927,0.12430,48.11556,0.47801,23.90068
602.60203,50.13268,6003.04492,0.12430,48.12747,0.47869,23.93473
603.45203,50.20340,6005.40526,0.12430,48.14639,0.47937,23.96873
604.30203,50.27448,6007.11815,0.12429,48.16012,0.48006,24.00291
605.15203,50.34512,6008.41008,0.12430,48.17048,0.48074,24.03687
606.00203,50.41592,6010.81476,0.12431,48.18976,0.48142,24.07091
606.85203,50.48684,6011.61309,0.12430,48.19616,0.48210,24.10500
607.70203,50.55764,6013.09203,0.12426,48.20802,0.48278,24.13904
608.55203,50.62852,6014.31988,0.12429,48.21786,0.48346,24.17312
609.40203,50.69912,6014.68459,0.12431,48.22078,0.48414,24.20706
610.25203,50.77032,6017.01699,0.12431,48.23948,0.48483,24.24129
611.10203,50.84096,6018.98283,0.12429,48.25524,0.48551,24.27525
611.95203,50.91180,6019.71895,0.12429,48.26115,0.48619,24.30931
612.80203,50.98264,6022.05358,0.12430,48.27986,0.48687,24.34337
613.65203,51.05356,6023.55599,0.12430,48.29191,0.48755,24.37747
614.50203,51.12420,6025.48234,0.12428,48.30735,0.48823,24.41142
615.35203,51.19512,6028.07552,0.12430,48.32814,0.48891,24.44552
616.20203,51.26612,6030.19148,0.12430,48.34511,0.48959,24.47966
617.05203,51.33676,6031.29901,0.12429,48.35399,0.49027,24.51362
617.90203,51.40764,6033.95998,0.12429,48.37532,0.49095,24.54770
618.75203,51.47852,6035.61886,0.12431,48.38862,0.49164,24.58177
619.60203,51.54944,6037.19689,0.12433,48.40127,0.49232,24.61587
620.45203,51.61996,6039.44026,0.12431,48.41926,0.49300,24.64977
621.30203,51.69116,6040.17302,0.12429,48.42513,0.49368,24.68401
622.15203,51.76180,6042.38622,0.12429,48.44287,0.49436,24.71796
623.00203,51.83276,6044.67914,0.12431,48.46126,0.49504,24.75208
623.85203,51.90340,6045.02037,0.12431,48.46399,0.49572,24.78604
624.70203,51.97444,6049.01575,0.12429,48.49602,0.49640,24.82020
625.55203,52.04520,6050.40714,0.12430,48.50718,0.49708,24.85421
626.40203,52.11600,6051.20175,0.12431,48.51355,0.49777,24.88825
627.25203,52.18680,6054.57090,0.12430,48.54056,0.49845,24.92229
628.10203,52.25784,6057.68412,0.12429,48.56552,0.49913,24.95645
628.95203,52.32848,6058.76595,0.12430,48.57419,0.49981,24.99041
629.80203,52.39920,6062.94833,0.12432,48.60772,0.50049,25.02441
630.65203,52.47036,6065.32693,0.12430,48.62679,0.50117,25.05862
631.50203,52.54084,6067.57924,0.12428,48.64485,0.50185,25.09251
632.35203,52.61188,6069.79877,0.12428,48.66264,0.50253,25.12666
633.20203,52.68268,6071.59026,0.12430,48.67701,0.50321,25.16070
634.05203,52.75356,6072.90529,0.12431,48.68755,0.50390,25.19477
634.90203,52.82428,6074.98698,0.12429,48.70424,0.50458,25.22877
635.75203,52.89520,6076.70248,0.12430,48.71799,0.50526,25.26287
636.60203,52.96600,6078.28274,0.12430,48.73066,0.50594,25.29691
637.45203,53.03680,6081.44291,0.12430,48.75600,0.50662,25.33094
638.30203,53.10764,6081.99909,0.12429,48.76046,0.50730,25.36500
639.15203,53.17844,6085.63647,0.12429,48.78962,0.50798,25.39904
640.00203,53.24948,6088.88157,0.12428,48.81564,0.50866,25.43320
640.85203,53.31984,6089.77452,0.12432,48.82279,0.50934,25.46702
641.70203,53.39108,6094.07276,0.12430,48.85725,0.51003,25.50127
642.55203,53.46184,6095.73200,0.12431,48.87056,0.51071,25.53529
643.40203,53.53264,6096.85034,0.12431,48.87952,0.51139,25.56933
644.25203,53.60340,6099.06763,0.12429,48.89730,0.51207,25.60335
645.10203,53.67440,6100.24966,0.12430,48.90678,0.51275,25.63748
645.95203,53.74516,6102.61485,0.12431,48.92574,0.51343,25.67150
646.80203,53.81592,6104.33221,0.12431,48.93951,0.51411,25.70552
647.65203,53.88688,6105.05156,0.12430,48.94527,0.51479,25.73964
648.50203,53.95764,6108.02956,0.12431,48.96915,0.51547,25.77366
649.35203,54.02852,6110.80602,0.12431,48.99141,0.51615,25.80774
650.20203,54.09924,6112.09497,0.12429,49.00174,0.51683,25.84174
651.05203,54.17036,6115.41681,0.12429,49.02837,0.51752,25.87593
651.90203,54.24092,6117.59424,0.12431,49.04583,0.51820,25.90985
652.75203,54.31192,6119.25088,0.12432,49.05911,0.51888,25.94398
653.60203,54.38264,6121.74571,0.12430,49.07911,0.51956,25.97798
654.45203,54.45360,6124.39997,0.12429,49.10039,0.52024,26.01210
655.30203,54.52424,6124.14405,0.12432,49.09834,0.52092,26.04606
656.15203,54.59520,6126.14714,0.12432,49.11440,0.52160,26.08018
657.00203,54.66608,6126.73685,0.12428,49.11913,0.52229,26.11425
657.85203,54.73684,6127.29900,0.12429,49.12363,0.52297,26.14827
658.70203,54.80760,6127.63688,0.12433,49.12634,0.52365,26.18229
659.55203,54.87860,6126.33079,0.12430,49.11587,0.52433,26.21643
660.40203,54.94940,6126.53792,0.12427,49.11753,0.52501,26.25047
661.25203,55.02004,6125.05376,0.12429,49.10563,0.52569,26.28443
662.10203,55.09108,6121.26775,0.12432,49.07528,0.52637,26.31858
662.95203,55.16172,6115.68876,0.12433,49.03055,0.52705,26.35254
663.80203,55.23280,6108.05154,0.12430,48.96932,0.52773,26.38671
664.65203,55.30340,6086.83415,0.12426,48.79922,0.52841,26.42066
665.50203,55.37440,6042.91931,0.12431,48.44715,0.52910,26.45479
666.22203,55.43456,657.72110,0.12447,5.27307,0.52967,26.48372